{"level": "ERROR", "message": "DNSError: (1, 'DNS server returned answer with no data')\nTraceback (most recent call last):\n  File \"/home/iman/Personal/TLS-Checker/TLS-Checker/TLS-Checker/main.py\", line 79, in dns_resolve\n    resp = await asyncio.wait_for(\n           ^^^^^^^^^^^^^^^^^^^^^^^\n  File \"/usr/local/lib/python3.12/asyncio/tasks.py\", line 520, in wait_for\n    return await fut\n           ^^^^^^^^^\naiodns.error.DNSError: (1, 'DNS server returned answer with no data')", "timestamp": "2024-05-28T08:42:56.313416+00:00", "logger": "__main__", "module": "main", "function": "dns_resolve", "line": 94, "task_name": "Task-81", "filename": "main.py", "exc_text": null, "msecs": 313.0, "relativeCreated": 7145.041227340698, "thread": 139786612279104, "threadName": "MainThread", "processName": "MainProcess", "process": 10662, "taskName": "Task-81"}
{"level": "ERROR", "message": "DNSError: (1, 'DNS server returned answer with no data')\nTraceback (most recent call last):\n  File \"/home/iman/Personal/TLS-Checker/TLS-Checker/TLS-Checker/main.py\", line 79, in dns_resolve\n    resp = await asyncio.wait_for(\n           ^^^^^^^^^^^^^^^^^^^^^^^\n  File \"/usr/local/lib/python3.12/asyncio/tasks.py\", line 520, in wait_for\n    return await fut\n           ^^^^^^^^^\naiodns.error.DNSError: (1, 'DNS server returned answer with no data')", "timestamp": "2024-05-28T08:42:56.313752+00:00", "logger": "__main__", "module": "main", "function": "dns_resolve", "line": 94, "task_name": "Task-82", "filename": "main.py", "exc_text": null, "msecs": 313.0, "relativeCreated": 7145.376682281494, "thread": 139786612279104, "threadName": "MainThread", "processName": "MainProcess", "process": 10662, "taskName": "Task-82"}
{"level": "ERROR", "message": "DNSError: (1, 'DNS server returned answer with no data')\nTraceback (most recent call last):\n  File \"/home/iman/Personal/TLS-Checker/TLS-Checker/TLS-Checker/main.py\", line 79, in dns_resolve\n    resp = await asyncio.wait_for(\n           ^^^^^^^^^^^^^^^^^^^^^^^\n  File \"/usr/local/lib/python3.12/asyncio/tasks.py\", line 520, in wait_for\n    return await fut\n           ^^^^^^^^^\naiodns.error.DNSError: (1, 'DNS server returned answer with no data')", "timestamp": "2024-05-28T08:42:56.314965+00:00", "logger": "__main__", "module": "main", "function": "dns_resolve", "line": 94, "task_name": "Task-83", "filename": "main.py", "exc_text": null, "msecs": 314.0, "relativeCreated": 7146.589994430542, "thread": 139786612279104, "threadName": "MainThread", "processName": "MainProcess", "process": 10662, "taskName": "Task-83"}
{"level": "ERROR", "message": "DNSError: (1, 'DNS server returned answer with no data')\nTraceback (most recent call last):\n  File \"/home/iman/Personal/TLS-Checker/TLS-Checker/TLS-Checker/main.py\", line 79, in dns_resolve\n    resp = await asyncio.wait_for(\n           ^^^^^^^^^^^^^^^^^^^^^^^\n  File \"/usr/local/lib/python3.12/asyncio/tasks.py\", line 520, in wait_for\n    return await fut\n           ^^^^^^^^^\naiodns.error.DNSError: (1, 'DNS server returned answer with no data')", "timestamp": "2024-05-28T08:42:56.315418+00:00", "logger": "__main__", "module": "main", "function": "dns_resolve", "line": 94, "task_name": "Task-86", "filename": "main.py", "exc_text": null, "msecs": 315.0, "relativeCreated": 7147.042751312256, "thread": 139786612279104, "threadName": "MainThread", "processName": "MainProcess", "process": 10662, "taskName": "Task-86"}
{"level": "ERROR", "message": "DNSError: (1, 'DNS server returned answer with no data')\nTraceback (most recent call last):\n  File \"/home/iman/Personal/TLS-Checker/TLS-Checker/TLS-Checker/main.py\", line 79, in dns_resolve\n    resp = await asyncio.wait_for(\n           ^^^^^^^^^^^^^^^^^^^^^^^\n  File \"/usr/local/lib/python3.12/asyncio/tasks.py\", line 520, in wait_for\n    return await fut\n           ^^^^^^^^^\naiodns.error.DNSError: (1, 'DNS server returned answer with no data')", "timestamp": "2024-05-28T08:42:56.315889+00:00", "logger": "__main__", "module": "main", "function": "dns_resolve", "line": 94, "task_name": "Task-95", "filename": "main.py", "exc_text": null, "msecs": 315.0, "relativeCreated": 7147.513866424561, "thread": 139786612279104, "threadName": "MainThread", "processName": "MainProcess", "process": 10662, "taskName": "Task-95"}
{"level": "ERROR", "message": "DNSError: (1, 'DNS server returned answer with no data')\nTraceback (most recent call last):\n  File \"/home/iman/Personal/TLS-Checker/TLS-Checker/TLS-Checker/main.py\", line 79, in dns_resolve\n    resp = await asyncio.wait_for(\n           ^^^^^^^^^^^^^^^^^^^^^^^\n  File \"/usr/local/lib/python3.12/asyncio/tasks.py\", line 520, in wait_for\n    return await fut\n           ^^^^^^^^^\naiodns.error.DNSError: (1, 'DNS server returned answer with no data')", "timestamp": "2024-05-28T08:42:56.316364+00:00", "logger": "__main__", "module": "main", "function": "dns_resolve", "line": 94, "task_name": "Task-96", "filename": "main.py", "exc_text": null, "msecs": 316.0, "relativeCreated": 7147.98903465271, "thread": 139786612279104, "threadName": "MainThread", "processName": "MainProcess", "process": 10662, "taskName": "Task-96"}
{"level": "ERROR", "message": "DNSError: (1, 'DNS server returned answer with no data')\nTraceback (most recent call last):\n  File \"/home/iman/Personal/TLS-Checker/TLS-Checker/TLS-Checker/main.py\", line 67, in dns_resolve\n    resp = await asyncio.wait_for(\n           ^^^^^^^^^^^^^^^^^^^^^^^\n  File \"/usr/local/lib/python3.12/asyncio/tasks.py\", line 520, in wait_for\n    return await fut\n           ^^^^^^^^^\naiodns.error.DNSError: (1, 'DNS server returned answer with no data')", "timestamp": "2024-05-28T08:42:56.316865+00:00", "logger": "__main__", "module": "main", "function": "dns_resolve", "line": 94, "task_name": "Task-41", "filename": "main.py", "exc_text": null, "msecs": 316.0, "relativeCreated": 7148.489713668823, "thread": 139786612279104, "threadName": "MainThread", "processName": "MainProcess", "process": 10662, "taskName": "Task-41"}
{"level": "ERROR", "message": "DNSError: (1, 'DNS server returned answer with no data')\nTraceback (most recent call last):\n  File \"/home/iman/Personal/TLS-Checker/TLS-Checker/TLS-Checker/main.py\", line 79, in dns_resolve\n    resp = await asyncio.wait_for(\n           ^^^^^^^^^^^^^^^^^^^^^^^\n  File \"/usr/local/lib/python3.12/asyncio/tasks.py\", line 520, in wait_for\n    return await fut\n           ^^^^^^^^^\naiodns.error.DNSError: (1, 'DNS server returned answer with no data')", "timestamp": "2024-05-28T08:42:56.317190+00:00", "logger": "__main__", "module": "main", "function": "dns_resolve", "line": 94, "task_name": "Task-18", "filename": "main.py", "exc_text": null, "msecs": 317.0, "relativeCreated": 7148.814678192139, "thread": 139786612279104, "threadName": "MainThread", "processName": "MainProcess", "process": 10662, "taskName": "Task-18"}
{"level": "ERROR", "message": "DNSError: (1, 'DNS server returned answer with no data')\nTraceback (most recent call last):\n  File \"/home/iman/Personal/TLS-Checker/TLS-Checker/TLS-Checker/main.py\", line 79, in dns_resolve\n    resp = await asyncio.wait_for(\n           ^^^^^^^^^^^^^^^^^^^^^^^\n  File \"/usr/local/lib/python3.12/asyncio/tasks.py\", line 520, in wait_for\n    return await fut\n           ^^^^^^^^^\naiodns.error.DNSError: (1, 'DNS server returned answer with no data')", "timestamp": "2024-05-28T08:42:56.317533+00:00", "logger": "__main__", "module": "main", "function": "dns_resolve", "line": 94, "task_name": "Task-16", "filename": "main.py", "exc_text": null, "msecs": 317.0, "relativeCreated": 7149.158000946045, "thread": 139786612279104, "threadName": "MainThread", "processName": "MainProcess", "process": 10662, "taskName": "Task-16"}
{"level": "ERROR", "message": "DNSError: (1, 'DNS server returned answer with no data')\nTraceback (most recent call last):\n  File \"/home/iman/Personal/TLS-Checker/TLS-Checker/TLS-Checker/main.py\", line 79, in dns_resolve\n    resp = await asyncio.wait_for(\n           ^^^^^^^^^^^^^^^^^^^^^^^\n  File \"/usr/local/lib/python3.12/asyncio/tasks.py\", line 520, in wait_for\n    return await fut\n           ^^^^^^^^^\naiodns.error.DNSError: (1, 'DNS server returned answer with no data')", "timestamp": "2024-05-28T08:42:56.318081+00:00", "logger": "__main__", "module": "main", "function": "dns_resolve", "line": 94, "task_name": "Task-12", "filename": "main.py", "exc_text": null, "msecs": 318.0, "relativeCreated": 7149.706125259399, "thread": 139786612279104, "threadName": "MainThread", "processName": "MainProcess", "process": 10662, "taskName": "Task-12"}
{"level": "ERROR", "message": "DNSError: (1, 'DNS server returned answer with no data')\nTraceback (most recent call last):\n  File \"/home/iman/Personal/TLS-Checker/TLS-Checker/TLS-Checker/main.py\", line 79, in dns_resolve\n    resp = await asyncio.wait_for(\n           ^^^^^^^^^^^^^^^^^^^^^^^\n  File \"/usr/local/lib/python3.12/asyncio/tasks.py\", line 520, in wait_for\n    return await fut\n           ^^^^^^^^^\naiodns.error.DNSError: (1, 'DNS server returned answer with no data')", "timestamp": "2024-05-28T08:42:56.320102+00:00", "logger": "__main__", "module": "main", "function": "dns_resolve", "line": 94, "task_name": "Task-21", "filename": "main.py", "exc_text": null, "msecs": 320.0, "relativeCreated": 7151.727199554443, "thread": 139786612279104, "threadName": "MainThread", "processName": "MainProcess", "process": 10662, "taskName": "Task-21"}
{"level": "ERROR", "message": "DNSError: (1, 'DNS server returned answer with no data')\nTraceback (most recent call last):\n  File \"/home/iman/Personal/TLS-Checker/TLS-Checker/TLS-Checker/main.py\", line 79, in dns_resolve\n    resp = await asyncio.wait_for(\n           ^^^^^^^^^^^^^^^^^^^^^^^\n  File \"/usr/local/lib/python3.12/asyncio/tasks.py\", line 520, in wait_for\n    return await fut\n           ^^^^^^^^^\naiodns.error.DNSError: (1, 'DNS server returned answer with no data')", "timestamp": "2024-05-28T08:42:56.322221+00:00", "logger": "__main__", "module": "main", "function": "dns_resolve", "line": 94, "task_name": "Task-47", "filename": "main.py", "exc_text": null, "msecs": 322.0, "relativeCreated": 7153.84578704834, "thread": 139786612279104, "threadName": "MainThread", "processName": "MainProcess", "process": 10662, "taskName": "Task-47"}
{"level": "ERROR", "message": "DNSError: (1, 'DNS server returned answer with no data')\nTraceback (most recent call last):\n  File \"/home/iman/Personal/TLS-Checker/TLS-Checker/TLS-Checker/main.py\", line 79, in dns_resolve\n    resp = await asyncio.wait_for(\n           ^^^^^^^^^^^^^^^^^^^^^^^\n  File \"/usr/local/lib/python3.12/asyncio/tasks.py\", line 520, in wait_for\n    return await fut\n           ^^^^^^^^^\naiodns.error.DNSError: (1, 'DNS server returned answer with no data')", "timestamp": "2024-05-28T08:42:56.347083+00:00", "logger": "__main__", "module": "main", "function": "dns_resolve", "line": 94, "task_name": "Task-29", "filename": "main.py", "exc_text": null, "msecs": 347.0, "relativeCreated": 7178.708076477051, "thread": 139786612279104, "threadName": "MainThread", "processName": "MainProcess", "process": 10662, "taskName": "Task-29"}
{"level": "ERROR", "message": "DNSError: (1, 'DNS server returned answer with no data')\nTraceback (most recent call last):\n  File \"/home/iman/Personal/TLS-Checker/TLS-Checker/TLS-Checker/main.py\", line 79, in dns_resolve\n    resp = await asyncio.wait_for(\n           ^^^^^^^^^^^^^^^^^^^^^^^\n  File \"/usr/local/lib/python3.12/asyncio/tasks.py\", line 520, in wait_for\n    return await fut\n           ^^^^^^^^^\naiodns.error.DNSError: (1, 'DNS server returned answer with no data')", "timestamp": "2024-05-28T08:42:56.349401+00:00", "logger": "__main__", "module": "main", "function": "dns_resolve", "line": 94, "task_name": "Task-34", "filename": "main.py", "exc_text": null, "msecs": 349.0, "relativeCreated": 7181.025743484497, "thread": 139786612279104, "threadName": "MainThread", "processName": "MainProcess", "process": 10662, "taskName": "Task-34"}
{"level": "ERROR", "message": "DNSError: (1, 'DNS server returned answer with no data')\nTraceback (most recent call last):\n  File \"/home/iman/Personal/TLS-Checker/TLS-Checker/TLS-Checker/main.py\", line 79, in dns_resolve\n    resp = await asyncio.wait_for(\n           ^^^^^^^^^^^^^^^^^^^^^^^\n  File \"/usr/local/lib/python3.12/asyncio/tasks.py\", line 520, in wait_for\n    return await fut\n           ^^^^^^^^^\naiodns.error.DNSError: (1, 'DNS server returned answer with no data')", "timestamp": "2024-05-28T08:42:56.350300+00:00", "logger": "__main__", "module": "main", "function": "dns_resolve", "line": 94, "task_name": "Task-49", "filename": "main.py", "exc_text": null, "msecs": 350.0, "relativeCreated": 7181.924819946289, "thread": 139786612279104, "threadName": "MainThread", "processName": "MainProcess", "process": 10662, "taskName": "Task-49"}
{"level": "ERROR", "message": "DNSError: (1, 'DNS server returned answer with no data')\nTraceback (most recent call last):\n  File \"/home/iman/Personal/TLS-Checker/TLS-Checker/TLS-Checker/main.py\", line 79, in dns_resolve\n    resp = await asyncio.wait_for(\n           ^^^^^^^^^^^^^^^^^^^^^^^\n  File \"/usr/local/lib/python3.12/asyncio/tasks.py\", line 520, in wait_for\n    return await fut\n           ^^^^^^^^^\naiodns.error.DNSError: (1, 'DNS server returned answer with no data')", "timestamp": "2024-05-28T08:42:56.350760+00:00", "logger": "__main__", "module": "main", "function": "dns_resolve", "line": 94, "task_name": "Task-43", "filename": "main.py", "exc_text": null, "msecs": 350.0, "relativeCreated": 7182.384729385376, "thread": 139786612279104, "threadName": "MainThread", "processName": "MainProcess", "process": 10662, "taskName": "Task-43"}
{"level": "ERROR", "message": "DNSError: (1, 'DNS server returned answer with no data')\nTraceback (most recent call last):\n  File \"/home/iman/Personal/TLS-Checker/TLS-Checker/TLS-Checker/main.py\", line 79, in dns_resolve\n    resp = await asyncio.wait_for(\n           ^^^^^^^^^^^^^^^^^^^^^^^\n  File \"/usr/local/lib/python3.12/asyncio/tasks.py\", line 520, in wait_for\n    return await fut\n           ^^^^^^^^^\naiodns.error.DNSError: (1, 'DNS server returned answer with no data')", "timestamp": "2024-05-28T08:42:56.352458+00:00", "logger": "__main__", "module": "main", "function": "dns_resolve", "line": 94, "task_name": "Task-63", "filename": "main.py", "exc_text": null, "msecs": 352.0, "relativeCreated": 7184.082984924316, "thread": 139786612279104, "threadName": "MainThread", "processName": "MainProcess", "process": 10662, "taskName": "Task-63"}
{"level": "ERROR", "message": "DNSError: (1, 'DNS server returned answer with no data')\nTraceback (most recent call last):\n  File \"/home/iman/Personal/TLS-Checker/TLS-Checker/TLS-Checker/main.py\", line 79, in dns_resolve\n    resp = await asyncio.wait_for(\n           ^^^^^^^^^^^^^^^^^^^^^^^\n  File \"/usr/local/lib/python3.12/asyncio/tasks.py\", line 520, in wait_for\n    return await fut\n           ^^^^^^^^^\naiodns.error.DNSError: (1, 'DNS server returned answer with no data')", "timestamp": "2024-05-28T08:42:56.353619+00:00", "logger": "__main__", "module": "main", "function": "dns_resolve", "line": 94, "task_name": "Task-39", "filename": "main.py", "exc_text": null, "msecs": 353.0, "relativeCreated": 7185.243606567383, "thread": 139786612279104, "threadName": "MainThread", "processName": "MainProcess", "process": 10662, "taskName": "Task-39"}
{"level": "ERROR", "message": "DNSError: (1, 'DNS server returned answer with no data')\nTraceback (most recent call last):\n  File \"/home/iman/Personal/TLS-Checker/TLS-Checker/TLS-Checker/main.py\", line 79, in dns_resolve\n    resp = await asyncio.wait_for(\n           ^^^^^^^^^^^^^^^^^^^^^^^\n  File \"/usr/local/lib/python3.12/asyncio/tasks.py\", line 520, in wait_for\n    return await fut\n           ^^^^^^^^^\naiodns.error.DNSError: (1, 'DNS server returned answer with no data')", "timestamp": "2024-05-28T08:42:56.354048+00:00", "logger": "__main__", "module": "main", "function": "dns_resolve", "line": 94, "task_name": "Task-99", "filename": "main.py", "exc_text": null, "msecs": 354.0, "relativeCreated": 7185.6725215911865, "thread": 139786612279104, "threadName": "MainThread", "processName": "MainProcess", "process": 10662, "taskName": "Task-99"}
{"level": "ERROR", "message": "DNSError: (1, 'DNS server returned answer with no data')\nTraceback (most recent call last):\n  File \"/home/iman/Personal/TLS-Checker/TLS-Checker/TLS-Checker/main.py\", line 79, in dns_resolve\n    resp = await asyncio.wait_for(\n           ^^^^^^^^^^^^^^^^^^^^^^^\n  File \"/usr/local/lib/python3.12/asyncio/tasks.py\", line 520, in wait_for\n    return await fut\n           ^^^^^^^^^\naiodns.error.DNSError: (1, 'DNS server returned answer with no data')", "timestamp": "2024-05-28T08:42:56.354958+00:00", "logger": "__main__", "module": "main", "function": "dns_resolve", "line": 94, "task_name": "Task-91", "filename": "main.py", "exc_text": null, "msecs": 354.0, "relativeCreated": 7186.583042144775, "thread": 139786612279104, "threadName": "MainThread", "processName": "MainProcess", "process": 10662, "taskName": "Task-91"}
{"level": "ERROR", "message": "DNSError: (1, 'DNS server returned answer with no data')\nTraceback (most recent call last):\n  File \"/home/iman/Personal/TLS-Checker/TLS-Checker/TLS-Checker/main.py\", line 79, in dns_resolve\n    resp = await asyncio.wait_for(\n           ^^^^^^^^^^^^^^^^^^^^^^^\n  File \"/usr/local/lib/python3.12/asyncio/tasks.py\", line 520, in wait_for\n    return await fut\n           ^^^^^^^^^\naiodns.error.DNSError: (1, 'DNS server returned answer with no data')", "timestamp": "2024-05-28T08:42:56.355912+00:00", "logger": "__main__", "module": "main", "function": "dns_resolve", "line": 94, "task_name": "Task-72", "filename": "main.py", "exc_text": null, "msecs": 355.0, "relativeCreated": 7187.53719329834, "thread": 139786612279104, "threadName": "MainThread", "processName": "MainProcess", "process": 10662, "taskName": "Task-72"}
{"level": "ERROR", "message": "DNSError: (1, 'DNS server returned answer with no data')\nTraceback (most recent call last):\n  File \"/home/iman/Personal/TLS-Checker/TLS-Checker/TLS-Checker/main.py\", line 79, in dns_resolve\n    resp = await asyncio.wait_for(\n           ^^^^^^^^^^^^^^^^^^^^^^^\n  File \"/usr/local/lib/python3.12/asyncio/tasks.py\", line 520, in wait_for\n    return await fut\n           ^^^^^^^^^\naiodns.error.DNSError: (1, 'DNS server returned answer with no data')", "timestamp": "2024-05-28T08:42:56.360526+00:00", "logger": "__main__", "module": "main", "function": "dns_resolve", "line": 94, "task_name": "Task-100", "filename": "main.py", "exc_text": null, "msecs": 360.0, "relativeCreated": 7192.151308059692, "thread": 139786612279104, "threadName": "MainThread", "processName": "MainProcess", "process": 10662, "taskName": "Task-100"}
{"level": "ERROR", "message": "DNSError: (1, 'DNS server returned answer with no data')\nTraceback (most recent call last):\n  File \"/home/iman/Personal/TLS-Checker/TLS-Checker/TLS-Checker/main.py\", line 79, in dns_resolve\n    resp = await asyncio.wait_for(\n           ^^^^^^^^^^^^^^^^^^^^^^^\n  File \"/usr/local/lib/python3.12/asyncio/tasks.py\", line 520, in wait_for\n    return await fut\n           ^^^^^^^^^\naiodns.error.DNSError: (1, 'DNS server returned answer with no data')", "timestamp": "2024-05-28T08:42:56.404010+00:00", "logger": "__main__", "module": "main", "function": "dns_resolve", "line": 94, "task_name": "Task-70", "filename": "main.py", "exc_text": null, "msecs": 404.0, "relativeCreated": 7235.635042190552, "thread": 139786612279104, "threadName": "MainThread", "processName": "MainProcess", "process": 10662, "taskName": "Task-70"}
{"level": "ERROR", "message": "DNSError: (1, 'DNS server returned answer with no data')\nTraceback (most recent call last):\n  File \"/home/iman/Personal/TLS-Checker/TLS-Checker/TLS-Checker/main.py\", line 79, in dns_resolve\n    resp = await asyncio.wait_for(\n           ^^^^^^^^^^^^^^^^^^^^^^^\n  File \"/usr/local/lib/python3.12/asyncio/tasks.py\", line 520, in wait_for\n    return await fut\n           ^^^^^^^^^\naiodns.error.DNSError: (1, 'DNS server returned answer with no data')", "timestamp": "2024-05-28T08:42:56.420501+00:00", "logger": "__main__", "module": "main", "function": "dns_resolve", "line": 94, "task_name": "Task-13", "filename": "main.py", "exc_text": null, "msecs": 420.0, "relativeCreated": 7252.126216888428, "thread": 139786612279104, "threadName": "MainThread", "processName": "MainProcess", "process": 10662, "taskName": "Task-13"}
{"level": "ERROR", "message": "DNSError: (1, 'DNS server returned answer with no data')\nTraceback (most recent call last):\n  File \"/home/iman/Personal/TLS-Checker/TLS-Checker/TLS-Checker/main.py\", line 67, in dns_resolve\n    resp = await asyncio.wait_for(\n           ^^^^^^^^^^^^^^^^^^^^^^^\n  File \"/usr/local/lib/python3.12/asyncio/tasks.py\", line 520, in wait_for\n    return await fut\n           ^^^^^^^^^\naiodns.error.DNSError: (1, 'DNS server returned answer with no data')", "timestamp": "2024-05-28T08:42:56.446091+00:00", "logger": "__main__", "module": "main", "function": "dns_resolve", "line": 94, "task_name": "Task-84", "filename": "main.py", "exc_text": null, "msecs": 446.0, "relativeCreated": 7277.7159214019775, "thread": 139786612279104, "threadName": "MainThread", "processName": "MainProcess", "process": 10662, "taskName": "Task-84"}
{"level": "ERROR", "message": "DNSError: (1, 'DNS server returned answer with no data')\nTraceback (most recent call last):\n  File \"/home/iman/Personal/TLS-Checker/TLS-Checker/TLS-Checker/main.py\", line 79, in dns_resolve\n    resp = await asyncio.wait_for(\n           ^^^^^^^^^^^^^^^^^^^^^^^\n  File \"/usr/local/lib/python3.12/asyncio/tasks.py\", line 520, in wait_for\n    return await fut\n           ^^^^^^^^^\naiodns.error.DNSError: (1, 'DNS server returned answer with no data')", "timestamp": "2024-05-28T08:42:56.449325+00:00", "logger": "__main__", "module": "main", "function": "dns_resolve", "line": 94, "task_name": "Task-69", "filename": "main.py", "exc_text": null, "msecs": 449.0, "relativeCreated": 7280.950307846069, "thread": 139786612279104, "threadName": "MainThread", "processName": "MainProcess", "process": 10662, "taskName": "Task-69"}
{"level": "ERROR", "message": "DNSError: (1, 'DNS server returned answer with no data')\nTraceback (most recent call last):\n  File \"/home/iman/Personal/TLS-Checker/TLS-Checker/TLS-Checker/main.py\", line 79, in dns_resolve\n    resp = await asyncio.wait_for(\n           ^^^^^^^^^^^^^^^^^^^^^^^\n  File \"/usr/local/lib/python3.12/asyncio/tasks.py\", line 520, in wait_for\n    return await fut\n           ^^^^^^^^^\naiodns.error.DNSError: (1, 'DNS server returned answer with no data')", "timestamp": "2024-05-28T08:42:56.456745+00:00", "logger": "__main__", "module": "main", "function": "dns_resolve", "line": 94, "task_name": "Task-57", "filename": "main.py", "exc_text": null, "msecs": 456.0, "relativeCreated": 7288.370370864868, "thread": 139786612279104, "threadName": "MainThread", "processName": "MainProcess", "process": 10662, "taskName": "Task-57"}
{"level": "ERROR", "message": "DNSError: (1, 'DNS server returned answer with no data')\nTraceback (most recent call last):\n  File \"/home/iman/Personal/TLS-Checker/TLS-Checker/TLS-Checker/main.py\", line 79, in dns_resolve\n    resp = await asyncio.wait_for(\n           ^^^^^^^^^^^^^^^^^^^^^^^\n  File \"/usr/local/lib/python3.12/asyncio/tasks.py\", line 520, in wait_for\n    return await fut\n           ^^^^^^^^^\naiodns.error.DNSError: (1, 'DNS server returned answer with no data')", "timestamp": "2024-05-28T08:42:56.457266+00:00", "logger": "__main__", "module": "main", "function": "dns_resolve", "line": 94, "task_name": "Task-58", "filename": "main.py", "exc_text": null, "msecs": 457.0, "relativeCreated": 7288.890600204468, "thread": 139786612279104, "threadName": "MainThread", "processName": "MainProcess", "process": 10662, "taskName": "Task-58"}
{"level": "ERROR", "message": "DNSError: (1, 'DNS server returned answer with no data')\nTraceback (most recent call last):\n  File \"/home/iman/Personal/TLS-Checker/TLS-Checker/TLS-Checker/main.py\", line 79, in dns_resolve\n    resp = await asyncio.wait_for(\n           ^^^^^^^^^^^^^^^^^^^^^^^\n  File \"/usr/local/lib/python3.12/asyncio/tasks.py\", line 520, in wait_for\n    return await fut\n           ^^^^^^^^^\naiodns.error.DNSError: (1, 'DNS server returned answer with no data')", "timestamp": "2024-05-28T08:42:56.471474+00:00", "logger": "__main__", "module": "main", "function": "dns_resolve", "line": 94, "task_name": "Task-50", "filename": "main.py", "exc_text": null, "msecs": 471.0, "relativeCreated": 7303.0993938446045, "thread": 139786612279104, "threadName": "MainThread", "processName": "MainProcess", "process": 10662, "taskName": "Task-50"}
{"level": "ERROR", "message": "DNSError: (1, 'DNS server returned answer with no data')\nTraceback (most recent call last):\n  File \"/home/iman/Personal/TLS-Checker/TLS-Checker/TLS-Checker/main.py\", line 79, in dns_resolve\n    resp = await asyncio.wait_for(\n           ^^^^^^^^^^^^^^^^^^^^^^^\n  File \"/usr/local/lib/python3.12/asyncio/tasks.py\", line 520, in wait_for\n    return await fut\n           ^^^^^^^^^\naiodns.error.DNSError: (1, 'DNS server returned answer with no data')", "timestamp": "2024-05-28T08:42:56.512244+00:00", "logger": "__main__", "module": "main", "function": "dns_resolve", "line": 94, "task_name": "Task-90", "filename": "main.py", "exc_text": null, "msecs": 512.0, "relativeCreated": 7343.868732452393, "thread": 139786612279104, "threadName": "MainThread", "processName": "MainProcess", "process": 10662, "taskName": "Task-90"}
{"level": "ERROR", "message": "DNSError: (1, 'DNS server returned answer with no data')\nTraceback (most recent call last):\n  File \"/home/iman/Personal/TLS-Checker/TLS-Checker/TLS-Checker/main.py\", line 79, in dns_resolve\n    resp = await asyncio.wait_for(\n           ^^^^^^^^^^^^^^^^^^^^^^^\n  File \"/usr/local/lib/python3.12/asyncio/tasks.py\", line 520, in wait_for\n    return await fut\n           ^^^^^^^^^\naiodns.error.DNSError: (1, 'DNS server returned answer with no data')", "timestamp": "2024-05-28T08:42:56.512957+00:00", "logger": "__main__", "module": "main", "function": "dns_resolve", "line": 94, "task_name": "Task-11", "filename": "main.py", "exc_text": null, "msecs": 512.0, "relativeCreated": 7344.581604003906, "thread": 139786612279104, "threadName": "MainThread", "processName": "MainProcess", "process": 10662, "taskName": "Task-11"}
{"level": "ERROR", "message": "DNSError: (1, 'DNS server returned answer with no data')\nTraceback (most recent call last):\n  File \"/home/iman/Personal/TLS-Checker/TLS-Checker/TLS-Checker/main.py\", line 79, in dns_resolve\n    resp = await asyncio.wait_for(\n           ^^^^^^^^^^^^^^^^^^^^^^^\n  File \"/usr/local/lib/python3.12/asyncio/tasks.py\", line 520, in wait_for\n    return await fut\n           ^^^^^^^^^\naiodns.error.DNSError: (1, 'DNS server returned answer with no data')", "timestamp": "2024-05-28T08:42:56.580361+00:00", "logger": "__main__", "module": "main", "function": "dns_resolve", "line": 94, "task_name": "Task-67", "filename": "main.py", "exc_text": null, "msecs": 580.0, "relativeCreated": 7411.985874176025, "thread": 139786612279104, "threadName": "MainThread", "processName": "MainProcess", "process": 10662, "taskName": "Task-67"}
{"level": "ERROR", "message": "DNSError: (1, 'DNS server returned answer with no data')\nTraceback (most recent call last):\n  File \"/home/iman/Personal/TLS-Checker/TLS-Checker/TLS-Checker/main.py\", line 79, in dns_resolve\n    resp = await asyncio.wait_for(\n           ^^^^^^^^^^^^^^^^^^^^^^^\n  File \"/usr/local/lib/python3.12/asyncio/tasks.py\", line 520, in wait_for\n    return await fut\n           ^^^^^^^^^\naiodns.error.DNSError: (1, 'DNS server returned answer with no data')", "timestamp": "2024-05-28T08:42:56.603041+00:00", "logger": "__main__", "module": "main", "function": "dns_resolve", "line": 94, "task_name": "Task-17", "filename": "main.py", "exc_text": null, "msecs": 603.0, "relativeCreated": 7434.666156768799, "thread": 139786612279104, "threadName": "MainThread", "processName": "MainProcess", "process": 10662, "taskName": "Task-17"}
{"level": "ERROR", "message": "DNSError: (1, 'DNS server returned answer with no data')\nTraceback (most recent call last):\n  File \"/home/iman/Personal/TLS-Checker/TLS-Checker/TLS-Checker/main.py\", line 79, in dns_resolve\n    resp = await asyncio.wait_for(\n           ^^^^^^^^^^^^^^^^^^^^^^^\n  File \"/usr/local/lib/python3.12/asyncio/tasks.py\", line 520, in wait_for\n    return await fut\n           ^^^^^^^^^\naiodns.error.DNSError: (1, 'DNS server returned answer with no data')", "timestamp": "2024-05-28T08:42:57.031280+00:00", "logger": "__main__", "module": "main", "function": "dns_resolve", "line": 94, "task_name": "Task-38", "filename": "main.py", "exc_text": null, "msecs": 31.0, "relativeCreated": 7862.9045486450195, "thread": 139786612279104, "threadName": "MainThread", "processName": "MainProcess", "process": 10662, "taskName": "Task-38"}
{"level": "ERROR", "message": "DNSError: (1, 'DNS server returned answer with no data')\nTraceback (most recent call last):\n  File \"/home/iman/Personal/TLS-Checker/TLS-Checker/TLS-Checker/main.py\", line 79, in dns_resolve\n    resp = await asyncio.wait_for(\n           ^^^^^^^^^^^^^^^^^^^^^^^\n  File \"/usr/local/lib/python3.12/asyncio/tasks.py\", line 520, in wait_for\n    return await fut\n           ^^^^^^^^^\naiodns.error.DNSError: (1, 'DNS server returned answer with no data')", "timestamp": "2024-05-28T08:42:58.112957+00:00", "logger": "__main__", "module": "main", "function": "dns_resolve", "line": 94, "task_name": "Task-25", "filename": "main.py", "exc_text": null, "msecs": 112.0, "relativeCreated": 8944.581985473633, "thread": 139786612279104, "threadName": "MainThread", "processName": "MainProcess", "process": 10662, "taskName": "Task-25"}
{"level": "ERROR", "message": "Timeout Error: \nTraceback (most recent call last):\n  File \"/usr/local/lib/python3.12/asyncio/tasks.py\", line 520, in wait_for\n    return await fut\n           ^^^^^^^^^\nasyncio.exceptions.CancelledError\n\nThe above exception was the direct cause of the following exception:\n\nTraceback (most recent call last):\n  File \"/home/iman/Personal/TLS-Checker/TLS-Checker/TLS-Checker/main.py\", line 79, in dns_resolve\n    resp = await asyncio.wait_for(\n           ^^^^^^^^^^^^^^^^^^^^^^^\n  File \"/usr/local/lib/python3.12/asyncio/tasks.py\", line 519, in wait_for\n    async with timeouts.timeout(timeout):\n  File \"/usr/local/lib/python3.12/asyncio/timeouts.py\", line 115, in __aexit__\n    raise TimeoutError from exc_val\nTimeoutError", "timestamp": "2024-05-28T08:42:59.162251+00:00", "logger": "__main__", "module": "main", "function": "dns_resolve", "line": 96, "task_name": "Task-6", "filename": "main.py", "exc_text": null, "msecs": 162.0, "relativeCreated": 9993.875980377197, "thread": 139786612279104, "threadName": "MainThread", "processName": "MainProcess", "process": 10662, "taskName": "Task-6"}
{"level": "ERROR", "message": "Timeout Error: \nTraceback (most recent call last):\n  File \"/usr/local/lib/python3.12/asyncio/tasks.py\", line 520, in wait_for\n    return await fut\n           ^^^^^^^^^\nasyncio.exceptions.CancelledError\n\nThe above exception was the direct cause of the following exception:\n\nTraceback (most recent call last):\n  File \"/home/iman/Personal/TLS-Checker/TLS-Checker/TLS-Checker/main.py\", line 79, in dns_resolve\n    resp = await asyncio.wait_for(\n           ^^^^^^^^^^^^^^^^^^^^^^^\n  File \"/usr/local/lib/python3.12/asyncio/tasks.py\", line 519, in wait_for\n    async with timeouts.timeout(timeout):\n  File \"/usr/local/lib/python3.12/asyncio/timeouts.py\", line 115, in __aexit__\n    raise TimeoutError from exc_val\nTimeoutError", "timestamp": "2024-05-28T08:42:59.166790+00:00", "logger": "__main__", "module": "main", "function": "dns_resolve", "line": 96, "task_name": "Task-19", "filename": "main.py", "exc_text": null, "msecs": 166.0, "relativeCreated": 9998.414516448975, "thread": 139786612279104, "threadName": "MainThread", "processName": "MainProcess", "process": 10662, "taskName": "Task-19"}
{"level": "ERROR", "message": "Timeout Error: \nTraceback (most recent call last):\n  File \"/usr/local/lib/python3.12/asyncio/tasks.py\", line 520, in wait_for\n    return await fut\n           ^^^^^^^^^\nasyncio.exceptions.CancelledError\n\nThe above exception was the direct cause of the following exception:\n\nTraceback (most recent call last):\n  File \"/home/iman/Personal/TLS-Checker/TLS-Checker/TLS-Checker/main.py\", line 79, in dns_resolve\n    resp = await asyncio.wait_for(\n           ^^^^^^^^^^^^^^^^^^^^^^^\n  File \"/usr/local/lib/python3.12/asyncio/tasks.py\", line 519, in wait_for\n    async with timeouts.timeout(timeout):\n  File \"/usr/local/lib/python3.12/asyncio/timeouts.py\", line 115, in __aexit__\n    raise TimeoutError from exc_val\nTimeoutError", "timestamp": "2024-05-28T08:42:59.172910+00:00", "logger": "__main__", "module": "main", "function": "dns_resolve", "line": 96, "task_name": "Task-9", "filename": "main.py", "exc_text": null, "msecs": 172.0, "relativeCreated": 10004.53495979309, "thread": 139786612279104, "threadName": "MainThread", "processName": "MainProcess", "process": 10662, "taskName": "Task-9"}
{"level": "INFO", "message": "Saving data into output.db was successfully", "timestamp": "2024-05-28T08:42:59.209710+00:00", "logger": "__main__", "module": "main", "function": "main", "line": 242, "task_name": "Task-1", "filename": "main.py", "exc_text": null, "msecs": 209.0, "relativeCreated": 10041.334867477417, "thread": 139786612279104, "threadName": "MainThread", "processName": "MainProcess", "process": 10662, "taskName": "Task-1"}
{"level": "INFO", "message": "Successfully converted", "timestamp": "2024-05-28T08:42:59.246536+00:00", "logger": "csv_convertor", "module": "csv_convertor", "function": "convertor", "line": 109, "task_name": "Task-1", "filename": "csv_convertor.py", "exc_text": null, "msecs": 246.0, "relativeCreated": 10078.161001205444, "thread": 139786612279104, "threadName": "MainThread", "processName": "MainProcess", "process": 10662, "taskName": "Task-1"}
{"level": "INFO", "message": "Database successfully converted to csv file", "timestamp": "2024-05-28T08:42:59.247525+00:00", "logger": "__main__", "module": "main", "function": "main", "line": 245, "task_name": "Task-1", "filename": "main.py", "exc_text": null, "msecs": 247.0, "relativeCreated": 10079.150199890137, "thread": 139786612279104, "threadName": "MainThread", "processName": "MainProcess", "process": 10662, "taskName": "Task-1"}
{"level": "INFO", "message": "App was finished gracefully", "timestamp": "2024-05-28T08:42:59.341835+00:00", "logger": "__main__", "module": "main", "function": "<module>", "line": 260, "task_name": null, "filename": "main.py", "exc_text": null, "msecs": 341.0, "relativeCreated": 10173.459529876709, "thread": 139786612279104, "threadName": "MainThread", "processName": "MainProcess", "process": 10662, "taskName": null}
{"level": "INFO", "message": "Start reading input.csv", "timestamp": "2024-05-28T08:50:26.128143+00:00", "logger": "__main__", "module": "main", "function": "open_csv", "line": 103, "task_name": "Task-1", "filename": "main.py", "exc_text": null, "msecs": 128.0, "relativeCreated": 151.02434158325195, "thread": 140579432793920, "threadName": "MainThread", "processName": "MainProcess", "process": 11044, "taskName": "Task-1"}
{"level": "INFO", "message": "Successfully extracted domains from input.csv", "timestamp": "2024-05-28T08:50:27.623322+00:00", "logger": "__main__", "module": "main", "function": "open_csv", "line": 112, "task_name": "Task-1", "filename": "main.py", "exc_text": null, "msecs": 623.0, "relativeCreated": 1646.2032794952393, "thread": 140579432793920, "threadName": "MainThread", "processName": "MainProcess", "process": 11044, "taskName": "Task-1"}
{"level": "INFO", "message": "Start config before scanning", "timestamp": "2024-05-28T08:50:27.623443+00:00", "logger": "__main__", "module": "main", "function": "create_tasks", "line": 157, "task_name": "Task-1", "filename": "main.py", "exc_text": null, "msecs": 623.0, "relativeCreated": 1646.324634552002, "thread": 140579432793920, "threadName": "MainThread", "processName": "MainProcess", "process": 11044, "taskName": "Task-1"}
{"level": "INFO", "message": "domain_chunk was set to 10", "timestamp": "2024-05-28T08:50:30.229745+00:00", "logger": "__main__", "module": "main", "function": "create_tasks", "line": 171, "task_name": "Task-1", "filename": "main.py", "exc_text": null, "msecs": 229.0, "relativeCreated": 4252.626895904541, "thread": 140579432793920, "threadName": "MainThread", "processName": "MainProcess", "process": 11044, "taskName": "Task-1"}
{"level": "ERROR", "message": "Invalid value for active tasks: invalid literal for int() with base 10: ''", "timestamp": "2024-05-28T08:50:31.876655+00:00", "logger": "__main__", "module": "main", "function": "create_tasks", "line": 192, "task_name": "Task-1", "filename": "main.py", "exc_text": null, "msecs": 876.0, "relativeCreated": 5899.536609649658, "thread": 140579432793920, "threadName": "MainThread", "processName": "MainProcess", "process": 11044, "taskName": "Task-1"}
{"level": "ERROR", "message": "Invalid value for timeout: invalid literal for int() with base 10: ''", "timestamp": "2024-05-28T08:50:32.496134+00:00", "logger": "__main__", "module": "main", "function": "create_tasks", "line": 203, "task_name": "Task-1", "filename": "main.py", "exc_text": null, "msecs": 496.0, "relativeCreated": 6519.015789031982, "thread": 140579432793920, "threadName": "MainThread", "processName": "MainProcess", "process": 11044, "taskName": "Task-1"}
{"level": "ERROR", "message": "DNSError: (1, 'DNS server returned answer with no data')\nTraceback (most recent call last):\n  File \"/home/iman/Personal/TLS-Checker/TLS-Checker/TLS-Checker/main.py\", line 79, in dns_resolve\n    resp = await asyncio.wait_for(\n           ^^^^^^^^^^^^^^^^^^^^^^^\n  File \"/usr/local/lib/python3.12/asyncio/tasks.py\", line 520, in wait_for\n    return await fut\n           ^^^^^^^^^\naiodns.error.DNSError: (1, 'DNS server returned answer with no data')", "timestamp": "2024-05-28T08:50:32.577141+00:00", "logger": "__main__", "module": "main", "function": "dns_resolve", "line": 94, "task_name": "Task-7", "filename": "main.py", "exc_text": null, "msecs": 577.0, "relativeCreated": 6600.022554397583, "thread": 140579432793920, "threadName": "MainThread", "processName": "MainProcess", "process": 11044, "taskName": "Task-7"}
{"level": "ERROR", "message": "DNSError: (1, 'DNS server returned answer with no data')\nTraceback (most recent call last):\n  File \"/home/iman/Personal/TLS-Checker/TLS-Checker/TLS-Checker/main.py\", line 79, in dns_resolve\n    resp = await asyncio.wait_for(\n           ^^^^^^^^^^^^^^^^^^^^^^^\n  File \"/usr/local/lib/python3.12/asyncio/tasks.py\", line 520, in wait_for\n    return await fut\n           ^^^^^^^^^\naiodns.error.DNSError: (1, 'DNS server returned answer with no data')", "timestamp": "2024-05-28T08:50:32.578777+00:00", "logger": "__main__", "module": "main", "function": "dns_resolve", "line": 94, "task_name": "Task-8", "filename": "main.py", "exc_text": null, "msecs": 578.0, "relativeCreated": 6601.658344268799, "thread": 140579432793920, "threadName": "MainThread", "processName": "MainProcess", "process": 11044, "taskName": "Task-8"}
{"level": "ERROR", "message": "DNSError: (1, 'DNS server returned answer with no data')\nTraceback (most recent call last):\n  File \"/home/iman/Personal/TLS-Checker/TLS-Checker/TLS-Checker/main.py\", line 79, in dns_resolve\n    resp = await asyncio.wait_for(\n           ^^^^^^^^^^^^^^^^^^^^^^^\n  File \"/usr/local/lib/python3.12/asyncio/tasks.py\", line 520, in wait_for\n    return await fut\n           ^^^^^^^^^\naiodns.error.DNSError: (1, 'DNS server returned answer with no data')", "timestamp": "2024-05-28T08:50:32.581752+00:00", "logger": "__main__", "module": "main", "function": "dns_resolve", "line": 94, "task_name": "Task-10", "filename": "main.py", "exc_text": null, "msecs": 581.0, "relativeCreated": 6604.633808135986, "thread": 140579432793920, "threadName": "MainThread", "processName": "MainProcess", "process": 11044, "taskName": "Task-10"}
{"level": "ERROR", "message": "DNSError: (1, 'DNS server returned answer with no data')\nTraceback (most recent call last):\n  File \"/home/iman/Personal/TLS-Checker/TLS-Checker/TLS-Checker/main.py\", line 79, in dns_resolve\n    resp = await asyncio.wait_for(\n           ^^^^^^^^^^^^^^^^^^^^^^^\n  File \"/usr/local/lib/python3.12/asyncio/tasks.py\", line 520, in wait_for\n    return await fut\n           ^^^^^^^^^\naiodns.error.DNSError: (1, 'DNS server returned answer with no data')", "timestamp": "2024-05-28T08:50:32.582400+00:00", "logger": "__main__", "module": "main", "function": "dns_resolve", "line": 94, "task_name": "Task-11", "filename": "main.py", "exc_text": null, "msecs": 582.0, "relativeCreated": 6605.281352996826, "thread": 140579432793920, "threadName": "MainThread", "processName": "MainProcess", "process": 11044, "taskName": "Task-11"}
{"level": "ERROR", "message": "DNSError: (1, 'DNS server returned answer with no data')\nTraceback (most recent call last):\n  File \"/home/iman/Personal/TLS-Checker/TLS-Checker/TLS-Checker/main.py\", line 67, in dns_resolve\n    resp = await asyncio.wait_for(\n           ^^^^^^^^^^^^^^^^^^^^^^^\n  File \"/usr/local/lib/python3.12/asyncio/tasks.py\", line 520, in wait_for\n    return await fut\n           ^^^^^^^^^\naiodns.error.DNSError: (1, 'DNS server returned answer with no data')", "timestamp": "2024-05-28T08:50:32.614566+00:00", "logger": "__main__", "module": "main", "function": "dns_resolve", "line": 94, "task_name": "Task-4", "filename": "main.py", "exc_text": null, "msecs": 614.0, "relativeCreated": 6637.447118759155, "thread": 140579432793920, "threadName": "MainThread", "processName": "MainProcess", "process": 11044, "taskName": "Task-4"}
{"level": "ERROR", "message": "DNSError: (1, 'DNS server returned answer with no data')\nTraceback (most recent call last):\n  File \"/home/iman/Personal/TLS-Checker/TLS-Checker/TLS-Checker/main.py\", line 79, in dns_resolve\n    resp = await asyncio.wait_for(\n           ^^^^^^^^^^^^^^^^^^^^^^^\n  File \"/usr/local/lib/python3.12/asyncio/tasks.py\", line 520, in wait_for\n    return await fut\n           ^^^^^^^^^\naiodns.error.DNSError: (1, 'DNS server returned answer with no data')", "timestamp": "2024-05-28T08:50:32.657397+00:00", "logger": "__main__", "module": "main", "function": "dns_resolve", "line": 94, "task_name": "Task-2", "filename": "main.py", "exc_text": null, "msecs": 657.0, "relativeCreated": 6680.278062820435, "thread": 140579432793920, "threadName": "MainThread", "processName": "MainProcess", "process": 11044, "taskName": "Task-2"}
{"level": "ERROR", "message": "DNSError: (1, 'DNS server returned answer with no data')\nTraceback (most recent call last):\n  File \"/home/iman/Personal/TLS-Checker/TLS-Checker/TLS-Checker/main.py\", line 79, in dns_resolve\n    resp = await asyncio.wait_for(\n           ^^^^^^^^^^^^^^^^^^^^^^^\n  File \"/usr/local/lib/python3.12/asyncio/tasks.py\", line 520, in wait_for\n    return await fut\n           ^^^^^^^^^\naiodns.error.DNSError: (1, 'DNS server returned answer with no data')", "timestamp": "2024-05-28T08:50:32.659324+00:00", "logger": "__main__", "module": "main", "function": "dns_resolve", "line": 94, "task_name": "Task-5", "filename": "main.py", "exc_text": null, "msecs": 659.0, "relativeCreated": 6682.20591545105, "thread": 140579432793920, "threadName": "MainThread", "processName": "MainProcess", "process": 11044, "taskName": "Task-5"}
{"level": "ERROR", "message": "Timeout Error: \nTraceback (most recent call last):\n  File \"/usr/local/lib/python3.12/asyncio/tasks.py\", line 520, in wait_for\n    return await fut\n           ^^^^^^^^^\nasyncio.exceptions.CancelledError\n\nThe above exception was the direct cause of the following exception:\n\nTraceback (most recent call last):\n  File \"/home/iman/Personal/TLS-Checker/TLS-Checker/TLS-Checker/main.py\", line 79, in dns_resolve\n    resp = await asyncio.wait_for(\n           ^^^^^^^^^^^^^^^^^^^^^^^\n  File \"/usr/local/lib/python3.12/asyncio/tasks.py\", line 519, in wait_for\n    async with timeouts.timeout(timeout):\n  File \"/usr/local/lib/python3.12/asyncio/timeouts.py\", line 115, in __aexit__\n    raise TimeoutError from exc_val\nTimeoutError", "timestamp": "2024-05-28T08:50:35.724284+00:00", "logger": "__main__", "module": "main", "function": "dns_resolve", "line": 96, "task_name": "Task-3", "filename": "main.py", "exc_text": null, "msecs": 724.0, "relativeCreated": 9747.16591835022, "thread": 140579432793920, "threadName": "MainThread", "processName": "MainProcess", "process": 11044, "taskName": "Task-3"}
{"level": "INFO", "message": "Saving data into output.db was successfully", "timestamp": "2024-05-28T08:50:35.755252+00:00", "logger": "__main__", "module": "main", "function": "main", "line": 242, "task_name": "Task-1", "filename": "main.py", "exc_text": null, "msecs": 755.0, "relativeCreated": 9778.133869171143, "thread": 140579432793920, "threadName": "MainThread", "processName": "MainProcess", "process": 11044, "taskName": "Task-1"}
{"level": "INFO", "message": "Successfully converted", "timestamp": "2024-05-28T08:50:35.790686+00:00", "logger": "csv_convertor", "module": "csv_convertor", "function": "convertor", "line": 109, "task_name": "Task-1", "filename": "csv_convertor.py", "exc_text": null, "msecs": 790.0, "relativeCreated": 9813.567399978638, "thread": 140579432793920, "threadName": "MainThread", "processName": "MainProcess", "process": 11044, "taskName": "Task-1"}
{"level": "INFO", "message": "Database successfully converted to csv file", "timestamp": "2024-05-28T08:50:35.791619+00:00", "logger": "__main__", "module": "main", "function": "main", "line": 245, "task_name": "Task-1", "filename": "main.py", "exc_text": null, "msecs": 791.0, "relativeCreated": 9814.50080871582, "thread": 140579432793920, "threadName": "MainThread", "processName": "MainProcess", "process": 11044, "taskName": "Task-1"}
{"level": "INFO", "message": "App was finished gracefully", "timestamp": "2024-05-28T08:50:35.872968+00:00", "logger": "__main__", "module": "main", "function": "<module>", "line": 260, "task_name": null, "filename": "main.py", "exc_text": null, "msecs": 872.0, "relativeCreated": 9895.849704742432, "thread": 140579432793920, "threadName": "MainThread", "processName": "MainProcess", "process": 11044, "taskName": null}
