{"level": "ERROR", "message": "DNSError: (1, 'DNS server returned answer with no data')\nTraceback (most recent call last):\n  File \"/home/iman/Personal/TLS-Checker/TLS-Checker/TLS-Checker/main.py\", line 79, in dns_resolve\n    resp = await asyncio.wait_for(\n           ^^^^^^^^^^^^^^^^^^^^^^^\n  File \"/usr/local/lib/python3.12/asyncio/tasks.py\", line 520, in wait_for\n    return await fut\n           ^^^^^^^^^\naiodns.error.DNSError: (1, 'DNS server returned answer with no data')", "timestamp": "2024-05-28T08:42:56.313416+00:00", "logger": "__main__", "module": "main", "function": "dns_resolve", "line": 94, "task_name": "Task-81", "filename": "main.py", "exc_text": null, "msecs": 313.0, "relativeCreated": 7145.041227340698, "thread": 139786612279104, "threadName": "MainThread", "processName": "MainProcess", "process": 10662, "taskName": "Task-81"}
{"level": "ERROR", "message": "DNSError: (1, 'DNS server returned answer with no data')\nTraceback (most recent call last):\n  File \"/home/iman/Personal/TLS-Checker/TLS-Checker/TLS-Checker/main.py\", line 79, in dns_resolve\n    resp = await asyncio.wait_for(\n           ^^^^^^^^^^^^^^^^^^^^^^^\n  File \"/usr/local/lib/python3.12/asyncio/tasks.py\", line 520, in wait_for\n    return await fut\n           ^^^^^^^^^\naiodns.error.DNSError: (1, 'DNS server returned answer with no data')", "timestamp": "2024-05-28T08:42:56.313752+00:00", "logger": "__main__", "module": "main", "function": "dns_resolve", "line": 94, "task_name": "Task-82", "filename": "main.py", "exc_text": null, "msecs": 313.0, "relativeCreated": 7145.376682281494, "thread": 139786612279104, "threadName": "MainThread", "processName": "MainProcess", "process": 10662, "taskName": "Task-82"}
{"level": "ERROR", "message": "DNSError: (1, 'DNS server returned answer with no data')\nTraceback (most recent call last):\n  File \"/home/iman/Personal/TLS-Checker/TLS-Checker/TLS-Checker/main.py\", line 79, in dns_resolve\n    resp = await asyncio.wait_for(\n           ^^^^^^^^^^^^^^^^^^^^^^^\n  File \"/usr/local/lib/python3.12/asyncio/tasks.py\", line 520, in wait_for\n    return await fut\n           ^^^^^^^^^\naiodns.error.DNSError: (1, 'DNS server returned answer with no data')", "timestamp": "2024-05-28T08:42:56.314965+00:00", "logger": "__main__", "module": "main", "function": "dns_resolve", "line": 94, "task_name": "Task-83", "filename": "main.py", "exc_text": null, "msecs": 314.0, "relativeCreated": 7146.589994430542, "thread": 139786612279104, "threadName": "MainThread", "processName": "MainProcess", "process": 10662, "taskName": "Task-83"}
{"level": "ERROR", "message": "DNSError: (1, 'DNS server returned answer with no data')\nTraceback (most recent call last):\n  File \"/home/iman/Personal/TLS-Checker/TLS-Checker/TLS-Checker/main.py\", line 79, in dns_resolve\n    resp = await asyncio.wait_for(\n           ^^^^^^^^^^^^^^^^^^^^^^^\n  File \"/usr/local/lib/python3.12/asyncio/tasks.py\", line 520, in wait_for\n    return await fut\n           ^^^^^^^^^\naiodns.error.DNSError: (1, 'DNS server returned answer with no data')", "timestamp": "2024-05-28T08:42:56.315418+00:00", "logger": "__main__", "module": "main", "function": "dns_resolve", "line": 94, "task_name": "Task-86", "filename": "main.py", "exc_text": null, "msecs": 315.0, "relativeCreated": 7147.042751312256, "thread": 139786612279104, "threadName": "MainThread", "processName": "MainProcess", "process": 10662, "taskName": "Task-86"}
{"level": "ERROR", "message": "DNSError: (1, 'DNS server returned answer with no data')\nTraceback (most recent call last):\n  File \"/home/iman/Personal/TLS-Checker/TLS-Checker/TLS-Checker/main.py\", line 79, in dns_resolve\n    resp = await asyncio.wait_for(\n           ^^^^^^^^^^^^^^^^^^^^^^^\n  File \"/usr/local/lib/python3.12/asyncio/tasks.py\", line 520, in wait_for\n    return await fut\n           ^^^^^^^^^\naiodns.error.DNSError: (1, 'DNS server returned answer with no data')", "timestamp": "2024-05-28T08:42:56.315889+00:00", "logger": "__main__", "module": "main", "function": "dns_resolve", "line": 94, "task_name": "Task-95", "filename": "main.py", "exc_text": null, "msecs": 315.0, "relativeCreated": 7147.513866424561, "thread": 139786612279104, "threadName": "MainThread", "processName": "MainProcess", "process": 10662, "taskName": "Task-95"}
{"level": "ERROR", "message": "DNSError: (1, 'DNS server returned answer with no data')\nTraceback (most recent call last):\n  File \"/home/iman/Personal/TLS-Checker/TLS-Checker/TLS-Checker/main.py\", line 79, in dns_resolve\n    resp = await asyncio.wait_for(\n           ^^^^^^^^^^^^^^^^^^^^^^^\n  File \"/usr/local/lib/python3.12/asyncio/tasks.py\", line 520, in wait_for\n    return await fut\n           ^^^^^^^^^\naiodns.error.DNSError: (1, 'DNS server returned answer with no data')", "timestamp": "2024-05-28T08:42:56.316364+00:00", "logger": "__main__", "module": "main", "function": "dns_resolve", "line": 94, "task_name": "Task-96", "filename": "main.py", "exc_text": null, "msecs": 316.0, "relativeCreated": 7147.98903465271, "thread": 139786612279104, "threadName": "MainThread", "processName": "MainProcess", "process": 10662, "taskName": "Task-96"}
{"level": "ERROR", "message": "DNSError: (1, 'DNS server returned answer with no data')\nTraceback (most recent call last):\n  File \"/home/iman/Personal/TLS-Checker/TLS-Checker/TLS-Checker/main.py\", line 67, in dns_resolve\n    resp = await asyncio.wait_for(\n           ^^^^^^^^^^^^^^^^^^^^^^^\n  File \"/usr/local/lib/python3.12/asyncio/tasks.py\", line 520, in wait_for\n    return await fut\n           ^^^^^^^^^\naiodns.error.DNSError: (1, 'DNS server returned answer with no data')", "timestamp": "2024-05-28T08:42:56.316865+00:00", "logger": "__main__", "module": "main", "function": "dns_resolve", "line": 94, "task_name": "Task-41", "filename": "main.py", "exc_text": null, "msecs": 316.0, "relativeCreated": 7148.489713668823, "thread": 139786612279104, "threadName": "MainThread", "processName": "MainProcess", "process": 10662, "taskName": "Task-41"}
{"level": "ERROR", "message": "DNSError: (1, 'DNS server returned answer with no data')\nTraceback (most recent call last):\n  File \"/home/iman/Personal/TLS-Checker/TLS-Checker/TLS-Checker/main.py\", line 79, in dns_resolve\n    resp = await asyncio.wait_for(\n           ^^^^^^^^^^^^^^^^^^^^^^^\n  File \"/usr/local/lib/python3.12/asyncio/tasks.py\", line 520, in wait_for\n    return await fut\n           ^^^^^^^^^\naiodns.error.DNSError: (1, 'DNS server returned answer with no data')", "timestamp": "2024-05-28T08:42:56.317190+00:00", "logger": "__main__", "module": "main", "function": "dns_resolve", "line": 94, "task_name": "Task-18", "filename": "main.py", "exc_text": null, "msecs": 317.0, "relativeCreated": 7148.814678192139, "thread": 139786612279104, "threadName": "MainThread", "processName": "MainProcess", "process": 10662, "taskName": "Task-18"}
{"level": "ERROR", "message": "DNSError: (1, 'DNS server returned answer with no data')\nTraceback (most recent call last):\n  File \"/home/iman/Personal/TLS-Checker/TLS-Checker/TLS-Checker/main.py\", line 79, in dns_resolve\n    resp = await asyncio.wait_for(\n           ^^^^^^^^^^^^^^^^^^^^^^^\n  File \"/usr/local/lib/python3.12/asyncio/tasks.py\", line 520, in wait_for\n    return await fut\n           ^^^^^^^^^\naiodns.error.DNSError: (1, 'DNS server returned answer with no data')", "timestamp": "2024-05-28T08:42:56.317533+00:00", "logger": "__main__", "module": "main", "function": "dns_resolve", "line": 94, "task_name": "Task-16", "filename": "main.py", "exc_text": null, "msecs": 317.0, "relativeCreated": 7149.158000946045, "thread": 139786612279104, "threadName": "MainThread", "processName": "MainProcess", "process": 10662, "taskName": "Task-16"}
{"level": "ERROR", "message": "DNSError: (1, 'DNS server returned answer with no data')\nTraceback (most recent call last):\n  File \"/home/iman/Personal/TLS-Checker/TLS-Checker/TLS-Checker/main.py\", line 79, in dns_resolve\n    resp = await asyncio.wait_for(\n           ^^^^^^^^^^^^^^^^^^^^^^^\n  File \"/usr/local/lib/python3.12/asyncio/tasks.py\", line 520, in wait_for\n    return await fut\n           ^^^^^^^^^\naiodns.error.DNSError: (1, 'DNS server returned answer with no data')", "timestamp": "2024-05-28T08:42:56.318081+00:00", "logger": "__main__", "module": "main", "function": "dns_resolve", "line": 94, "task_name": "Task-12", "filename": "main.py", "exc_text": null, "msecs": 318.0, "relativeCreated": 7149.706125259399, "thread": 139786612279104, "threadName": "MainThread", "processName": "MainProcess", "process": 10662, "taskName": "Task-12"}
{"level": "ERROR", "message": "DNSError: (1, 'DNS server returned answer with no data')\nTraceback (most recent call last):\n  File \"/home/iman/Personal/TLS-Checker/TLS-Checker/TLS-Checker/main.py\", line 79, in dns_resolve\n    resp = await asyncio.wait_for(\n           ^^^^^^^^^^^^^^^^^^^^^^^\n  File \"/usr/local/lib/python3.12/asyncio/tasks.py\", line 520, in wait_for\n    return await fut\n           ^^^^^^^^^\naiodns.error.DNSError: (1, 'DNS server returned answer with no data')", "timestamp": "2024-05-28T08:42:56.320102+00:00", "logger": "__main__", "module": "main", "function": "dns_resolve", "line": 94, "task_name": "Task-21", "filename": "main.py", "exc_text": null, "msecs": 320.0, "relativeCreated": 7151.727199554443, "thread": 139786612279104, "threadName": "MainThread", "processName": "MainProcess", "process": 10662, "taskName": "Task-21"}
{"level": "ERROR", "message": "DNSError: (1, 'DNS server returned answer with no data')\nTraceback (most recent call last):\n  File \"/home/iman/Personal/TLS-Checker/TLS-Checker/TLS-Checker/main.py\", line 79, in dns_resolve\n    resp = await asyncio.wait_for(\n           ^^^^^^^^^^^^^^^^^^^^^^^\n  File \"/usr/local/lib/python3.12/asyncio/tasks.py\", line 520, in wait_for\n    return await fut\n           ^^^^^^^^^\naiodns.error.DNSError: (1, 'DNS server returned answer with no data')", "timestamp": "2024-05-28T08:42:56.322221+00:00", "logger": "__main__", "module": "main", "function": "dns_resolve", "line": 94, "task_name": "Task-47", "filename": "main.py", "exc_text": null, "msecs": 322.0, "relativeCreated": 7153.84578704834, "thread": 139786612279104, "threadName": "MainThread", "processName": "MainProcess", "process": 10662, "taskName": "Task-47"}
{"level": "ERROR", "message": "DNSError: (1, 'DNS server returned answer with no data')\nTraceback (most recent call last):\n  File \"/home/iman/Personal/TLS-Checker/TLS-Checker/TLS-Checker/main.py\", line 79, in dns_resolve\n    resp = await asyncio.wait_for(\n           ^^^^^^^^^^^^^^^^^^^^^^^\n  File \"/usr/local/lib/python3.12/asyncio/tasks.py\", line 520, in wait_for\n    return await fut\n           ^^^^^^^^^\naiodns.error.DNSError: (1, 'DNS server returned answer with no data')", "timestamp": "2024-05-28T08:42:56.347083+00:00", "logger": "__main__", "module": "main", "function": "dns_resolve", "line": 94, "task_name": "Task-29", "filename": "main.py", "exc_text": null, "msecs": 347.0, "relativeCreated": 7178.708076477051, "thread": 139786612279104, "threadName": "MainThread", "processName": "MainProcess", "process": 10662, "taskName": "Task-29"}
{"level": "ERROR", "message": "DNSError: (1, 'DNS server returned answer with no data')\nTraceback (most recent call last):\n  File \"/home/iman/Personal/TLS-Checker/TLS-Checker/TLS-Checker/main.py\", line 79, in dns_resolve\n    resp = await asyncio.wait_for(\n           ^^^^^^^^^^^^^^^^^^^^^^^\n  File \"/usr/local/lib/python3.12/asyncio/tasks.py\", line 520, in wait_for\n    return await fut\n           ^^^^^^^^^\naiodns.error.DNSError: (1, 'DNS server returned answer with no data')", "timestamp": "2024-05-28T08:42:56.349401+00:00", "logger": "__main__", "module": "main", "function": "dns_resolve", "line": 94, "task_name": "Task-34", "filename": "main.py", "exc_text": null, "msecs": 349.0, "relativeCreated": 7181.025743484497, "thread": 139786612279104, "threadName": "MainThread", "processName": "MainProcess", "process": 10662, "taskName": "Task-34"}
{"level": "ERROR", "message": "DNSError: (1, 'DNS server returned answer with no data')\nTraceback (most recent call last):\n  File \"/home/iman/Personal/TLS-Checker/TLS-Checker/TLS-Checker/main.py\", line 79, in dns_resolve\n    resp = await asyncio.wait_for(\n           ^^^^^^^^^^^^^^^^^^^^^^^\n  File \"/usr/local/lib/python3.12/asyncio/tasks.py\", line 520, in wait_for\n    return await fut\n           ^^^^^^^^^\naiodns.error.DNSError: (1, 'DNS server returned answer with no data')", "timestamp": "2024-05-28T08:42:56.350300+00:00", "logger": "__main__", "module": "main", "function": "dns_resolve", "line": 94, "task_name": "Task-49", "filename": "main.py", "exc_text": null, "msecs": 350.0, "relativeCreated": 7181.924819946289, "thread": 139786612279104, "threadName": "MainThread", "processName": "MainProcess", "process": 10662, "taskName": "Task-49"}
{"level": "ERROR", "message": "DNSError: (1, 'DNS server returned answer with no data')\nTraceback (most recent call last):\n  File \"/home/iman/Personal/TLS-Checker/TLS-Checker/TLS-Checker/main.py\", line 79, in dns_resolve\n    resp = await asyncio.wait_for(\n           ^^^^^^^^^^^^^^^^^^^^^^^\n  File \"/usr/local/lib/python3.12/asyncio/tasks.py\", line 520, in wait_for\n    return await fut\n           ^^^^^^^^^\naiodns.error.DNSError: (1, 'DNS server returned answer with no data')", "timestamp": "2024-05-28T08:42:56.350760+00:00", "logger": "__main__", "module": "main", "function": "dns_resolve", "line": 94, "task_name": "Task-43", "filename": "main.py", "exc_text": null, "msecs": 350.0, "relativeCreated": 7182.384729385376, "thread": 139786612279104, "threadName": "MainThread", "processName": "MainProcess", "process": 10662, "taskName": "Task-43"}
{"level": "ERROR", "message": "DNSError: (1, 'DNS server returned answer with no data')\nTraceback (most recent call last):\n  File \"/home/iman/Personal/TLS-Checker/TLS-Checker/TLS-Checker/main.py\", line 79, in dns_resolve\n    resp = await asyncio.wait_for(\n           ^^^^^^^^^^^^^^^^^^^^^^^\n  File \"/usr/local/lib/python3.12/asyncio/tasks.py\", line 520, in wait_for\n    return await fut\n           ^^^^^^^^^\naiodns.error.DNSError: (1, 'DNS server returned answer with no data')", "timestamp": "2024-05-28T08:42:56.352458+00:00", "logger": "__main__", "module": "main", "function": "dns_resolve", "line": 94, "task_name": "Task-63", "filename": "main.py", "exc_text": null, "msecs": 352.0, "relativeCreated": 7184.082984924316, "thread": 139786612279104, "threadName": "MainThread", "processName": "MainProcess", "process": 10662, "taskName": "Task-63"}
{"level": "ERROR", "message": "DNSError: (1, 'DNS server returned answer with no data')\nTraceback (most recent call last):\n  File \"/home/iman/Personal/TLS-Checker/TLS-Checker/TLS-Checker/main.py\", line 79, in dns_resolve\n    resp = await asyncio.wait_for(\n           ^^^^^^^^^^^^^^^^^^^^^^^\n  File \"/usr/local/lib/python3.12/asyncio/tasks.py\", line 520, in wait_for\n    return await fut\n           ^^^^^^^^^\naiodns.error.DNSError: (1, 'DNS server returned answer with no data')", "timestamp": "2024-05-28T08:42:56.353619+00:00", "logger": "__main__", "module": "main", "function": "dns_resolve", "line": 94, "task_name": "Task-39", "filename": "main.py", "exc_text": null, "msecs": 353.0, "relativeCreated": 7185.243606567383, "thread": 139786612279104, "threadName": "MainThread", "processName": "MainProcess", "process": 10662, "taskName": "Task-39"}
{"level": "ERROR", "message": "DNSError: (1, 'DNS server returned answer with no data')\nTraceback (most recent call last):\n  File \"/home/iman/Personal/TLS-Checker/TLS-Checker/TLS-Checker/main.py\", line 79, in dns_resolve\n    resp = await asyncio.wait_for(\n           ^^^^^^^^^^^^^^^^^^^^^^^\n  File \"/usr/local/lib/python3.12/asyncio/tasks.py\", line 520, in wait_for\n    return await fut\n           ^^^^^^^^^\naiodns.error.DNSError: (1, 'DNS server returned answer with no data')", "timestamp": "2024-05-28T08:42:56.354048+00:00", "logger": "__main__", "module": "main", "function": "dns_resolve", "line": 94, "task_name": "Task-99", "filename": "main.py", "exc_text": null, "msecs": 354.0, "relativeCreated": 7185.6725215911865, "thread": 139786612279104, "threadName": "MainThread", "processName": "MainProcess", "process": 10662, "taskName": "Task-99"}
{"level": "ERROR", "message": "DNSError: (1, 'DNS server returned answer with no data')\nTraceback (most recent call last):\n  File \"/home/iman/Personal/TLS-Checker/TLS-Checker/TLS-Checker/main.py\", line 79, in dns_resolve\n    resp = await asyncio.wait_for(\n           ^^^^^^^^^^^^^^^^^^^^^^^\n  File \"/usr/local/lib/python3.12/asyncio/tasks.py\", line 520, in wait_for\n    return await fut\n           ^^^^^^^^^\naiodns.error.DNSError: (1, 'DNS server returned answer with no data')", "timestamp": "2024-05-28T08:42:56.354958+00:00", "logger": "__main__", "module": "main", "function": "dns_resolve", "line": 94, "task_name": "Task-91", "filename": "main.py", "exc_text": null, "msecs": 354.0, "relativeCreated": 7186.583042144775, "thread": 139786612279104, "threadName": "MainThread", "processName": "MainProcess", "process": 10662, "taskName": "Task-91"}
{"level": "ERROR", "message": "DNSError: (1, 'DNS server returned answer with no data')\nTraceback (most recent call last):\n  File \"/home/iman/Personal/TLS-Checker/TLS-Checker/TLS-Checker/main.py\", line 79, in dns_resolve\n    resp = await asyncio.wait_for(\n           ^^^^^^^^^^^^^^^^^^^^^^^\n  File \"/usr/local/lib/python3.12/asyncio/tasks.py\", line 520, in wait_for\n    return await fut\n           ^^^^^^^^^\naiodns.error.DNSError: (1, 'DNS server returned answer with no data')", "timestamp": "2024-05-28T08:42:56.355912+00:00", "logger": "__main__", "module": "main", "function": "dns_resolve", "line": 94, "task_name": "Task-72", "filename": "main.py", "exc_text": null, "msecs": 355.0, "relativeCreated": 7187.53719329834, "thread": 139786612279104, "threadName": "MainThread", "processName": "MainProcess", "process": 10662, "taskName": "Task-72"}
{"level": "ERROR", "message": "DNSError: (1, 'DNS server returned answer with no data')\nTraceback (most recent call last):\n  File \"/home/iman/Personal/TLS-Checker/TLS-Checker/TLS-Checker/main.py\", line 79, in dns_resolve\n    resp = await asyncio.wait_for(\n           ^^^^^^^^^^^^^^^^^^^^^^^\n  File \"/usr/local/lib/python3.12/asyncio/tasks.py\", line 520, in wait_for\n    return await fut\n           ^^^^^^^^^\naiodns.error.DNSError: (1, 'DNS server returned answer with no data')", "timestamp": "2024-05-28T08:42:56.360526+00:00", "logger": "__main__", "module": "main", "function": "dns_resolve", "line": 94, "task_name": "Task-100", "filename": "main.py", "exc_text": null, "msecs": 360.0, "relativeCreated": 7192.151308059692, "thread": 139786612279104, "threadName": "MainThread", "processName": "MainProcess", "process": 10662, "taskName": "Task-100"}
{"level": "ERROR", "message": "DNSError: (1, 'DNS server returned answer with no data')\nTraceback (most recent call last):\n  File \"/home/iman/Personal/TLS-Checker/TLS-Checker/TLS-Checker/main.py\", line 79, in dns_resolve\n    resp = await asyncio.wait_for(\n           ^^^^^^^^^^^^^^^^^^^^^^^\n  File \"/usr/local/lib/python3.12/asyncio/tasks.py\", line 520, in wait_for\n    return await fut\n           ^^^^^^^^^\naiodns.error.DNSError: (1, 'DNS server returned answer with no data')", "timestamp": "2024-05-28T08:42:56.404010+00:00", "logger": "__main__", "module": "main", "function": "dns_resolve", "line": 94, "task_name": "Task-70", "filename": "main.py", "exc_text": null, "msecs": 404.0, "relativeCreated": 7235.635042190552, "thread": 139786612279104, "threadName": "MainThread", "processName": "MainProcess", "process": 10662, "taskName": "Task-70"}
{"level": "ERROR", "message": "DNSError: (1, 'DNS server returned answer with no data')\nTraceback (most recent call last):\n  File \"/home/iman/Personal/TLS-Checker/TLS-Checker/TLS-Checker/main.py\", line 79, in dns_resolve\n    resp = await asyncio.wait_for(\n           ^^^^^^^^^^^^^^^^^^^^^^^\n  File \"/usr/local/lib/python3.12/asyncio/tasks.py\", line 520, in wait_for\n    return await fut\n           ^^^^^^^^^\naiodns.error.DNSError: (1, 'DNS server returned answer with no data')", "timestamp": "2024-05-28T08:42:56.420501+00:00", "logger": "__main__", "module": "main", "function": "dns_resolve", "line": 94, "task_name": "Task-13", "filename": "main.py", "exc_text": null, "msecs": 420.0, "relativeCreated": 7252.126216888428, "thread": 139786612279104, "threadName": "MainThread", "processName": "MainProcess", "process": 10662, "taskName": "Task-13"}
{"level": "ERROR", "message": "DNSError: (1, 'DNS server returned answer with no data')\nTraceback (most recent call last):\n  File \"/home/iman/Personal/TLS-Checker/TLS-Checker/TLS-Checker/main.py\", line 67, in dns_resolve\n    resp = await asyncio.wait_for(\n           ^^^^^^^^^^^^^^^^^^^^^^^\n  File \"/usr/local/lib/python3.12/asyncio/tasks.py\", line 520, in wait_for\n    return await fut\n           ^^^^^^^^^\naiodns.error.DNSError: (1, 'DNS server returned answer with no data')", "timestamp": "2024-05-28T08:42:56.446091+00:00", "logger": "__main__", "module": "main", "function": "dns_resolve", "line": 94, "task_name": "Task-84", "filename": "main.py", "exc_text": null, "msecs": 446.0, "relativeCreated": 7277.7159214019775, "thread": 139786612279104, "threadName": "MainThread", "processName": "MainProcess", "process": 10662, "taskName": "Task-84"}
{"level": "ERROR", "message": "DNSError: (1, 'DNS server returned answer with no data')\nTraceback (most recent call last):\n  File \"/home/iman/Personal/TLS-Checker/TLS-Checker/TLS-Checker/main.py\", line 79, in dns_resolve\n    resp = await asyncio.wait_for(\n           ^^^^^^^^^^^^^^^^^^^^^^^\n  File \"/usr/local/lib/python3.12/asyncio/tasks.py\", line 520, in wait_for\n    return await fut\n           ^^^^^^^^^\naiodns.error.DNSError: (1, 'DNS server returned answer with no data')", "timestamp": "2024-05-28T08:42:56.449325+00:00", "logger": "__main__", "module": "main", "function": "dns_resolve", "line": 94, "task_name": "Task-69", "filename": "main.py", "exc_text": null, "msecs": 449.0, "relativeCreated": 7280.950307846069, "thread": 139786612279104, "threadName": "MainThread", "processName": "MainProcess", "process": 10662, "taskName": "Task-69"}
{"level": "ERROR", "message": "DNSError: (1, 'DNS server returned answer with no data')\nTraceback (most recent call last):\n  File \"/home/iman/Personal/TLS-Checker/TLS-Checker/TLS-Checker/main.py\", line 79, in dns_resolve\n    resp = await asyncio.wait_for(\n           ^^^^^^^^^^^^^^^^^^^^^^^\n  File \"/usr/local/lib/python3.12/asyncio/tasks.py\", line 520, in wait_for\n    return await fut\n           ^^^^^^^^^\naiodns.error.DNSError: (1, 'DNS server returned answer with no data')", "timestamp": "2024-05-28T08:42:56.456745+00:00", "logger": "__main__", "module": "main", "function": "dns_resolve", "line": 94, "task_name": "Task-57", "filename": "main.py", "exc_text": null, "msecs": 456.0, "relativeCreated": 7288.370370864868, "thread": 139786612279104, "threadName": "MainThread", "processName": "MainProcess", "process": 10662, "taskName": "Task-57"}
{"level": "ERROR", "message": "DNSError: (1, 'DNS server returned answer with no data')\nTraceback (most recent call last):\n  File \"/home/iman/Personal/TLS-Checker/TLS-Checker/TLS-Checker/main.py\", line 79, in dns_resolve\n    resp = await asyncio.wait_for(\n           ^^^^^^^^^^^^^^^^^^^^^^^\n  File \"/usr/local/lib/python3.12/asyncio/tasks.py\", line 520, in wait_for\n    return await fut\n           ^^^^^^^^^\naiodns.error.DNSError: (1, 'DNS server returned answer with no data')", "timestamp": "2024-05-28T08:42:56.457266+00:00", "logger": "__main__", "module": "main", "function": "dns_resolve", "line": 94, "task_name": "Task-58", "filename": "main.py", "exc_text": null, "msecs": 457.0, "relativeCreated": 7288.890600204468, "thread": 139786612279104, "threadName": "MainThread", "processName": "MainProcess", "process": 10662, "taskName": "Task-58"}
{"level": "ERROR", "message": "DNSError: (1, 'DNS server returned answer with no data')\nTraceback (most recent call last):\n  File \"/home/iman/Personal/TLS-Checker/TLS-Checker/TLS-Checker/main.py\", line 79, in dns_resolve\n    resp = await asyncio.wait_for(\n           ^^^^^^^^^^^^^^^^^^^^^^^\n  File \"/usr/local/lib/python3.12/asyncio/tasks.py\", line 520, in wait_for\n    return await fut\n           ^^^^^^^^^\naiodns.error.DNSError: (1, 'DNS server returned answer with no data')", "timestamp": "2024-05-28T08:42:56.471474+00:00", "logger": "__main__", "module": "main", "function": "dns_resolve", "line": 94, "task_name": "Task-50", "filename": "main.py", "exc_text": null, "msecs": 471.0, "relativeCreated": 7303.0993938446045, "thread": 139786612279104, "threadName": "MainThread", "processName": "MainProcess", "process": 10662, "taskName": "Task-50"}
{"level": "ERROR", "message": "DNSError: (1, 'DNS server returned answer with no data')\nTraceback (most recent call last):\n  File \"/home/iman/Personal/TLS-Checker/TLS-Checker/TLS-Checker/main.py\", line 79, in dns_resolve\n    resp = await asyncio.wait_for(\n           ^^^^^^^^^^^^^^^^^^^^^^^\n  File \"/usr/local/lib/python3.12/asyncio/tasks.py\", line 520, in wait_for\n    return await fut\n           ^^^^^^^^^\naiodns.error.DNSError: (1, 'DNS server returned answer with no data')", "timestamp": "2024-05-28T08:42:56.512244+00:00", "logger": "__main__", "module": "main", "function": "dns_resolve", "line": 94, "task_name": "Task-90", "filename": "main.py", "exc_text": null, "msecs": 512.0, "relativeCreated": 7343.868732452393, "thread": 139786612279104, "threadName": "MainThread", "processName": "MainProcess", "process": 10662, "taskName": "Task-90"}
{"level": "ERROR", "message": "DNSError: (1, 'DNS server returned answer with no data')\nTraceback (most recent call last):\n  File \"/home/iman/Personal/TLS-Checker/TLS-Checker/TLS-Checker/main.py\", line 79, in dns_resolve\n    resp = await asyncio.wait_for(\n           ^^^^^^^^^^^^^^^^^^^^^^^\n  File \"/usr/local/lib/python3.12/asyncio/tasks.py\", line 520, in wait_for\n    return await fut\n           ^^^^^^^^^\naiodns.error.DNSError: (1, 'DNS server returned answer with no data')", "timestamp": "2024-05-28T08:42:56.512957+00:00", "logger": "__main__", "module": "main", "function": "dns_resolve", "line": 94, "task_name": "Task-11", "filename": "main.py", "exc_text": null, "msecs": 512.0, "relativeCreated": 7344.581604003906, "thread": 139786612279104, "threadName": "MainThread", "processName": "MainProcess", "process": 10662, "taskName": "Task-11"}
{"level": "ERROR", "message": "DNSError: (1, 'DNS server returned answer with no data')\nTraceback (most recent call last):\n  File \"/home/iman/Personal/TLS-Checker/TLS-Checker/TLS-Checker/main.py\", line 79, in dns_resolve\n    resp = await asyncio.wait_for(\n           ^^^^^^^^^^^^^^^^^^^^^^^\n  File \"/usr/local/lib/python3.12/asyncio/tasks.py\", line 520, in wait_for\n    return await fut\n           ^^^^^^^^^\naiodns.error.DNSError: (1, 'DNS server returned answer with no data')", "timestamp": "2024-05-28T08:42:56.580361+00:00", "logger": "__main__", "module": "main", "function": "dns_resolve", "line": 94, "task_name": "Task-67", "filename": "main.py", "exc_text": null, "msecs": 580.0, "relativeCreated": 7411.985874176025, "thread": 139786612279104, "threadName": "MainThread", "processName": "MainProcess", "process": 10662, "taskName": "Task-67"}
{"level": "ERROR", "message": "DNSError: (1, 'DNS server returned answer with no data')\nTraceback (most recent call last):\n  File \"/home/iman/Personal/TLS-Checker/TLS-Checker/TLS-Checker/main.py\", line 79, in dns_resolve\n    resp = await asyncio.wait_for(\n           ^^^^^^^^^^^^^^^^^^^^^^^\n  File \"/usr/local/lib/python3.12/asyncio/tasks.py\", line 520, in wait_for\n    return await fut\n           ^^^^^^^^^\naiodns.error.DNSError: (1, 'DNS server returned answer with no data')", "timestamp": "2024-05-28T08:42:56.603041+00:00", "logger": "__main__", "module": "main", "function": "dns_resolve", "line": 94, "task_name": "Task-17", "filename": "main.py", "exc_text": null, "msecs": 603.0, "relativeCreated": 7434.666156768799, "thread": 139786612279104, "threadName": "MainThread", "processName": "MainProcess", "process": 10662, "taskName": "Task-17"}
{"level": "ERROR", "message": "DNSError: (1, 'DNS server returned answer with no data')\nTraceback (most recent call last):\n  File \"/home/iman/Personal/TLS-Checker/TLS-Checker/TLS-Checker/main.py\", line 79, in dns_resolve\n    resp = await asyncio.wait_for(\n           ^^^^^^^^^^^^^^^^^^^^^^^\n  File \"/usr/local/lib/python3.12/asyncio/tasks.py\", line 520, in wait_for\n    return await fut\n           ^^^^^^^^^\naiodns.error.DNSError: (1, 'DNS server returned answer with no data')", "timestamp": "2024-05-28T08:42:57.031280+00:00", "logger": "__main__", "module": "main", "function": "dns_resolve", "line": 94, "task_name": "Task-38", "filename": "main.py", "exc_text": null, "msecs": 31.0, "relativeCreated": 7862.9045486450195, "thread": 139786612279104, "threadName": "MainThread", "processName": "MainProcess", "process": 10662, "taskName": "Task-38"}
{"level": "ERROR", "message": "DNSError: (1, 'DNS server returned answer with no data')\nTraceback (most recent call last):\n  File \"/home/iman/Personal/TLS-Checker/TLS-Checker/TLS-Checker/main.py\", line 79, in dns_resolve\n    resp = await asyncio.wait_for(\n           ^^^^^^^^^^^^^^^^^^^^^^^\n  File \"/usr/local/lib/python3.12/asyncio/tasks.py\", line 520, in wait_for\n    return await fut\n           ^^^^^^^^^\naiodns.error.DNSError: (1, 'DNS server returned answer with no data')", "timestamp": "2024-05-28T08:42:58.112957+00:00", "logger": "__main__", "module": "main", "function": "dns_resolve", "line": 94, "task_name": "Task-25", "filename": "main.py", "exc_text": null, "msecs": 112.0, "relativeCreated": 8944.581985473633, "thread": 139786612279104, "threadName": "MainThread", "processName": "MainProcess", "process": 10662, "taskName": "Task-25"}
{"level": "ERROR", "message": "Timeout Error: \nTraceback (most recent call last):\n  File \"/usr/local/lib/python3.12/asyncio/tasks.py\", line 520, in wait_for\n    return await fut\n           ^^^^^^^^^\nasyncio.exceptions.CancelledError\n\nThe above exception was the direct cause of the following exception:\n\nTraceback (most recent call last):\n  File \"/home/iman/Personal/TLS-Checker/TLS-Checker/TLS-Checker/main.py\", line 79, in dns_resolve\n    resp = await asyncio.wait_for(\n           ^^^^^^^^^^^^^^^^^^^^^^^\n  File \"/usr/local/lib/python3.12/asyncio/tasks.py\", line 519, in wait_for\n    async with timeouts.timeout(timeout):\n  File \"/usr/local/lib/python3.12/asyncio/timeouts.py\", line 115, in __aexit__\n    raise TimeoutError from exc_val\nTimeoutError", "timestamp": "2024-05-28T08:42:59.162251+00:00", "logger": "__main__", "module": "main", "function": "dns_resolve", "line": 96, "task_name": "Task-6", "filename": "main.py", "exc_text": null, "msecs": 162.0, "relativeCreated": 9993.875980377197, "thread": 139786612279104, "threadName": "MainThread", "processName": "MainProcess", "process": 10662, "taskName": "Task-6"}
{"level": "ERROR", "message": "Timeout Error: \nTraceback (most recent call last):\n  File \"/usr/local/lib/python3.12/asyncio/tasks.py\", line 520, in wait_for\n    return await fut\n           ^^^^^^^^^\nasyncio.exceptions.CancelledError\n\nThe above exception was the direct cause of the following exception:\n\nTraceback (most recent call last):\n  File \"/home/iman/Personal/TLS-Checker/TLS-Checker/TLS-Checker/main.py\", line 79, in dns_resolve\n    resp = await asyncio.wait_for(\n           ^^^^^^^^^^^^^^^^^^^^^^^\n  File \"/usr/local/lib/python3.12/asyncio/tasks.py\", line 519, in wait_for\n    async with timeouts.timeout(timeout):\n  File \"/usr/local/lib/python3.12/asyncio/timeouts.py\", line 115, in __aexit__\n    raise TimeoutError from exc_val\nTimeoutError", "timestamp": "2024-05-28T08:42:59.166790+00:00", "logger": "__main__", "module": "main", "function": "dns_resolve", "line": 96, "task_name": "Task-19", "filename": "main.py", "exc_text": null, "msecs": 166.0, "relativeCreated": 9998.414516448975, "thread": 139786612279104, "threadName": "MainThread", "processName": "MainProcess", "process": 10662, "taskName": "Task-19"}
{"level": "ERROR", "message": "Timeout Error: \nTraceback (most recent call last):\n  File \"/usr/local/lib/python3.12/asyncio/tasks.py\", line 520, in wait_for\n    return await fut\n           ^^^^^^^^^\nasyncio.exceptions.CancelledError\n\nThe above exception was the direct cause of the following exception:\n\nTraceback (most recent call last):\n  File \"/home/iman/Personal/TLS-Checker/TLS-Checker/TLS-Checker/main.py\", line 79, in dns_resolve\n    resp = await asyncio.wait_for(\n           ^^^^^^^^^^^^^^^^^^^^^^^\n  File \"/usr/local/lib/python3.12/asyncio/tasks.py\", line 519, in wait_for\n    async with timeouts.timeout(timeout):\n  File \"/usr/local/lib/python3.12/asyncio/timeouts.py\", line 115, in __aexit__\n    raise TimeoutError from exc_val\nTimeoutError", "timestamp": "2024-05-28T08:42:59.172910+00:00", "logger": "__main__", "module": "main", "function": "dns_resolve", "line": 96, "task_name": "Task-9", "filename": "main.py", "exc_text": null, "msecs": 172.0, "relativeCreated": 10004.53495979309, "thread": 139786612279104, "threadName": "MainThread", "processName": "MainProcess", "process": 10662, "taskName": "Task-9"}
{"level": "INFO", "message": "Saving data into output.db was successfully", "timestamp": "2024-05-28T08:42:59.209710+00:00", "logger": "__main__", "module": "main", "function": "main", "line": 242, "task_name": "Task-1", "filename": "main.py", "exc_text": null, "msecs": 209.0, "relativeCreated": 10041.334867477417, "thread": 139786612279104, "threadName": "MainThread", "processName": "MainProcess", "process": 10662, "taskName": "Task-1"}
{"level": "INFO", "message": "Successfully converted", "timestamp": "2024-05-28T08:42:59.246536+00:00", "logger": "csv_convertor", "module": "csv_convertor", "function": "convertor", "line": 109, "task_name": "Task-1", "filename": "csv_convertor.py", "exc_text": null, "msecs": 246.0, "relativeCreated": 10078.161001205444, "thread": 139786612279104, "threadName": "MainThread", "processName": "MainProcess", "process": 10662, "taskName": "Task-1"}
{"level": "INFO", "message": "Database successfully converted to csv file", "timestamp": "2024-05-28T08:42:59.247525+00:00", "logger": "__main__", "module": "main", "function": "main", "line": 245, "task_name": "Task-1", "filename": "main.py", "exc_text": null, "msecs": 247.0, "relativeCreated": 10079.150199890137, "thread": 139786612279104, "threadName": "MainThread", "processName": "MainProcess", "process": 10662, "taskName": "Task-1"}
{"level": "INFO", "message": "App was finished gracefully", "timestamp": "2024-05-28T08:42:59.341835+00:00", "logger": "__main__", "module": "main", "function": "<module>", "line": 260, "task_name": null, "filename": "main.py", "exc_text": null, "msecs": 341.0, "relativeCreated": 10173.459529876709, "thread": 139786612279104, "threadName": "MainThread", "processName": "MainProcess", "process": 10662, "taskName": null}
{"level": "INFO", "message": "Start reading input.csv", "timestamp": "2024-05-28T08:50:26.128143+00:00", "logger": "__main__", "module": "main", "function": "open_csv", "line": 103, "task_name": "Task-1", "filename": "main.py", "exc_text": null, "msecs": 128.0, "relativeCreated": 151.02434158325195, "thread": 140579432793920, "threadName": "MainThread", "processName": "MainProcess", "process": 11044, "taskName": "Task-1"}
{"level": "INFO", "message": "Successfully extracted domains from input.csv", "timestamp": "2024-05-28T08:50:27.623322+00:00", "logger": "__main__", "module": "main", "function": "open_csv", "line": 112, "task_name": "Task-1", "filename": "main.py", "exc_text": null, "msecs": 623.0, "relativeCreated": 1646.2032794952393, "thread": 140579432793920, "threadName": "MainThread", "processName": "MainProcess", "process": 11044, "taskName": "Task-1"}
{"level": "INFO", "message": "Start config before scanning", "timestamp": "2024-05-28T08:50:27.623443+00:00", "logger": "__main__", "module": "main", "function": "create_tasks", "line": 157, "task_name": "Task-1", "filename": "main.py", "exc_text": null, "msecs": 623.0, "relativeCreated": 1646.324634552002, "thread": 140579432793920, "threadName": "MainThread", "processName": "MainProcess", "process": 11044, "taskName": "Task-1"}
{"level": "INFO", "message": "domain_chunk was set to 10", "timestamp": "2024-05-28T08:50:30.229745+00:00", "logger": "__main__", "module": "main", "function": "create_tasks", "line": 171, "task_name": "Task-1", "filename": "main.py", "exc_text": null, "msecs": 229.0, "relativeCreated": 4252.626895904541, "thread": 140579432793920, "threadName": "MainThread", "processName": "MainProcess", "process": 11044, "taskName": "Task-1"}
{"level": "ERROR", "message": "Invalid value for active tasks: invalid literal for int() with base 10: ''", "timestamp": "2024-05-28T08:50:31.876655+00:00", "logger": "__main__", "module": "main", "function": "create_tasks", "line": 192, "task_name": "Task-1", "filename": "main.py", "exc_text": null, "msecs": 876.0, "relativeCreated": 5899.536609649658, "thread": 140579432793920, "threadName": "MainThread", "processName": "MainProcess", "process": 11044, "taskName": "Task-1"}
{"level": "ERROR", "message": "Invalid value for timeout: invalid literal for int() with base 10: ''", "timestamp": "2024-05-28T08:50:32.496134+00:00", "logger": "__main__", "module": "main", "function": "create_tasks", "line": 203, "task_name": "Task-1", "filename": "main.py", "exc_text": null, "msecs": 496.0, "relativeCreated": 6519.015789031982, "thread": 140579432793920, "threadName": "MainThread", "processName": "MainProcess", "process": 11044, "taskName": "Task-1"}
{"level": "ERROR", "message": "DNSError: (1, 'DNS server returned answer with no data')\nTraceback (most recent call last):\n  File \"/home/iman/Personal/TLS-Checker/TLS-Checker/TLS-Checker/main.py\", line 79, in dns_resolve\n    resp = await asyncio.wait_for(\n           ^^^^^^^^^^^^^^^^^^^^^^^\n  File \"/usr/local/lib/python3.12/asyncio/tasks.py\", line 520, in wait_for\n    return await fut\n           ^^^^^^^^^\naiodns.error.DNSError: (1, 'DNS server returned answer with no data')", "timestamp": "2024-05-28T08:50:32.577141+00:00", "logger": "__main__", "module": "main", "function": "dns_resolve", "line": 94, "task_name": "Task-7", "filename": "main.py", "exc_text": null, "msecs": 577.0, "relativeCreated": 6600.022554397583, "thread": 140579432793920, "threadName": "MainThread", "processName": "MainProcess", "process": 11044, "taskName": "Task-7"}
{"level": "ERROR", "message": "DNSError: (1, 'DNS server returned answer with no data')\nTraceback (most recent call last):\n  File \"/home/iman/Personal/TLS-Checker/TLS-Checker/TLS-Checker/main.py\", line 79, in dns_resolve\n    resp = await asyncio.wait_for(\n           ^^^^^^^^^^^^^^^^^^^^^^^\n  File \"/usr/local/lib/python3.12/asyncio/tasks.py\", line 520, in wait_for\n    return await fut\n           ^^^^^^^^^\naiodns.error.DNSError: (1, 'DNS server returned answer with no data')", "timestamp": "2024-05-28T08:50:32.578777+00:00", "logger": "__main__", "module": "main", "function": "dns_resolve", "line": 94, "task_name": "Task-8", "filename": "main.py", "exc_text": null, "msecs": 578.0, "relativeCreated": 6601.658344268799, "thread": 140579432793920, "threadName": "MainThread", "processName": "MainProcess", "process": 11044, "taskName": "Task-8"}
{"level": "ERROR", "message": "DNSError: (1, 'DNS server returned answer with no data')\nTraceback (most recent call last):\n  File \"/home/iman/Personal/TLS-Checker/TLS-Checker/TLS-Checker/main.py\", line 79, in dns_resolve\n    resp = await asyncio.wait_for(\n           ^^^^^^^^^^^^^^^^^^^^^^^\n  File \"/usr/local/lib/python3.12/asyncio/tasks.py\", line 520, in wait_for\n    return await fut\n           ^^^^^^^^^\naiodns.error.DNSError: (1, 'DNS server returned answer with no data')", "timestamp": "2024-05-28T08:50:32.581752+00:00", "logger": "__main__", "module": "main", "function": "dns_resolve", "line": 94, "task_name": "Task-10", "filename": "main.py", "exc_text": null, "msecs": 581.0, "relativeCreated": 6604.633808135986, "thread": 140579432793920, "threadName": "MainThread", "processName": "MainProcess", "process": 11044, "taskName": "Task-10"}
{"level": "ERROR", "message": "DNSError: (1, 'DNS server returned answer with no data')\nTraceback (most recent call last):\n  File \"/home/iman/Personal/TLS-Checker/TLS-Checker/TLS-Checker/main.py\", line 79, in dns_resolve\n    resp = await asyncio.wait_for(\n           ^^^^^^^^^^^^^^^^^^^^^^^\n  File \"/usr/local/lib/python3.12/asyncio/tasks.py\", line 520, in wait_for\n    return await fut\n           ^^^^^^^^^\naiodns.error.DNSError: (1, 'DNS server returned answer with no data')", "timestamp": "2024-05-28T08:50:32.582400+00:00", "logger": "__main__", "module": "main", "function": "dns_resolve", "line": 94, "task_name": "Task-11", "filename": "main.py", "exc_text": null, "msecs": 582.0, "relativeCreated": 6605.281352996826, "thread": 140579432793920, "threadName": "MainThread", "processName": "MainProcess", "process": 11044, "taskName": "Task-11"}
{"level": "ERROR", "message": "DNSError: (1, 'DNS server returned answer with no data')\nTraceback (most recent call last):\n  File \"/home/iman/Personal/TLS-Checker/TLS-Checker/TLS-Checker/main.py\", line 67, in dns_resolve\n    resp = await asyncio.wait_for(\n           ^^^^^^^^^^^^^^^^^^^^^^^\n  File \"/usr/local/lib/python3.12/asyncio/tasks.py\", line 520, in wait_for\n    return await fut\n           ^^^^^^^^^\naiodns.error.DNSError: (1, 'DNS server returned answer with no data')", "timestamp": "2024-05-28T08:50:32.614566+00:00", "logger": "__main__", "module": "main", "function": "dns_resolve", "line": 94, "task_name": "Task-4", "filename": "main.py", "exc_text": null, "msecs": 614.0, "relativeCreated": 6637.447118759155, "thread": 140579432793920, "threadName": "MainThread", "processName": "MainProcess", "process": 11044, "taskName": "Task-4"}
{"level": "ERROR", "message": "DNSError: (1, 'DNS server returned answer with no data')\nTraceback (most recent call last):\n  File \"/home/iman/Personal/TLS-Checker/TLS-Checker/TLS-Checker/main.py\", line 79, in dns_resolve\n    resp = await asyncio.wait_for(\n           ^^^^^^^^^^^^^^^^^^^^^^^\n  File \"/usr/local/lib/python3.12/asyncio/tasks.py\", line 520, in wait_for\n    return await fut\n           ^^^^^^^^^\naiodns.error.DNSError: (1, 'DNS server returned answer with no data')", "timestamp": "2024-05-28T08:50:32.657397+00:00", "logger": "__main__", "module": "main", "function": "dns_resolve", "line": 94, "task_name": "Task-2", "filename": "main.py", "exc_text": null, "msecs": 657.0, "relativeCreated": 6680.278062820435, "thread": 140579432793920, "threadName": "MainThread", "processName": "MainProcess", "process": 11044, "taskName": "Task-2"}
{"level": "ERROR", "message": "DNSError: (1, 'DNS server returned answer with no data')\nTraceback (most recent call last):\n  File \"/home/iman/Personal/TLS-Checker/TLS-Checker/TLS-Checker/main.py\", line 79, in dns_resolve\n    resp = await asyncio.wait_for(\n           ^^^^^^^^^^^^^^^^^^^^^^^\n  File \"/usr/local/lib/python3.12/asyncio/tasks.py\", line 520, in wait_for\n    return await fut\n           ^^^^^^^^^\naiodns.error.DNSError: (1, 'DNS server returned answer with no data')", "timestamp": "2024-05-28T08:50:32.659324+00:00", "logger": "__main__", "module": "main", "function": "dns_resolve", "line": 94, "task_name": "Task-5", "filename": "main.py", "exc_text": null, "msecs": 659.0, "relativeCreated": 6682.20591545105, "thread": 140579432793920, "threadName": "MainThread", "processName": "MainProcess", "process": 11044, "taskName": "Task-5"}
{"level": "ERROR", "message": "Timeout Error: \nTraceback (most recent call last):\n  File \"/usr/local/lib/python3.12/asyncio/tasks.py\", line 520, in wait_for\n    return await fut\n           ^^^^^^^^^\nasyncio.exceptions.CancelledError\n\nThe above exception was the direct cause of the following exception:\n\nTraceback (most recent call last):\n  File \"/home/iman/Personal/TLS-Checker/TLS-Checker/TLS-Checker/main.py\", line 79, in dns_resolve\n    resp = await asyncio.wait_for(\n           ^^^^^^^^^^^^^^^^^^^^^^^\n  File \"/usr/local/lib/python3.12/asyncio/tasks.py\", line 519, in wait_for\n    async with timeouts.timeout(timeout):\n  File \"/usr/local/lib/python3.12/asyncio/timeouts.py\", line 115, in __aexit__\n    raise TimeoutError from exc_val\nTimeoutError", "timestamp": "2024-05-28T08:50:35.724284+00:00", "logger": "__main__", "module": "main", "function": "dns_resolve", "line": 96, "task_name": "Task-3", "filename": "main.py", "exc_text": null, "msecs": 724.0, "relativeCreated": 9747.16591835022, "thread": 140579432793920, "threadName": "MainThread", "processName": "MainProcess", "process": 11044, "taskName": "Task-3"}
{"level": "INFO", "message": "Saving data into output.db was successfully", "timestamp": "2024-05-28T08:50:35.755252+00:00", "logger": "__main__", "module": "main", "function": "main", "line": 242, "task_name": "Task-1", "filename": "main.py", "exc_text": null, "msecs": 755.0, "relativeCreated": 9778.133869171143, "thread": 140579432793920, "threadName": "MainThread", "processName": "MainProcess", "process": 11044, "taskName": "Task-1"}
{"level": "INFO", "message": "Successfully converted", "timestamp": "2024-05-28T08:50:35.790686+00:00", "logger": "csv_convertor", "module": "csv_convertor", "function": "convertor", "line": 109, "task_name": "Task-1", "filename": "csv_convertor.py", "exc_text": null, "msecs": 790.0, "relativeCreated": 9813.567399978638, "thread": 140579432793920, "threadName": "MainThread", "processName": "MainProcess", "process": 11044, "taskName": "Task-1"}
{"level": "INFO", "message": "Database successfully converted to csv file", "timestamp": "2024-05-28T08:50:35.791619+00:00", "logger": "__main__", "module": "main", "function": "main", "line": 245, "task_name": "Task-1", "filename": "main.py", "exc_text": null, "msecs": 791.0, "relativeCreated": 9814.50080871582, "thread": 140579432793920, "threadName": "MainThread", "processName": "MainProcess", "process": 11044, "taskName": "Task-1"}
{"level": "INFO", "message": "App was finished gracefully", "timestamp": "2024-05-28T08:50:35.872968+00:00", "logger": "__main__", "module": "main", "function": "<module>", "line": 260, "task_name": null, "filename": "main.py", "exc_text": null, "msecs": 872.0, "relativeCreated": 9895.849704742432, "thread": 140579432793920, "threadName": "MainThread", "processName": "MainProcess", "process": 11044, "taskName": null}
{"level": "INFO", "message": "Start reading input.csv", "timestamp": "2024-05-28T08:51:42.147928+00:00", "logger": "__main__", "module": "main", "function": "open_csv", "line": 103, "task_name": "Task-1", "filename": "main.py", "exc_text": null, "msecs": 147.0, "relativeCreated": 153.65886688232422, "thread": 140273247729472, "threadName": "MainThread", "processName": "MainProcess", "process": 11110, "taskName": "Task-1"}
{"level": "INFO", "message": "Successfully extracted domains from input.csv", "timestamp": "2024-05-28T08:51:43.587459+00:00", "logger": "__main__", "module": "main", "function": "open_csv", "line": 112, "task_name": "Task-1", "filename": "main.py", "exc_text": null, "msecs": 587.0, "relativeCreated": 1593.1894779205322, "thread": 140273247729472, "threadName": "MainThread", "processName": "MainProcess", "process": 11110, "taskName": "Task-1"}
{"level": "INFO", "message": "Start config before scanning", "timestamp": "2024-05-28T08:51:43.587645+00:00", "logger": "__main__", "module": "main", "function": "create_tasks", "line": 157, "task_name": "Task-1", "filename": "main.py", "exc_text": null, "msecs": 587.0, "relativeCreated": 1593.3756828308105, "thread": 140273247729472, "threadName": "MainThread", "processName": "MainProcess", "process": 11110, "taskName": "Task-1"}
{"level": "INFO", "message": "domain_chunk was set to 11", "timestamp": "2024-05-28T08:51:46.269419+00:00", "logger": "__main__", "module": "main", "function": "create_tasks", "line": 171, "task_name": "Task-1", "filename": "main.py", "exc_text": null, "msecs": 269.0, "relativeCreated": 4275.14910697937, "thread": 140273247729472, "threadName": "MainThread", "processName": "MainProcess", "process": 11110, "taskName": "Task-1"}
{"level": "ERROR", "message": "Invalid value for active tasks: invalid literal for int() with base 10: ''", "timestamp": "2024-05-28T08:51:47.395983+00:00", "logger": "__main__", "module": "main", "function": "create_tasks", "line": 192, "task_name": "Task-1", "filename": "main.py", "exc_text": null, "msecs": 395.0, "relativeCreated": 5401.712894439697, "thread": 140273247729472, "threadName": "MainThread", "processName": "MainProcess", "process": 11110, "taskName": "Task-1"}
{"level": "ERROR", "message": "Invalid value for timeout: invalid literal for int() with base 10: ''", "timestamp": "2024-05-28T08:51:47.851849+00:00", "logger": "__main__", "module": "main", "function": "create_tasks", "line": 203, "task_name": "Task-1", "filename": "main.py", "exc_text": null, "msecs": 851.0, "relativeCreated": 5857.579469680786, "thread": 140273247729472, "threadName": "MainThread", "processName": "MainProcess", "process": 11110, "taskName": "Task-1"}
{"level": "ERROR", "message": "DNSError: (1, 'DNS server returned answer with no data')\nTraceback (most recent call last):\n  File \"/home/iman/Personal/TLS-Checker/TLS-Checker/TLS-Checker/main.py\", line 79, in dns_resolve\n    resp = await asyncio.wait_for(\n           ^^^^^^^^^^^^^^^^^^^^^^^\n  File \"/usr/local/lib/python3.12/asyncio/tasks.py\", line 520, in wait_for\n    return await fut\n           ^^^^^^^^^\naiodns.error.DNSError: (1, 'DNS server returned answer with no data')", "timestamp": "2024-05-28T08:51:47.937329+00:00", "logger": "__main__", "module": "main", "function": "dns_resolve", "line": 94, "task_name": "Task-8", "filename": "main.py", "exc_text": null, "msecs": 937.0, "relativeCreated": 5943.05944442749, "thread": 140273247729472, "threadName": "MainThread", "processName": "MainProcess", "process": 11110, "taskName": "Task-8"}
{"level": "ERROR", "message": "DNSError: (1, 'DNS server returned answer with no data')\nTraceback (most recent call last):\n  File \"/home/iman/Personal/TLS-Checker/TLS-Checker/TLS-Checker/main.py\", line 79, in dns_resolve\n    resp = await asyncio.wait_for(\n           ^^^^^^^^^^^^^^^^^^^^^^^\n  File \"/usr/local/lib/python3.12/asyncio/tasks.py\", line 520, in wait_for\n    return await fut\n           ^^^^^^^^^\naiodns.error.DNSError: (1, 'DNS server returned answer with no data')", "timestamp": "2024-05-28T08:51:47.939233+00:00", "logger": "__main__", "module": "main", "function": "dns_resolve", "line": 94, "task_name": "Task-9", "filename": "main.py", "exc_text": null, "msecs": 939.0, "relativeCreated": 5944.963455200195, "thread": 140273247729472, "threadName": "MainThread", "processName": "MainProcess", "process": 11110, "taskName": "Task-9"}
{"level": "ERROR", "message": "DNSError: (1, 'DNS server returned answer with no data')\nTraceback (most recent call last):\n  File \"/home/iman/Personal/TLS-Checker/TLS-Checker/TLS-Checker/main.py\", line 79, in dns_resolve\n    resp = await asyncio.wait_for(\n           ^^^^^^^^^^^^^^^^^^^^^^^\n  File \"/usr/local/lib/python3.12/asyncio/tasks.py\", line 520, in wait_for\n    return await fut\n           ^^^^^^^^^\naiodns.error.DNSError: (1, 'DNS server returned answer with no data')", "timestamp": "2024-05-28T08:51:47.942970+00:00", "logger": "__main__", "module": "main", "function": "dns_resolve", "line": 94, "task_name": "Task-11", "filename": "main.py", "exc_text": null, "msecs": 942.0, "relativeCreated": 5948.700189590454, "thread": 140273247729472, "threadName": "MainThread", "processName": "MainProcess", "process": 11110, "taskName": "Task-11"}
{"level": "ERROR", "message": "DNSError: (1, 'DNS server returned answer with no data')\nTraceback (most recent call last):\n  File \"/home/iman/Personal/TLS-Checker/TLS-Checker/TLS-Checker/main.py\", line 79, in dns_resolve\n    resp = await asyncio.wait_for(\n           ^^^^^^^^^^^^^^^^^^^^^^^\n  File \"/usr/local/lib/python3.12/asyncio/tasks.py\", line 520, in wait_for\n    return await fut\n           ^^^^^^^^^\naiodns.error.DNSError: (1, 'DNS server returned answer with no data')", "timestamp": "2024-05-28T08:51:47.943471+00:00", "logger": "__main__", "module": "main", "function": "dns_resolve", "line": 94, "task_name": "Task-12", "filename": "main.py", "exc_text": null, "msecs": 943.0, "relativeCreated": 5949.201583862305, "thread": 140273247729472, "threadName": "MainThread", "processName": "MainProcess", "process": 11110, "taskName": "Task-12"}
{"level": "ERROR", "message": "DNSError: (1, 'DNS server returned answer with no data')\nTraceback (most recent call last):\n  File \"/home/iman/Personal/TLS-Checker/TLS-Checker/TLS-Checker/main.py\", line 67, in dns_resolve\n    resp = await asyncio.wait_for(\n           ^^^^^^^^^^^^^^^^^^^^^^^\n  File \"/usr/local/lib/python3.12/asyncio/tasks.py\", line 520, in wait_for\n    return await fut\n           ^^^^^^^^^\naiodns.error.DNSError: (1, 'DNS server returned answer with no data')", "timestamp": "2024-05-28T08:51:47.960088+00:00", "logger": "__main__", "module": "main", "function": "dns_resolve", "line": 94, "task_name": "Task-4", "filename": "main.py", "exc_text": null, "msecs": 960.0, "relativeCreated": 5965.818643569946, "thread": 140273247729472, "threadName": "MainThread", "processName": "MainProcess", "process": 11110, "taskName": "Task-4"}
{"level": "ERROR", "message": "DNSError: (1, 'DNS server returned answer with no data')\nTraceback (most recent call last):\n  File \"/home/iman/Personal/TLS-Checker/TLS-Checker/TLS-Checker/main.py\", line 79, in dns_resolve\n    resp = await asyncio.wait_for(\n           ^^^^^^^^^^^^^^^^^^^^^^^\n  File \"/usr/local/lib/python3.12/asyncio/tasks.py\", line 520, in wait_for\n    return await fut\n           ^^^^^^^^^\naiodns.error.DNSError: (1, 'DNS server returned answer with no data')", "timestamp": "2024-05-28T08:51:48.003902+00:00", "logger": "__main__", "module": "main", "function": "dns_resolve", "line": 94, "task_name": "Task-5", "filename": "main.py", "exc_text": null, "msecs": 3.0, "relativeCreated": 6009.63282585144, "thread": 140273247729472, "threadName": "MainThread", "processName": "MainProcess", "process": 11110, "taskName": "Task-5"}
{"level": "ERROR", "message": "DNSError: (1, 'DNS server returned answer with no data')\nTraceback (most recent call last):\n  File \"/home/iman/Personal/TLS-Checker/TLS-Checker/TLS-Checker/main.py\", line 79, in dns_resolve\n    resp = await asyncio.wait_for(\n           ^^^^^^^^^^^^^^^^^^^^^^^\n  File \"/usr/local/lib/python3.12/asyncio/tasks.py\", line 520, in wait_for\n    return await fut\n           ^^^^^^^^^\naiodns.error.DNSError: (1, 'DNS server returned answer with no data')", "timestamp": "2024-05-28T08:51:48.017097+00:00", "logger": "__main__", "module": "main", "function": "dns_resolve", "line": 94, "task_name": "Task-2", "filename": "main.py", "exc_text": null, "msecs": 17.0, "relativeCreated": 6022.827386856079, "thread": 140273247729472, "threadName": "MainThread", "processName": "MainProcess", "process": 11110, "taskName": "Task-2"}
{"level": "INFO", "message": "Saving data into output.db was successfully", "timestamp": "2024-05-28T08:51:48.104721+00:00", "logger": "__main__", "module": "main", "function": "main", "line": 242, "task_name": "Task-1", "filename": "main.py", "exc_text": null, "msecs": 104.0, "relativeCreated": 6110.451221466064, "thread": 140273247729472, "threadName": "MainThread", "processName": "MainProcess", "process": 11110, "taskName": "Task-1"}
{"level": "INFO", "message": "Successfully converted", "timestamp": "2024-05-28T08:51:48.141007+00:00", "logger": "csv_convertor", "module": "csv_convertor", "function": "convertor", "line": 109, "task_name": "Task-1", "filename": "csv_convertor.py", "exc_text": null, "msecs": 141.0, "relativeCreated": 6146.737337112427, "thread": 140273247729472, "threadName": "MainThread", "processName": "MainProcess", "process": 11110, "taskName": "Task-1"}
{"level": "INFO", "message": "Database successfully converted to csv file", "timestamp": "2024-05-28T08:51:48.141952+00:00", "logger": "__main__", "module": "main", "function": "main", "line": 245, "task_name": "Task-1", "filename": "main.py", "exc_text": null, "msecs": 141.0, "relativeCreated": 6147.682189941406, "thread": 140273247729472, "threadName": "MainThread", "processName": "MainProcess", "process": 11110, "taskName": "Task-1"}
{"level": "INFO", "message": "App was finished gracefully", "timestamp": "2024-05-28T08:51:48.223802+00:00", "logger": "__main__", "module": "main", "function": "<module>", "line": 260, "task_name": null, "filename": "main.py", "exc_text": null, "msecs": 223.0, "relativeCreated": 6229.532241821289, "thread": 140273247729472, "threadName": "MainThread", "processName": "MainProcess", "process": 11110, "taskName": null}
{"level": "INFO", "message": "Start reading input.csv", "timestamp": "2024-05-28T08:54:34.972735+00:00", "logger": "__main__", "module": "main", "function": "open_csv", "line": 103, "task_name": "Task-1", "filename": "main.py", "exc_text": null, "msecs": 972.0, "relativeCreated": 169.99340057373047, "thread": 139863780357952, "threadName": "MainThread", "processName": "MainProcess", "process": 11570, "taskName": "Task-1"}
{"level": "INFO", "message": "Successfully extracted domains from input.csv", "timestamp": "2024-05-28T08:54:37.261022+00:00", "logger": "__main__", "module": "main", "function": "open_csv", "line": 112, "task_name": "Task-1", "filename": "main.py", "exc_text": null, "msecs": 261.0, "relativeCreated": 2458.280324935913, "thread": 139863780357952, "threadName": "MainThread", "processName": "MainProcess", "process": 11570, "taskName": "Task-1"}
{"level": "INFO", "message": "Start config before scanning", "timestamp": "2024-05-28T08:54:37.261493+00:00", "logger": "__main__", "module": "main", "function": "create_tasks", "line": 157, "task_name": "Task-1", "filename": "main.py", "exc_text": null, "msecs": 261.0, "relativeCreated": 2458.751678466797, "thread": 139863780357952, "threadName": "MainThread", "processName": "MainProcess", "process": 11570, "taskName": "Task-1"}
{"level": "INFO", "message": "Start reading input.csv", "timestamp": "2024-05-28T08:55:15.319287+00:00", "logger": "__main__", "module": "main", "function": "open_csv", "line": 103, "task_name": "Task-1", "filename": "main.py", "exc_text": null, "msecs": 319.0, "relativeCreated": 146.5303897857666, "thread": 139900710250304, "threadName": "MainThread", "processName": "MainProcess", "process": 11627, "taskName": "Task-1"}
{"level": "INFO", "message": "Successfully extracted domains from input.csv", "timestamp": "2024-05-28T08:55:16.923333+00:00", "logger": "__main__", "module": "main", "function": "open_csv", "line": 112, "task_name": "Task-1", "filename": "main.py", "exc_text": null, "msecs": 923.0, "relativeCreated": 1750.5757808685303, "thread": 139900710250304, "threadName": "MainThread", "processName": "MainProcess", "process": 11627, "taskName": "Task-1"}
{"level": "INFO", "message": "Start config before scanning", "timestamp": "2024-05-28T08:55:16.923532+00:00", "logger": "__main__", "module": "main", "function": "create_tasks", "line": 157, "task_name": "Task-1", "filename": "main.py", "exc_text": null, "msecs": 923.0, "relativeCreated": 1750.7753372192383, "thread": 139900710250304, "threadName": "MainThread", "processName": "MainProcess", "process": 11627, "taskName": "Task-1"}
{"level": "INFO", "message": "domain_chunk was set to 100", "timestamp": "2024-05-28T08:55:23.376022+00:00", "logger": "__main__", "module": "main", "function": "create_tasks", "line": 171, "task_name": "Task-1", "filename": "main.py", "exc_text": null, "msecs": 376.0, "relativeCreated": 8203.265190124512, "thread": 139900710250304, "threadName": "MainThread", "processName": "MainProcess", "process": 11627, "taskName": "Task-1"}
{"level": "ERROR", "message": "Invalid value for active tasks: invalid literal for int() with base 10: ''", "timestamp": "2024-05-28T08:55:25.097436+00:00", "logger": "__main__", "module": "main", "function": "create_tasks", "line": 192, "task_name": "Task-1", "filename": "main.py", "exc_text": null, "msecs": 97.0, "relativeCreated": 9924.678802490234, "thread": 139900710250304, "threadName": "MainThread", "processName": "MainProcess", "process": 11627, "taskName": "Task-1"}
{"level": "ERROR", "message": "Invalid value for timeout: invalid literal for int() with base 10: ''", "timestamp": "2024-05-28T08:55:25.738275+00:00", "logger": "__main__", "module": "main", "function": "create_tasks", "line": 203, "task_name": "Task-1", "filename": "main.py", "exc_text": null, "msecs": 738.0, "relativeCreated": 10565.518140792847, "thread": 139900710250304, "threadName": "MainThread", "processName": "MainProcess", "process": 11627, "taskName": "Task-1"}
{"level": "ERROR", "message": "DNSError: (1, 'DNS server returned answer with no data')\nTraceback (most recent call last):\n  File \"/home/iman/Personal/TLS-Checker/TLS-Checker/TLS-Checker/main.py\", line 67, in dns_resolve\n    resp = await asyncio.wait_for(\n           ^^^^^^^^^^^^^^^^^^^^^^^\n  File \"/usr/local/lib/python3.12/asyncio/tasks.py\", line 520, in wait_for\n    return await fut\n           ^^^^^^^^^\naiodns.error.DNSError: (1, 'DNS server returned answer with no data')", "timestamp": "2024-05-28T08:55:25.874953+00:00", "logger": "__main__", "module": "main", "function": "dns_resolve", "line": 94, "task_name": "Task-4", "filename": "main.py", "exc_text": null, "msecs": 874.0, "relativeCreated": 10702.1963596344, "thread": 139900710250304, "threadName": "MainThread", "processName": "MainProcess", "process": 11627, "taskName": "Task-4"}
{"level": "ERROR", "message": "DNSError: (1, 'DNS server returned answer with no data')\nTraceback (most recent call last):\n  File \"/home/iman/Personal/TLS-Checker/TLS-Checker/TLS-Checker/main.py\", line 67, in dns_resolve\n    resp = await asyncio.wait_for(\n           ^^^^^^^^^^^^^^^^^^^^^^^\n  File \"/usr/local/lib/python3.12/asyncio/tasks.py\", line 520, in wait_for\n    return await fut\n           ^^^^^^^^^\naiodns.error.DNSError: (1, 'DNS server returned answer with no data')", "timestamp": "2024-05-28T08:55:25.877003+00:00", "logger": "__main__", "module": "main", "function": "dns_resolve", "line": 94, "task_name": "Task-22", "filename": "main.py", "exc_text": null, "msecs": 877.0, "relativeCreated": 10704.246282577515, "thread": 139900710250304, "threadName": "MainThread", "processName": "MainProcess", "process": 11627, "taskName": "Task-22"}
{"level": "ERROR", "message": "DNSError: (1, 'DNS server returned answer with no data')\nTraceback (most recent call last):\n  File \"/home/iman/Personal/TLS-Checker/TLS-Checker/TLS-Checker/main.py\", line 67, in dns_resolve\n    resp = await asyncio.wait_for(\n           ^^^^^^^^^^^^^^^^^^^^^^^\n  File \"/usr/local/lib/python3.12/asyncio/tasks.py\", line 520, in wait_for\n    return await fut\n           ^^^^^^^^^\naiodns.error.DNSError: (1, 'DNS server returned answer with no data')", "timestamp": "2024-05-28T08:55:25.879730+00:00", "logger": "__main__", "module": "main", "function": "dns_resolve", "line": 94, "task_name": "Task-26", "filename": "main.py", "exc_text": null, "msecs": 879.0, "relativeCreated": 10706.973552703857, "thread": 139900710250304, "threadName": "MainThread", "processName": "MainProcess", "process": 11627, "taskName": "Task-26"}
{"level": "ERROR", "message": "DNSError: (1, 'DNS server returned answer with no data')\nTraceback (most recent call last):\n  File \"/home/iman/Personal/TLS-Checker/TLS-Checker/TLS-Checker/main.py\", line 67, in dns_resolve\n    resp = await asyncio.wait_for(\n           ^^^^^^^^^^^^^^^^^^^^^^^\n  File \"/usr/local/lib/python3.12/asyncio/tasks.py\", line 520, in wait_for\n    return await fut\n           ^^^^^^^^^\naiodns.error.DNSError: (1, 'DNS server returned answer with no data')", "timestamp": "2024-05-28T08:55:25.905382+00:00", "logger": "__main__", "module": "main", "function": "dns_resolve", "line": 94, "task_name": "Task-46", "filename": "main.py", "exc_text": null, "msecs": 905.0, "relativeCreated": 10732.625484466553, "thread": 139900710250304, "threadName": "MainThread", "processName": "MainProcess", "process": 11627, "taskName": "Task-46"}
{"level": "ERROR", "message": "DNSError: (1, 'DNS server returned answer with no data')\nTraceback (most recent call last):\n  File \"/home/iman/Personal/TLS-Checker/TLS-Checker/TLS-Checker/main.py\", line 67, in dns_resolve\n    resp = await asyncio.wait_for(\n           ^^^^^^^^^^^^^^^^^^^^^^^\n  File \"/usr/local/lib/python3.12/asyncio/tasks.py\", line 520, in wait_for\n    return await fut\n           ^^^^^^^^^\naiodns.error.DNSError: (1, 'DNS server returned answer with no data')", "timestamp": "2024-05-28T08:55:25.907153+00:00", "logger": "__main__", "module": "main", "function": "dns_resolve", "line": 94, "task_name": "Task-41", "filename": "main.py", "exc_text": null, "msecs": 907.0, "relativeCreated": 10734.39621925354, "thread": 139900710250304, "threadName": "MainThread", "processName": "MainProcess", "process": 11627, "taskName": "Task-41"}
{"level": "ERROR", "message": "DNSError: (1, 'DNS server returned answer with no data')\nTraceback (most recent call last):\n  File \"/home/iman/Personal/TLS-Checker/TLS-Checker/TLS-Checker/main.py\", line 79, in dns_resolve\n    resp = await asyncio.wait_for(\n           ^^^^^^^^^^^^^^^^^^^^^^^\n  File \"/usr/local/lib/python3.12/asyncio/tasks.py\", line 520, in wait_for\n    return await fut\n           ^^^^^^^^^\naiodns.error.DNSError: (1, 'DNS server returned answer with no data')", "timestamp": "2024-05-28T08:55:25.908174+00:00", "logger": "__main__", "module": "main", "function": "dns_resolve", "line": 94, "task_name": "Task-7", "filename": "main.py", "exc_text": null, "msecs": 908.0, "relativeCreated": 10735.416889190674, "thread": 139900710250304, "threadName": "MainThread", "processName": "MainProcess", "process": 11627, "taskName": "Task-7"}
{"level": "ERROR", "message": "DNSError: (1, 'DNS server returned answer with no data')\nTraceback (most recent call last):\n  File \"/home/iman/Personal/TLS-Checker/TLS-Checker/TLS-Checker/main.py\", line 79, in dns_resolve\n    resp = await asyncio.wait_for(\n           ^^^^^^^^^^^^^^^^^^^^^^^\n  File \"/usr/local/lib/python3.12/asyncio/tasks.py\", line 520, in wait_for\n    return await fut\n           ^^^^^^^^^\naiodns.error.DNSError: (1, 'DNS server returned answer with no data')", "timestamp": "2024-05-28T08:55:25.908512+00:00", "logger": "__main__", "module": "main", "function": "dns_resolve", "line": 94, "task_name": "Task-8", "filename": "main.py", "exc_text": null, "msecs": 908.0, "relativeCreated": 10735.755205154419, "thread": 139900710250304, "threadName": "MainThread", "processName": "MainProcess", "process": 11627, "taskName": "Task-8"}
{"level": "ERROR", "message": "DNSError: (1, 'DNS server returned answer with no data')\nTraceback (most recent call last):\n  File \"/home/iman/Personal/TLS-Checker/TLS-Checker/TLS-Checker/main.py\", line 79, in dns_resolve\n    resp = await asyncio.wait_for(\n           ^^^^^^^^^^^^^^^^^^^^^^^\n  File \"/usr/local/lib/python3.12/asyncio/tasks.py\", line 520, in wait_for\n    return await fut\n           ^^^^^^^^^\naiodns.error.DNSError: (1, 'DNS server returned answer with no data')", "timestamp": "2024-05-28T08:55:25.908823+00:00", "logger": "__main__", "module": "main", "function": "dns_resolve", "line": 94, "task_name": "Task-6", "filename": "main.py", "exc_text": null, "msecs": 908.0, "relativeCreated": 10736.066341400146, "thread": 139900710250304, "threadName": "MainThread", "processName": "MainProcess", "process": 11627, "taskName": "Task-6"}
{"level": "ERROR", "message": "DNSError: (1, 'DNS server returned answer with no data')\nTraceback (most recent call last):\n  File \"/home/iman/Personal/TLS-Checker/TLS-Checker/TLS-Checker/main.py\", line 67, in dns_resolve\n    resp = await asyncio.wait_for(\n           ^^^^^^^^^^^^^^^^^^^^^^^\n  File \"/usr/local/lib/python3.12/asyncio/tasks.py\", line 520, in wait_for\n    return await fut\n           ^^^^^^^^^\naiodns.error.DNSError: (1, 'DNS server returned answer with no data')", "timestamp": "2024-05-28T08:55:25.909245+00:00", "logger": "__main__", "module": "main", "function": "dns_resolve", "line": 94, "task_name": "Task-44", "filename": "main.py", "exc_text": null, "msecs": 909.0, "relativeCreated": 10736.488342285156, "thread": 139900710250304, "threadName": "MainThread", "processName": "MainProcess", "process": 11627, "taskName": "Task-44"}
{"level": "ERROR", "message": "DNSError: (1, 'DNS server returned answer with no data')\nTraceback (most recent call last):\n  File \"/home/iman/Personal/TLS-Checker/TLS-Checker/TLS-Checker/main.py\", line 79, in dns_resolve\n    resp = await asyncio.wait_for(\n           ^^^^^^^^^^^^^^^^^^^^^^^\n  File \"/usr/local/lib/python3.12/asyncio/tasks.py\", line 520, in wait_for\n    return await fut\n           ^^^^^^^^^\naiodns.error.DNSError: (1, 'DNS server returned answer with no data')", "timestamp": "2024-05-28T08:55:25.910240+00:00", "logger": "__main__", "module": "main", "function": "dns_resolve", "line": 94, "task_name": "Task-19", "filename": "main.py", "exc_text": null, "msecs": 910.0, "relativeCreated": 10737.483263015747, "thread": 139900710250304, "threadName": "MainThread", "processName": "MainProcess", "process": 11627, "taskName": "Task-19"}
{"level": "ERROR", "message": "DNSError: (1, 'DNS server returned answer with no data')\nTraceback (most recent call last):\n  File \"/home/iman/Personal/TLS-Checker/TLS-Checker/TLS-Checker/main.py\", line 79, in dns_resolve\n    resp = await asyncio.wait_for(\n           ^^^^^^^^^^^^^^^^^^^^^^^\n  File \"/usr/local/lib/python3.12/asyncio/tasks.py\", line 520, in wait_for\n    return await fut\n           ^^^^^^^^^\naiodns.error.DNSError: (1, 'DNS server returned answer with no data')", "timestamp": "2024-05-28T08:55:25.910752+00:00", "logger": "__main__", "module": "main", "function": "dns_resolve", "line": 94, "task_name": "Task-15", "filename": "main.py", "exc_text": null, "msecs": 910.0, "relativeCreated": 10737.99467086792, "thread": 139900710250304, "threadName": "MainThread", "processName": "MainProcess", "process": 11627, "taskName": "Task-15"}
{"level": "ERROR", "message": "DNSError: (1, 'DNS server returned answer with no data')\nTraceback (most recent call last):\n  File \"/home/iman/Personal/TLS-Checker/TLS-Checker/TLS-Checker/main.py\", line 79, in dns_resolve\n    resp = await asyncio.wait_for(\n           ^^^^^^^^^^^^^^^^^^^^^^^\n  File \"/usr/local/lib/python3.12/asyncio/tasks.py\", line 520, in wait_for\n    return await fut\n           ^^^^^^^^^\naiodns.error.DNSError: (1, 'DNS server returned answer with no data')", "timestamp": "2024-05-28T08:55:25.911211+00:00", "logger": "__main__", "module": "main", "function": "dns_resolve", "line": 94, "task_name": "Task-31", "filename": "main.py", "exc_text": null, "msecs": 911.0, "relativeCreated": 10738.45386505127, "thread": 139900710250304, "threadName": "MainThread", "processName": "MainProcess", "process": 11627, "taskName": "Task-31"}
{"level": "ERROR", "message": "DNSError: (1, 'DNS server returned answer with no data')\nTraceback (most recent call last):\n  File \"/home/iman/Personal/TLS-Checker/TLS-Checker/TLS-Checker/main.py\", line 79, in dns_resolve\n    resp = await asyncio.wait_for(\n           ^^^^^^^^^^^^^^^^^^^^^^^\n  File \"/usr/local/lib/python3.12/asyncio/tasks.py\", line 520, in wait_for\n    return await fut\n           ^^^^^^^^^\naiodns.error.DNSError: (1, 'DNS server returned answer with no data')", "timestamp": "2024-05-28T08:55:25.912083+00:00", "logger": "__main__", "module": "main", "function": "dns_resolve", "line": 94, "task_name": "Task-20", "filename": "main.py", "exc_text": null, "msecs": 912.0, "relativeCreated": 10739.326000213623, "thread": 139900710250304, "threadName": "MainThread", "processName": "MainProcess", "process": 11627, "taskName": "Task-20"}
{"level": "ERROR", "message": "DNSError: (1, 'DNS server returned answer with no data')\nTraceback (most recent call last):\n  File \"/home/iman/Personal/TLS-Checker/TLS-Checker/TLS-Checker/main.py\", line 79, in dns_resolve\n    resp = await asyncio.wait_for(\n           ^^^^^^^^^^^^^^^^^^^^^^^\n  File \"/usr/local/lib/python3.12/asyncio/tasks.py\", line 520, in wait_for\n    return await fut\n           ^^^^^^^^^\naiodns.error.DNSError: (1, 'DNS server returned answer with no data')", "timestamp": "2024-05-28T08:55:25.912344+00:00", "logger": "__main__", "module": "main", "function": "dns_resolve", "line": 94, "task_name": "Task-27", "filename": "main.py", "exc_text": null, "msecs": 912.0, "relativeCreated": 10739.586591720581, "thread": 139900710250304, "threadName": "MainThread", "processName": "MainProcess", "process": 11627, "taskName": "Task-27"}
{"level": "ERROR", "message": "DNSError: (1, 'DNS server returned answer with no data')\nTraceback (most recent call last):\n  File \"/home/iman/Personal/TLS-Checker/TLS-Checker/TLS-Checker/main.py\", line 79, in dns_resolve\n    resp = await asyncio.wait_for(\n           ^^^^^^^^^^^^^^^^^^^^^^^\n  File \"/usr/local/lib/python3.12/asyncio/tasks.py\", line 520, in wait_for\n    return await fut\n           ^^^^^^^^^\naiodns.error.DNSError: (1, 'DNS server returned answer with no data')", "timestamp": "2024-05-28T08:55:25.912622+00:00", "logger": "__main__", "module": "main", "function": "dns_resolve", "line": 94, "task_name": "Task-42", "filename": "main.py", "exc_text": null, "msecs": 912.0, "relativeCreated": 10739.865064620972, "thread": 139900710250304, "threadName": "MainThread", "processName": "MainProcess", "process": 11627, "taskName": "Task-42"}
{"level": "ERROR", "message": "DNSError: (1, 'DNS server returned answer with no data')\nTraceback (most recent call last):\n  File \"/home/iman/Personal/TLS-Checker/TLS-Checker/TLS-Checker/main.py\", line 79, in dns_resolve\n    resp = await asyncio.wait_for(\n           ^^^^^^^^^^^^^^^^^^^^^^^\n  File \"/usr/local/lib/python3.12/asyncio/tasks.py\", line 520, in wait_for\n    return await fut\n           ^^^^^^^^^\naiodns.error.DNSError: (1, 'DNS server returned answer with no data')", "timestamp": "2024-05-28T08:55:25.913165+00:00", "logger": "__main__", "module": "main", "function": "dns_resolve", "line": 94, "task_name": "Task-35", "filename": "main.py", "exc_text": null, "msecs": 913.0, "relativeCreated": 10740.407705307007, "thread": 139900710250304, "threadName": "MainThread", "processName": "MainProcess", "process": 11627, "taskName": "Task-35"}
{"level": "ERROR", "message": "DNSError: (1, 'DNS server returned answer with no data')\nTraceback (most recent call last):\n  File \"/home/iman/Personal/TLS-Checker/TLS-Checker/TLS-Checker/main.py\", line 67, in dns_resolve\n    resp = await asyncio.wait_for(\n           ^^^^^^^^^^^^^^^^^^^^^^^\n  File \"/usr/local/lib/python3.12/asyncio/tasks.py\", line 520, in wait_for\n    return await fut\n           ^^^^^^^^^\naiodns.error.DNSError: (1, 'DNS server returned answer with no data')", "timestamp": "2024-05-28T08:55:25.913494+00:00", "logger": "__main__", "module": "main", "function": "dns_resolve", "line": 94, "task_name": "Task-54", "filename": "main.py", "exc_text": null, "msecs": 913.0, "relativeCreated": 10740.737199783325, "thread": 139900710250304, "threadName": "MainThread", "processName": "MainProcess", "process": 11627, "taskName": "Task-54"}
{"level": "ERROR", "message": "DNSError: (1, 'DNS server returned answer with no data')\nTraceback (most recent call last):\n  File \"/home/iman/Personal/TLS-Checker/TLS-Checker/TLS-Checker/main.py\", line 67, in dns_resolve\n    resp = await asyncio.wait_for(\n           ^^^^^^^^^^^^^^^^^^^^^^^\n  File \"/usr/local/lib/python3.12/asyncio/tasks.py\", line 520, in wait_for\n    return await fut\n           ^^^^^^^^^\naiodns.error.DNSError: (1, 'DNS server returned answer with no data')", "timestamp": "2024-05-28T08:55:25.914542+00:00", "logger": "__main__", "module": "main", "function": "dns_resolve", "line": 94, "task_name": "Task-73", "filename": "main.py", "exc_text": null, "msecs": 914.0, "relativeCreated": 10741.785526275635, "thread": 139900710250304, "threadName": "MainThread", "processName": "MainProcess", "process": 11627, "taskName": "Task-73"}
{"level": "ERROR", "message": "DNSError: (1, 'DNS server returned answer with no data')\nTraceback (most recent call last):\n  File \"/home/iman/Personal/TLS-Checker/TLS-Checker/TLS-Checker/main.py\", line 79, in dns_resolve\n    resp = await asyncio.wait_for(\n           ^^^^^^^^^^^^^^^^^^^^^^^\n  File \"/usr/local/lib/python3.12/asyncio/tasks.py\", line 520, in wait_for\n    return await fut\n           ^^^^^^^^^\naiodns.error.DNSError: (1, 'DNS server returned answer with no data')", "timestamp": "2024-05-28T08:55:25.915002+00:00", "logger": "__main__", "module": "main", "function": "dns_resolve", "line": 94, "task_name": "Task-61", "filename": "main.py", "exc_text": null, "msecs": 915.0, "relativeCreated": 10742.245197296143, "thread": 139900710250304, "threadName": "MainThread", "processName": "MainProcess", "process": 11627, "taskName": "Task-61"}
{"level": "ERROR", "message": "DNSError: (1, 'DNS server returned answer with no data')\nTraceback (most recent call last):\n  File \"/home/iman/Personal/TLS-Checker/TLS-Checker/TLS-Checker/main.py\", line 79, in dns_resolve\n    resp = await asyncio.wait_for(\n           ^^^^^^^^^^^^^^^^^^^^^^^\n  File \"/usr/local/lib/python3.12/asyncio/tasks.py\", line 520, in wait_for\n    return await fut\n           ^^^^^^^^^\naiodns.error.DNSError: (1, 'DNS server returned answer with no data')", "timestamp": "2024-05-28T08:55:25.915547+00:00", "logger": "__main__", "module": "main", "function": "dns_resolve", "line": 94, "task_name": "Task-62", "filename": "main.py", "exc_text": null, "msecs": 915.0, "relativeCreated": 10742.78998374939, "thread": 139900710250304, "threadName": "MainThread", "processName": "MainProcess", "process": 11627, "taskName": "Task-62"}
{"level": "ERROR", "message": "DNSError: (1, 'DNS server returned answer with no data')\nTraceback (most recent call last):\n  File \"/home/iman/Personal/TLS-Checker/TLS-Checker/TLS-Checker/main.py\", line 79, in dns_resolve\n    resp = await asyncio.wait_for(\n           ^^^^^^^^^^^^^^^^^^^^^^^\n  File \"/usr/local/lib/python3.12/asyncio/tasks.py\", line 520, in wait_for\n    return await fut\n           ^^^^^^^^^\naiodns.error.DNSError: (1, 'DNS server returned answer with no data')", "timestamp": "2024-05-28T08:55:25.915879+00:00", "logger": "__main__", "module": "main", "function": "dns_resolve", "line": 94, "task_name": "Task-60", "filename": "main.py", "exc_text": null, "msecs": 915.0, "relativeCreated": 10743.122100830078, "thread": 139900710250304, "threadName": "MainThread", "processName": "MainProcess", "process": 11627, "taskName": "Task-60"}
{"level": "ERROR", "message": "DNSError: (1, 'DNS server returned answer with no data')\nTraceback (most recent call last):\n  File \"/home/iman/Personal/TLS-Checker/TLS-Checker/TLS-Checker/main.py\", line 67, in dns_resolve\n    resp = await asyncio.wait_for(\n           ^^^^^^^^^^^^^^^^^^^^^^^\n  File \"/usr/local/lib/python3.12/asyncio/tasks.py\", line 520, in wait_for\n    return await fut\n           ^^^^^^^^^\naiodns.error.DNSError: (1, 'DNS server returned answer with no data')", "timestamp": "2024-05-28T08:55:25.916235+00:00", "logger": "__main__", "module": "main", "function": "dns_resolve", "line": 94, "task_name": "Task-79", "filename": "main.py", "exc_text": null, "msecs": 916.0, "relativeCreated": 10743.478298187256, "thread": 139900710250304, "threadName": "MainThread", "processName": "MainProcess", "process": 11627, "taskName": "Task-79"}
{"level": "ERROR", "message": "DNSError: (1, 'DNS server returned answer with no data')\nTraceback (most recent call last):\n  File \"/home/iman/Personal/TLS-Checker/TLS-Checker/TLS-Checker/main.py\", line 79, in dns_resolve\n    resp = await asyncio.wait_for(\n           ^^^^^^^^^^^^^^^^^^^^^^^\n  File \"/usr/local/lib/python3.12/asyncio/tasks.py\", line 520, in wait_for\n    return await fut\n           ^^^^^^^^^\naiodns.error.DNSError: (1, 'DNS server returned answer with no data')", "timestamp": "2024-05-28T08:55:25.916951+00:00", "logger": "__main__", "module": "main", "function": "dns_resolve", "line": 94, "task_name": "Task-74", "filename": "main.py", "exc_text": null, "msecs": 916.0, "relativeCreated": 10744.194030761719, "thread": 139900710250304, "threadName": "MainThread", "processName": "MainProcess", "process": 11627, "taskName": "Task-74"}
{"level": "ERROR", "message": "DNSError: (1, 'DNS server returned answer with no data')\nTraceback (most recent call last):\n  File \"/home/iman/Personal/TLS-Checker/TLS-Checker/TLS-Checker/main.py\", line 79, in dns_resolve\n    resp = await asyncio.wait_for(\n           ^^^^^^^^^^^^^^^^^^^^^^^\n  File \"/usr/local/lib/python3.12/asyncio/tasks.py\", line 520, in wait_for\n    return await fut\n           ^^^^^^^^^\naiodns.error.DNSError: (1, 'DNS server returned answer with no data')", "timestamp": "2024-05-28T08:55:25.917288+00:00", "logger": "__main__", "module": "main", "function": "dns_resolve", "line": 94, "task_name": "Task-75", "filename": "main.py", "exc_text": null, "msecs": 917.0, "relativeCreated": 10744.531393051147, "thread": 139900710250304, "threadName": "MainThread", "processName": "MainProcess", "process": 11627, "taskName": "Task-75"}
{"level": "ERROR", "message": "DNSError: (1, 'DNS server returned answer with no data')\nTraceback (most recent call last):\n  File \"/home/iman/Personal/TLS-Checker/TLS-Checker/TLS-Checker/main.py\", line 79, in dns_resolve\n    resp = await asyncio.wait_for(\n           ^^^^^^^^^^^^^^^^^^^^^^^\n  File \"/usr/local/lib/python3.12/asyncio/tasks.py\", line 520, in wait_for\n    return await fut\n           ^^^^^^^^^\naiodns.error.DNSError: (1, 'DNS server returned answer with no data')", "timestamp": "2024-05-28T08:55:25.929431+00:00", "logger": "__main__", "module": "main", "function": "dns_resolve", "line": 94, "task_name": "Task-77", "filename": "main.py", "exc_text": null, "msecs": 929.0, "relativeCreated": 10756.673812866211, "thread": 139900710250304, "threadName": "MainThread", "processName": "MainProcess", "process": 11627, "taskName": "Task-77"}
{"level": "ERROR", "message": "DNSError: (1, 'DNS server returned answer with no data')\nTraceback (most recent call last):\n  File \"/home/iman/Personal/TLS-Checker/TLS-Checker/TLS-Checker/main.py\", line 79, in dns_resolve\n    resp = await asyncio.wait_for(\n           ^^^^^^^^^^^^^^^^^^^^^^^\n  File \"/usr/local/lib/python3.12/asyncio/tasks.py\", line 520, in wait_for\n    return await fut\n           ^^^^^^^^^\naiodns.error.DNSError: (1, 'DNS server returned answer with no data')", "timestamp": "2024-05-28T08:55:25.930645+00:00", "logger": "__main__", "module": "main", "function": "dns_resolve", "line": 94, "task_name": "Task-76", "filename": "main.py", "exc_text": null, "msecs": 930.0, "relativeCreated": 10757.888317108154, "thread": 139900710250304, "threadName": "MainThread", "processName": "MainProcess", "process": 11627, "taskName": "Task-76"}
{"level": "ERROR", "message": "DNSError: (1, 'DNS server returned answer with no data')\nTraceback (most recent call last):\n  File \"/home/iman/Personal/TLS-Checker/TLS-Checker/TLS-Checker/main.py\", line 79, in dns_resolve\n    resp = await asyncio.wait_for(\n           ^^^^^^^^^^^^^^^^^^^^^^^\n  File \"/usr/local/lib/python3.12/asyncio/tasks.py\", line 520, in wait_for\n    return await fut\n           ^^^^^^^^^\naiodns.error.DNSError: (1, 'DNS server returned answer with no data')", "timestamp": "2024-05-28T08:55:25.931028+00:00", "logger": "__main__", "module": "main", "function": "dns_resolve", "line": 94, "task_name": "Task-81", "filename": "main.py", "exc_text": null, "msecs": 931.0, "relativeCreated": 10758.271217346191, "thread": 139900710250304, "threadName": "MainThread", "processName": "MainProcess", "process": 11627, "taskName": "Task-81"}
{"level": "ERROR", "message": "DNSError: (1, 'DNS server returned answer with no data')\nTraceback (most recent call last):\n  File \"/home/iman/Personal/TLS-Checker/TLS-Checker/TLS-Checker/main.py\", line 67, in dns_resolve\n    resp = await asyncio.wait_for(\n           ^^^^^^^^^^^^^^^^^^^^^^^\n  File \"/usr/local/lib/python3.12/asyncio/tasks.py\", line 520, in wait_for\n    return await fut\n           ^^^^^^^^^\naiodns.error.DNSError: (1, 'DNS server returned answer with no data')", "timestamp": "2024-05-28T08:55:25.936136+00:00", "logger": "__main__", "module": "main", "function": "dns_resolve", "line": 94, "task_name": "Task-55", "filename": "main.py", "exc_text": null, "msecs": 936.0, "relativeCreated": 10763.379573822021, "thread": 139900710250304, "threadName": "MainThread", "processName": "MainProcess", "process": 11627, "taskName": "Task-55"}
{"level": "ERROR", "message": "DNSError: (1, 'DNS server returned answer with no data')\nTraceback (most recent call last):\n  File \"/home/iman/Personal/TLS-Checker/TLS-Checker/TLS-Checker/main.py\", line 79, in dns_resolve\n    resp = await asyncio.wait_for(\n           ^^^^^^^^^^^^^^^^^^^^^^^\n  File \"/usr/local/lib/python3.12/asyncio/tasks.py\", line 520, in wait_for\n    return await fut\n           ^^^^^^^^^\naiodns.error.DNSError: (1, 'DNS server returned answer with no data')", "timestamp": "2024-05-28T08:55:25.937477+00:00", "logger": "__main__", "module": "main", "function": "dns_resolve", "line": 94, "task_name": "Task-82", "filename": "main.py", "exc_text": null, "msecs": 937.0, "relativeCreated": 10764.720439910889, "thread": 139900710250304, "threadName": "MainThread", "processName": "MainProcess", "process": 11627, "taskName": "Task-82"}
{"level": "ERROR", "message": "DNSError: (1, 'DNS server returned answer with no data')\nTraceback (most recent call last):\n  File \"/home/iman/Personal/TLS-Checker/TLS-Checker/TLS-Checker/main.py\", line 67, in dns_resolve\n    resp = await asyncio.wait_for(\n           ^^^^^^^^^^^^^^^^^^^^^^^\n  File \"/usr/local/lib/python3.12/asyncio/tasks.py\", line 520, in wait_for\n    return await fut\n           ^^^^^^^^^\naiodns.error.DNSError: (1, 'DNS server returned answer with no data')", "timestamp": "2024-05-28T08:55:25.937915+00:00", "logger": "__main__", "module": "main", "function": "dns_resolve", "line": 94, "task_name": "Task-80", "filename": "main.py", "exc_text": null, "msecs": 937.0, "relativeCreated": 10765.15793800354, "thread": 139900710250304, "threadName": "MainThread", "processName": "MainProcess", "process": 11627, "taskName": "Task-80"}
{"level": "ERROR", "message": "DNSError: (1, 'DNS server returned answer with no data')\nTraceback (most recent call last):\n  File \"/home/iman/Personal/TLS-Checker/TLS-Checker/TLS-Checker/main.py\", line 79, in dns_resolve\n    resp = await asyncio.wait_for(\n           ^^^^^^^^^^^^^^^^^^^^^^^\n  File \"/usr/local/lib/python3.12/asyncio/tasks.py\", line 520, in wait_for\n    return await fut\n           ^^^^^^^^^\naiodns.error.DNSError: (1, 'DNS server returned answer with no data')", "timestamp": "2024-05-28T08:55:25.938384+00:00", "logger": "__main__", "module": "main", "function": "dns_resolve", "line": 94, "task_name": "Task-83", "filename": "main.py", "exc_text": null, "msecs": 938.0, "relativeCreated": 10765.626668930054, "thread": 139900710250304, "threadName": "MainThread", "processName": "MainProcess", "process": 11627, "taskName": "Task-83"}
{"level": "ERROR", "message": "DNSError: (1, 'DNS server returned answer with no data')\nTraceback (most recent call last):\n  File \"/home/iman/Personal/TLS-Checker/TLS-Checker/TLS-Checker/main.py\", line 79, in dns_resolve\n    resp = await asyncio.wait_for(\n           ^^^^^^^^^^^^^^^^^^^^^^^\n  File \"/usr/local/lib/python3.12/asyncio/tasks.py\", line 520, in wait_for\n    return await fut\n           ^^^^^^^^^\naiodns.error.DNSError: (1, 'DNS server returned answer with no data')", "timestamp": "2024-05-28T08:55:25.938678+00:00", "logger": "__main__", "module": "main", "function": "dns_resolve", "line": 94, "task_name": "Task-96", "filename": "main.py", "exc_text": null, "msecs": 938.0, "relativeCreated": 10765.920639038086, "thread": 139900710250304, "threadName": "MainThread", "processName": "MainProcess", "process": 11627, "taskName": "Task-96"}
{"level": "ERROR", "message": "DNSError: (1, 'DNS server returned answer with no data')\nTraceback (most recent call last):\n  File \"/home/iman/Personal/TLS-Checker/TLS-Checker/TLS-Checker/main.py\", line 79, in dns_resolve\n    resp = await asyncio.wait_for(\n           ^^^^^^^^^^^^^^^^^^^^^^^\n  File \"/usr/local/lib/python3.12/asyncio/tasks.py\", line 520, in wait_for\n    return await fut\n           ^^^^^^^^^\naiodns.error.DNSError: (1, 'DNS server returned answer with no data')", "timestamp": "2024-05-28T08:55:25.939045+00:00", "logger": "__main__", "module": "main", "function": "dns_resolve", "line": 94, "task_name": "Task-86", "filename": "main.py", "exc_text": null, "msecs": 939.0, "relativeCreated": 10766.28851890564, "thread": 139900710250304, "threadName": "MainThread", "processName": "MainProcess", "process": 11627, "taskName": "Task-86"}
{"level": "ERROR", "message": "DNSError: (1, 'DNS server returned answer with no data')\nTraceback (most recent call last):\n  File \"/home/iman/Personal/TLS-Checker/TLS-Checker/TLS-Checker/main.py\", line 79, in dns_resolve\n    resp = await asyncio.wait_for(\n           ^^^^^^^^^^^^^^^^^^^^^^^\n  File \"/usr/local/lib/python3.12/asyncio/tasks.py\", line 520, in wait_for\n    return await fut\n           ^^^^^^^^^\naiodns.error.DNSError: (1, 'DNS server returned answer with no data')", "timestamp": "2024-05-28T08:55:25.939361+00:00", "logger": "__main__", "module": "main", "function": "dns_resolve", "line": 94, "task_name": "Task-12", "filename": "main.py", "exc_text": null, "msecs": 939.0, "relativeCreated": 10766.603708267212, "thread": 139900710250304, "threadName": "MainThread", "processName": "MainProcess", "process": 11627, "taskName": "Task-12"}
{"level": "ERROR", "message": "DNSError: (1, 'DNS server returned answer with no data')\nTraceback (most recent call last):\n  File \"/home/iman/Personal/TLS-Checker/TLS-Checker/TLS-Checker/main.py\", line 67, in dns_resolve\n    resp = await asyncio.wait_for(\n           ^^^^^^^^^^^^^^^^^^^^^^^\n  File \"/usr/local/lib/python3.12/asyncio/tasks.py\", line 520, in wait_for\n    return await fut\n           ^^^^^^^^^\naiodns.error.DNSError: (1, 'DNS server returned answer with no data')", "timestamp": "2024-05-28T08:55:25.942008+00:00", "logger": "__main__", "module": "main", "function": "dns_resolve", "line": 94, "task_name": "Task-98", "filename": "main.py", "exc_text": null, "msecs": 942.0, "relativeCreated": 10769.251108169556, "thread": 139900710250304, "threadName": "MainThread", "processName": "MainProcess", "process": 11627, "taskName": "Task-98"}
{"level": "ERROR", "message": "DNSError: (1, 'DNS server returned answer with no data')\nTraceback (most recent call last):\n  File \"/home/iman/Personal/TLS-Checker/TLS-Checker/TLS-Checker/main.py\", line 79, in dns_resolve\n    resp = await asyncio.wait_for(\n           ^^^^^^^^^^^^^^^^^^^^^^^\n  File \"/usr/local/lib/python3.12/asyncio/tasks.py\", line 520, in wait_for\n    return await fut\n           ^^^^^^^^^\naiodns.error.DNSError: (1, 'DNS server returned answer with no data')", "timestamp": "2024-05-28T08:55:25.952703+00:00", "logger": "__main__", "module": "main", "function": "dns_resolve", "line": 94, "task_name": "Task-18", "filename": "main.py", "exc_text": null, "msecs": 952.0, "relativeCreated": 10779.946088790894, "thread": 139900710250304, "threadName": "MainThread", "processName": "MainProcess", "process": 11627, "taskName": "Task-18"}
{"level": "ERROR", "message": "DNSError: (1, 'DNS server returned answer with no data')\nTraceback (most recent call last):\n  File \"/home/iman/Personal/TLS-Checker/TLS-Checker/TLS-Checker/main.py\", line 79, in dns_resolve\n    resp = await asyncio.wait_for(\n           ^^^^^^^^^^^^^^^^^^^^^^^\n  File \"/usr/local/lib/python3.12/asyncio/tasks.py\", line 520, in wait_for\n    return await fut\n           ^^^^^^^^^\naiodns.error.DNSError: (1, 'DNS server returned answer with no data')", "timestamp": "2024-05-28T08:55:25.958224+00:00", "logger": "__main__", "module": "main", "function": "dns_resolve", "line": 94, "task_name": "Task-47", "filename": "main.py", "exc_text": null, "msecs": 958.0, "relativeCreated": 10785.467386245728, "thread": 139900710250304, "threadName": "MainThread", "processName": "MainProcess", "process": 11627, "taskName": "Task-47"}
{"level": "ERROR", "message": "DNSError: (1, 'DNS server returned answer with no data')\nTraceback (most recent call last):\n  File \"/home/iman/Personal/TLS-Checker/TLS-Checker/TLS-Checker/main.py\", line 79, in dns_resolve\n    resp = await asyncio.wait_for(\n           ^^^^^^^^^^^^^^^^^^^^^^^\n  File \"/usr/local/lib/python3.12/asyncio/tasks.py\", line 520, in wait_for\n    return await fut\n           ^^^^^^^^^\naiodns.error.DNSError: (1, 'DNS server returned answer with no data')", "timestamp": "2024-05-28T08:55:25.959229+00:00", "logger": "__main__", "module": "main", "function": "dns_resolve", "line": 94, "task_name": "Task-9", "filename": "main.py", "exc_text": null, "msecs": 959.0, "relativeCreated": 10786.471843719482, "thread": 139900710250304, "threadName": "MainThread", "processName": "MainProcess", "process": 11627, "taskName": "Task-9"}
{"level": "ERROR", "message": "DNSError: (1, 'DNS server returned answer with no data')\nTraceback (most recent call last):\n  File \"/home/iman/Personal/TLS-Checker/TLS-Checker/TLS-Checker/main.py\", line 79, in dns_resolve\n    resp = await asyncio.wait_for(\n           ^^^^^^^^^^^^^^^^^^^^^^^\n  File \"/usr/local/lib/python3.12/asyncio/tasks.py\", line 520, in wait_for\n    return await fut\n           ^^^^^^^^^\naiodns.error.DNSError: (1, 'DNS server returned answer with no data')", "timestamp": "2024-05-28T08:55:25.962971+00:00", "logger": "__main__", "module": "main", "function": "dns_resolve", "line": 94, "task_name": "Task-43", "filename": "main.py", "exc_text": null, "msecs": 962.0, "relativeCreated": 10790.21430015564, "thread": 139900710250304, "threadName": "MainThread", "processName": "MainProcess", "process": 11627, "taskName": "Task-43"}
{"level": "ERROR", "message": "DNSError: (1, 'DNS server returned answer with no data')\nTraceback (most recent call last):\n  File \"/home/iman/Personal/TLS-Checker/TLS-Checker/TLS-Checker/main.py\", line 79, in dns_resolve\n    resp = await asyncio.wait_for(\n           ^^^^^^^^^^^^^^^^^^^^^^^\n  File \"/usr/local/lib/python3.12/asyncio/tasks.py\", line 520, in wait_for\n    return await fut\n           ^^^^^^^^^\naiodns.error.DNSError: (1, 'DNS server returned answer with no data')", "timestamp": "2024-05-28T08:55:25.964822+00:00", "logger": "__main__", "module": "main", "function": "dns_resolve", "line": 94, "task_name": "Task-34", "filename": "main.py", "exc_text": null, "msecs": 964.0, "relativeCreated": 10792.064666748047, "thread": 139900710250304, "threadName": "MainThread", "processName": "MainProcess", "process": 11627, "taskName": "Task-34"}
{"level": "ERROR", "message": "DNSError: (1, 'DNS server returned answer with no data')\nTraceback (most recent call last):\n  File \"/home/iman/Personal/TLS-Checker/TLS-Checker/TLS-Checker/main.py\", line 79, in dns_resolve\n    resp = await asyncio.wait_for(\n           ^^^^^^^^^^^^^^^^^^^^^^^\n  File \"/usr/local/lib/python3.12/asyncio/tasks.py\", line 520, in wait_for\n    return await fut\n           ^^^^^^^^^\naiodns.error.DNSError: (1, 'DNS server returned answer with no data')", "timestamp": "2024-05-28T08:55:25.966321+00:00", "logger": "__main__", "module": "main", "function": "dns_resolve", "line": 94, "task_name": "Task-13", "filename": "main.py", "exc_text": null, "msecs": 966.0, "relativeCreated": 10793.563842773438, "thread": 139900710250304, "threadName": "MainThread", "processName": "MainProcess", "process": 11627, "taskName": "Task-13"}
{"level": "ERROR", "message": "DNSError: (1, 'DNS server returned answer with no data')\nTraceback (most recent call last):\n  File \"/home/iman/Personal/TLS-Checker/TLS-Checker/TLS-Checker/main.py\", line 79, in dns_resolve\n    resp = await asyncio.wait_for(\n           ^^^^^^^^^^^^^^^^^^^^^^^\n  File \"/usr/local/lib/python3.12/asyncio/tasks.py\", line 520, in wait_for\n    return await fut\n           ^^^^^^^^^\naiodns.error.DNSError: (1, 'DNS server returned answer with no data')", "timestamp": "2024-05-28T08:55:25.966979+00:00", "logger": "__main__", "module": "main", "function": "dns_resolve", "line": 94, "task_name": "Task-49", "filename": "main.py", "exc_text": null, "msecs": 966.0, "relativeCreated": 10794.221639633179, "thread": 139900710250304, "threadName": "MainThread", "processName": "MainProcess", "process": 11627, "taskName": "Task-49"}
{"level": "ERROR", "message": "DNSError: (1, 'DNS server returned answer with no data')\nTraceback (most recent call last):\n  File \"/home/iman/Personal/TLS-Checker/TLS-Checker/TLS-Checker/main.py\", line 79, in dns_resolve\n    resp = await asyncio.wait_for(\n           ^^^^^^^^^^^^^^^^^^^^^^^\n  File \"/usr/local/lib/python3.12/asyncio/tasks.py\", line 520, in wait_for\n    return await fut\n           ^^^^^^^^^\naiodns.error.DNSError: (1, 'DNS server returned answer with no data')", "timestamp": "2024-05-28T08:55:25.973319+00:00", "logger": "__main__", "module": "main", "function": "dns_resolve", "line": 94, "task_name": "Task-39", "filename": "main.py", "exc_text": null, "msecs": 973.0, "relativeCreated": 10800.562143325806, "thread": 139900710250304, "threadName": "MainThread", "processName": "MainProcess", "process": 11627, "taskName": "Task-39"}
{"level": "ERROR", "message": "DNSError: (1, 'DNS server returned answer with no data')\nTraceback (most recent call last):\n  File \"/home/iman/Personal/TLS-Checker/TLS-Checker/TLS-Checker/main.py\", line 79, in dns_resolve\n    resp = await asyncio.wait_for(\n           ^^^^^^^^^^^^^^^^^^^^^^^\n  File \"/usr/local/lib/python3.12/asyncio/tasks.py\", line 520, in wait_for\n    return await fut\n           ^^^^^^^^^\naiodns.error.DNSError: (1, 'DNS server returned answer with no data')", "timestamp": "2024-05-28T08:55:25.982568+00:00", "logger": "__main__", "module": "main", "function": "dns_resolve", "line": 94, "task_name": "Task-72", "filename": "main.py", "exc_text": null, "msecs": 982.0, "relativeCreated": 10809.811115264893, "thread": 139900710250304, "threadName": "MainThread", "processName": "MainProcess", "process": 11627, "taskName": "Task-72"}
{"level": "ERROR", "message": "DNSError: (1, 'DNS server returned answer with no data')\nTraceback (most recent call last):\n  File \"/home/iman/Personal/TLS-Checker/TLS-Checker/TLS-Checker/main.py\", line 79, in dns_resolve\n    resp = await asyncio.wait_for(\n           ^^^^^^^^^^^^^^^^^^^^^^^\n  File \"/usr/local/lib/python3.12/asyncio/tasks.py\", line 520, in wait_for\n    return await fut\n           ^^^^^^^^^\naiodns.error.DNSError: (1, 'DNS server returned answer with no data')", "timestamp": "2024-05-28T08:55:25.986696+00:00", "logger": "__main__", "module": "main", "function": "dns_resolve", "line": 94, "task_name": "Task-58", "filename": "main.py", "exc_text": null, "msecs": 986.0, "relativeCreated": 10813.938856124878, "thread": 139900710250304, "threadName": "MainThread", "processName": "MainProcess", "process": 11627, "taskName": "Task-58"}
{"level": "ERROR", "message": "DNSError: (1, 'DNS server returned answer with no data')\nTraceback (most recent call last):\n  File \"/home/iman/Personal/TLS-Checker/TLS-Checker/TLS-Checker/main.py\", line 79, in dns_resolve\n    resp = await asyncio.wait_for(\n           ^^^^^^^^^^^^^^^^^^^^^^^\n  File \"/usr/local/lib/python3.12/asyncio/tasks.py\", line 520, in wait_for\n    return await fut\n           ^^^^^^^^^\naiodns.error.DNSError: (1, 'DNS server returned answer with no data')", "timestamp": "2024-05-28T08:55:25.997618+00:00", "logger": "__main__", "module": "main", "function": "dns_resolve", "line": 94, "task_name": "Task-91", "filename": "main.py", "exc_text": null, "msecs": 997.0, "relativeCreated": 10824.861288070679, "thread": 139900710250304, "threadName": "MainThread", "processName": "MainProcess", "process": 11627, "taskName": "Task-91"}
{"level": "ERROR", "message": "DNSError: (1, 'DNS server returned answer with no data')\nTraceback (most recent call last):\n  File \"/home/iman/Personal/TLS-Checker/TLS-Checker/TLS-Checker/main.py\", line 79, in dns_resolve\n    resp = await asyncio.wait_for(\n           ^^^^^^^^^^^^^^^^^^^^^^^\n  File \"/usr/local/lib/python3.12/asyncio/tasks.py\", line 520, in wait_for\n    return await fut\n           ^^^^^^^^^\naiodns.error.DNSError: (1, 'DNS server returned answer with no data')", "timestamp": "2024-05-28T08:55:26.001534+00:00", "logger": "__main__", "module": "main", "function": "dns_resolve", "line": 94, "task_name": "Task-64", "filename": "main.py", "exc_text": null, "msecs": 1.0, "relativeCreated": 10828.777074813843, "thread": 139900710250304, "threadName": "MainThread", "processName": "MainProcess", "process": 11627, "taskName": "Task-64"}
{"level": "ERROR", "message": "DNSError: (1, 'DNS server returned answer with no data')\nTraceback (most recent call last):\n  File \"/home/iman/Personal/TLS-Checker/TLS-Checker/TLS-Checker/main.py\", line 79, in dns_resolve\n    resp = await asyncio.wait_for(\n           ^^^^^^^^^^^^^^^^^^^^^^^\n  File \"/usr/local/lib/python3.12/asyncio/tasks.py\", line 520, in wait_for\n    return await fut\n           ^^^^^^^^^\naiodns.error.DNSError: (1, 'DNS server returned answer with no data')", "timestamp": "2024-05-28T08:55:26.002453+00:00", "logger": "__main__", "module": "main", "function": "dns_resolve", "line": 94, "task_name": "Task-100", "filename": "main.py", "exc_text": null, "msecs": 2.0, "relativeCreated": 10829.696416854858, "thread": 139900710250304, "threadName": "MainThread", "processName": "MainProcess", "process": 11627, "taskName": "Task-100"}
{"level": "ERROR", "message": "DNSError: (1, 'DNS server returned answer with no data')\nTraceback (most recent call last):\n  File \"/home/iman/Personal/TLS-Checker/TLS-Checker/TLS-Checker/main.py\", line 67, in dns_resolve\n    resp = await asyncio.wait_for(\n           ^^^^^^^^^^^^^^^^^^^^^^^\n  File \"/usr/local/lib/python3.12/asyncio/tasks.py\", line 520, in wait_for\n    return await fut\n           ^^^^^^^^^\naiodns.error.DNSError: (1, 'DNS server returned answer with no data')", "timestamp": "2024-05-28T08:55:26.003207+00:00", "logger": "__main__", "module": "main", "function": "dns_resolve", "line": 94, "task_name": "Task-51", "filename": "main.py", "exc_text": null, "msecs": 3.0, "relativeCreated": 10830.450057983398, "thread": 139900710250304, "threadName": "MainThread", "processName": "MainProcess", "process": 11627, "taskName": "Task-51"}
{"level": "ERROR", "message": "DNSError: (1, 'DNS server returned answer with no data')\nTraceback (most recent call last):\n  File \"/home/iman/Personal/TLS-Checker/TLS-Checker/TLS-Checker/main.py\", line 79, in dns_resolve\n    resp = await asyncio.wait_for(\n           ^^^^^^^^^^^^^^^^^^^^^^^\n  File \"/usr/local/lib/python3.12/asyncio/tasks.py\", line 520, in wait_for\n    return await fut\n           ^^^^^^^^^\naiodns.error.DNSError: (1, 'DNS server returned answer with no data')", "timestamp": "2024-05-28T08:55:26.028821+00:00", "logger": "__main__", "module": "main", "function": "dns_resolve", "line": 94, "task_name": "Task-21", "filename": "main.py", "exc_text": null, "msecs": 28.0, "relativeCreated": 10856.064558029175, "thread": 139900710250304, "threadName": "MainThread", "processName": "MainProcess", "process": 11627, "taskName": "Task-21"}
{"level": "ERROR", "message": "DNSError: (1, 'DNS server returned answer with no data')\nTraceback (most recent call last):\n  File \"/home/iman/Personal/TLS-Checker/TLS-Checker/TLS-Checker/main.py\", line 79, in dns_resolve\n    resp = await asyncio.wait_for(\n           ^^^^^^^^^^^^^^^^^^^^^^^\n  File \"/usr/local/lib/python3.12/asyncio/tasks.py\", line 520, in wait_for\n    return await fut\n           ^^^^^^^^^\naiodns.error.DNSError: (1, 'DNS server returned answer with no data')", "timestamp": "2024-05-28T08:55:26.039143+00:00", "logger": "__main__", "module": "main", "function": "dns_resolve", "line": 94, "task_name": "Task-11", "filename": "main.py", "exc_text": null, "msecs": 39.0, "relativeCreated": 10866.38593673706, "thread": 139900710250304, "threadName": "MainThread", "processName": "MainProcess", "process": 11627, "taskName": "Task-11"}
{"level": "ERROR", "message": "DNSError: (1, 'DNS server returned answer with no data')\nTraceback (most recent call last):\n  File \"/home/iman/Personal/TLS-Checker/TLS-Checker/TLS-Checker/main.py\", line 79, in dns_resolve\n    resp = await asyncio.wait_for(\n           ^^^^^^^^^^^^^^^^^^^^^^^\n  File \"/usr/local/lib/python3.12/asyncio/tasks.py\", line 520, in wait_for\n    return await fut\n           ^^^^^^^^^\naiodns.error.DNSError: (1, 'DNS server returned answer with no data')", "timestamp": "2024-05-28T08:55:26.060721+00:00", "logger": "__main__", "module": "main", "function": "dns_resolve", "line": 94, "task_name": "Task-29", "filename": "main.py", "exc_text": null, "msecs": 60.0, "relativeCreated": 10887.964248657227, "thread": 139900710250304, "threadName": "MainThread", "processName": "MainProcess", "process": 11627, "taskName": "Task-29"}
{"level": "ERROR", "message": "DNSError: (1, 'DNS server returned answer with no data')\nTraceback (most recent call last):\n  File \"/home/iman/Personal/TLS-Checker/TLS-Checker/TLS-Checker/main.py\", line 79, in dns_resolve\n    resp = await asyncio.wait_for(\n           ^^^^^^^^^^^^^^^^^^^^^^^\n  File \"/usr/local/lib/python3.12/asyncio/tasks.py\", line 520, in wait_for\n    return await fut\n           ^^^^^^^^^\naiodns.error.DNSError: (1, 'DNS server returned answer with no data')", "timestamp": "2024-05-28T08:55:26.086155+00:00", "logger": "__main__", "module": "main", "function": "dns_resolve", "line": 94, "task_name": "Task-93", "filename": "main.py", "exc_text": null, "msecs": 86.0, "relativeCreated": 10913.398027420044, "thread": 139900710250304, "threadName": "MainThread", "processName": "MainProcess", "process": 11627, "taskName": "Task-93"}
{"level": "ERROR", "message": "DNSError: (1, 'DNS server returned answer with no data')\nTraceback (most recent call last):\n  File \"/home/iman/Personal/TLS-Checker/TLS-Checker/TLS-Checker/main.py\", line 79, in dns_resolve\n    resp = await asyncio.wait_for(\n           ^^^^^^^^^^^^^^^^^^^^^^^\n  File \"/usr/local/lib/python3.12/asyncio/tasks.py\", line 520, in wait_for\n    return await fut\n           ^^^^^^^^^\naiodns.error.DNSError: (1, 'DNS server returned answer with no data')", "timestamp": "2024-05-28T08:55:26.086634+00:00", "logger": "__main__", "module": "main", "function": "dns_resolve", "line": 94, "task_name": "Task-69", "filename": "main.py", "exc_text": null, "msecs": 86.0, "relativeCreated": 10913.877487182617, "thread": 139900710250304, "threadName": "MainThread", "processName": "MainProcess", "process": 11627, "taskName": "Task-69"}
{"level": "ERROR", "message": "DNSError: (1, 'DNS server returned answer with no data')\nTraceback (most recent call last):\n  File \"/home/iman/Personal/TLS-Checker/TLS-Checker/TLS-Checker/main.py\", line 79, in dns_resolve\n    resp = await asyncio.wait_for(\n           ^^^^^^^^^^^^^^^^^^^^^^^\n  File \"/usr/local/lib/python3.12/asyncio/tasks.py\", line 520, in wait_for\n    return await fut\n           ^^^^^^^^^\naiodns.error.DNSError: (1, 'DNS server returned answer with no data')", "timestamp": "2024-05-28T08:55:26.109648+00:00", "logger": "__main__", "module": "main", "function": "dns_resolve", "line": 94, "task_name": "Task-50", "filename": "main.py", "exc_text": null, "msecs": 109.0, "relativeCreated": 10936.891078948975, "thread": 139900710250304, "threadName": "MainThread", "processName": "MainProcess", "process": 11627, "taskName": "Task-50"}
{"level": "ERROR", "message": "DNSError: (1, 'DNS server returned answer with no data')\nTraceback (most recent call last):\n  File \"/home/iman/Personal/TLS-Checker/TLS-Checker/TLS-Checker/main.py\", line 79, in dns_resolve\n    resp = await asyncio.wait_for(\n           ^^^^^^^^^^^^^^^^^^^^^^^\n  File \"/usr/local/lib/python3.12/asyncio/tasks.py\", line 520, in wait_for\n    return await fut\n           ^^^^^^^^^\naiodns.error.DNSError: (1, 'DNS server returned answer with no data')", "timestamp": "2024-05-28T08:55:26.157620+00:00", "logger": "__main__", "module": "main", "function": "dns_resolve", "line": 94, "task_name": "Task-17", "filename": "main.py", "exc_text": null, "msecs": 157.0, "relativeCreated": 10984.86328125, "thread": 139900710250304, "threadName": "MainThread", "processName": "MainProcess", "process": 11627, "taskName": "Task-17"}
{"level": "ERROR", "message": "DNSError: (1, 'DNS server returned answer with no data')\nTraceback (most recent call last):\n  File \"/home/iman/Personal/TLS-Checker/TLS-Checker/TLS-Checker/main.py\", line 67, in dns_resolve\n    resp = await asyncio.wait_for(\n           ^^^^^^^^^^^^^^^^^^^^^^^\n  File \"/usr/local/lib/python3.12/asyncio/tasks.py\", line 520, in wait_for\n    return await fut\n           ^^^^^^^^^\naiodns.error.DNSError: (1, 'DNS server returned answer with no data')", "timestamp": "2024-05-28T08:55:26.174222+00:00", "logger": "__main__", "module": "main", "function": "dns_resolve", "line": 94, "task_name": "Task-84", "filename": "main.py", "exc_text": null, "msecs": 174.0, "relativeCreated": 11001.465320587158, "thread": 139900710250304, "threadName": "MainThread", "processName": "MainProcess", "process": 11627, "taskName": "Task-84"}
{"level": "ERROR", "message": "DNSError: (1, 'DNS server returned answer with no data')\nTraceback (most recent call last):\n  File \"/home/iman/Personal/TLS-Checker/TLS-Checker/TLS-Checker/main.py\", line 79, in dns_resolve\n    resp = await asyncio.wait_for(\n           ^^^^^^^^^^^^^^^^^^^^^^^\n  File \"/usr/local/lib/python3.12/asyncio/tasks.py\", line 520, in wait_for\n    return await fut\n           ^^^^^^^^^\naiodns.error.DNSError: (1, 'DNS server returned answer with no data')", "timestamp": "2024-05-28T08:55:26.179398+00:00", "logger": "__main__", "module": "main", "function": "dns_resolve", "line": 94, "task_name": "Task-59", "filename": "main.py", "exc_text": null, "msecs": 179.0, "relativeCreated": 11006.640911102295, "thread": 139900710250304, "threadName": "MainThread", "processName": "MainProcess", "process": 11627, "taskName": "Task-59"}
{"level": "ERROR", "message": "DNSError: (1, 'DNS server returned answer with no data')\nTraceback (most recent call last):\n  File \"/home/iman/Personal/TLS-Checker/TLS-Checker/TLS-Checker/main.py\", line 79, in dns_resolve\n    resp = await asyncio.wait_for(\n           ^^^^^^^^^^^^^^^^^^^^^^^\n  File \"/usr/local/lib/python3.12/asyncio/tasks.py\", line 520, in wait_for\n    return await fut\n           ^^^^^^^^^\naiodns.error.DNSError: (1, 'DNS server returned answer with no data')", "timestamp": "2024-05-28T08:55:26.282953+00:00", "logger": "__main__", "module": "main", "function": "dns_resolve", "line": 94, "task_name": "Task-68", "filename": "main.py", "exc_text": null, "msecs": 282.0, "relativeCreated": 11110.196113586426, "thread": 139900710250304, "threadName": "MainThread", "processName": "MainProcess", "process": 11627, "taskName": "Task-68"}
{"level": "ERROR", "message": "DNSError: (1, 'DNS server returned answer with no data')\nTraceback (most recent call last):\n  File \"/home/iman/Personal/TLS-Checker/TLS-Checker/TLS-Checker/main.py\", line 79, in dns_resolve\n    resp = await asyncio.wait_for(\n           ^^^^^^^^^^^^^^^^^^^^^^^\n  File \"/usr/local/lib/python3.12/asyncio/tasks.py\", line 520, in wait_for\n    return await fut\n           ^^^^^^^^^\naiodns.error.DNSError: (1, 'DNS server returned answer with no data')", "timestamp": "2024-05-28T08:55:26.728446+00:00", "logger": "__main__", "module": "main", "function": "dns_resolve", "line": 94, "task_name": "Task-38", "filename": "main.py", "exc_text": null, "msecs": 728.0, "relativeCreated": 11555.688619613647, "thread": 139900710250304, "threadName": "MainThread", "processName": "MainProcess", "process": 11627, "taskName": "Task-38"}
{"level": "ERROR", "message": "DNSError: (1, 'DNS server returned answer with no data')\nTraceback (most recent call last):\n  File \"/home/iman/Personal/TLS-Checker/TLS-Checker/TLS-Checker/main.py\", line 79, in dns_resolve\n    resp = await asyncio.wait_for(\n           ^^^^^^^^^^^^^^^^^^^^^^^\n  File \"/usr/local/lib/python3.12/asyncio/tasks.py\", line 520, in wait_for\n    return await fut\n           ^^^^^^^^^\naiodns.error.DNSError: (1, 'DNS server returned answer with no data')", "timestamp": "2024-05-28T08:55:27.914366+00:00", "logger": "__main__", "module": "main", "function": "dns_resolve", "line": 94, "task_name": "Task-25", "filename": "main.py", "exc_text": null, "msecs": 914.0, "relativeCreated": 12741.60885810852, "thread": 139900710250304, "threadName": "MainThread", "processName": "MainProcess", "process": 11627, "taskName": "Task-25"}
{"level": "ERROR", "message": "Timeout Error: \nTraceback (most recent call last):\n  File \"/usr/local/lib/python3.12/asyncio/tasks.py\", line 520, in wait_for\n    return await fut\n           ^^^^^^^^^\nasyncio.exceptions.CancelledError\n\nThe above exception was the direct cause of the following exception:\n\nTraceback (most recent call last):\n  File \"/home/iman/Personal/TLS-Checker/TLS-Checker/TLS-Checker/main.py\", line 67, in dns_resolve\n    resp = await asyncio.wait_for(\n           ^^^^^^^^^^^^^^^^^^^^^^^\n  File \"/usr/local/lib/python3.12/asyncio/tasks.py\", line 519, in wait_for\n    async with timeouts.timeout(timeout):\n  File \"/usr/local/lib/python3.12/asyncio/timeouts.py\", line 115, in __aexit__\n    raise TimeoutError from exc_val\nTimeoutError", "timestamp": "2024-05-28T08:55:28.794885+00:00", "logger": "__main__", "module": "main", "function": "dns_resolve", "line": 96, "task_name": "Task-16", "filename": "main.py", "exc_text": null, "msecs": 794.0, "relativeCreated": 13622.128248214722, "thread": 139900710250304, "threadName": "MainThread", "processName": "MainProcess", "process": 11627, "taskName": "Task-16"}
{"level": "ERROR", "message": "Timeout Error: \nTraceback (most recent call last):\n  File \"/usr/local/lib/python3.12/asyncio/tasks.py\", line 520, in wait_for\n    return await fut\n           ^^^^^^^^^\nasyncio.exceptions.CancelledError\n\nThe above exception was the direct cause of the following exception:\n\nTraceback (most recent call last):\n  File \"/home/iman/Personal/TLS-Checker/TLS-Checker/TLS-Checker/main.py\", line 67, in dns_resolve\n    resp = await asyncio.wait_for(\n           ^^^^^^^^^^^^^^^^^^^^^^^\n  File \"/usr/local/lib/python3.12/asyncio/tasks.py\", line 519, in wait_for\n    async with timeouts.timeout(timeout):\n  File \"/usr/local/lib/python3.12/asyncio/timeouts.py\", line 115, in __aexit__\n    raise TimeoutError from exc_val\nTimeoutError", "timestamp": "2024-05-28T08:55:28.795531+00:00", "logger": "__main__", "module": "main", "function": "dns_resolve", "line": 96, "task_name": "Task-24", "filename": "main.py", "exc_text": null, "msecs": 795.0, "relativeCreated": 13622.773885726929, "thread": 139900710250304, "threadName": "MainThread", "processName": "MainProcess", "process": 11627, "taskName": "Task-24"}
{"level": "ERROR", "message": "Timeout Error: \nTraceback (most recent call last):\n  File \"/usr/local/lib/python3.12/asyncio/tasks.py\", line 520, in wait_for\n    return await fut\n           ^^^^^^^^^\nasyncio.exceptions.CancelledError\n\nThe above exception was the direct cause of the following exception:\n\nTraceback (most recent call last):\n  File \"/home/iman/Personal/TLS-Checker/TLS-Checker/TLS-Checker/main.py\", line 67, in dns_resolve\n    resp = await asyncio.wait_for(\n           ^^^^^^^^^^^^^^^^^^^^^^^\n  File \"/usr/local/lib/python3.12/asyncio/tasks.py\", line 519, in wait_for\n    async with timeouts.timeout(timeout):\n  File \"/usr/local/lib/python3.12/asyncio/timeouts.py\", line 115, in __aexit__\n    raise TimeoutError from exc_val\nTimeoutError", "timestamp": "2024-05-28T08:55:28.795969+00:00", "logger": "__main__", "module": "main", "function": "dns_resolve", "line": 96, "task_name": "Task-28", "filename": "main.py", "exc_text": null, "msecs": 795.0, "relativeCreated": 13623.212337493896, "thread": 139900710250304, "threadName": "MainThread", "processName": "MainProcess", "process": 11627, "taskName": "Task-28"}
{"level": "ERROR", "message": "Timeout Error: \nTraceback (most recent call last):\n  File \"/usr/local/lib/python3.12/asyncio/tasks.py\", line 520, in wait_for\n    return await fut\n           ^^^^^^^^^\nasyncio.exceptions.CancelledError\n\nThe above exception was the direct cause of the following exception:\n\nTraceback (most recent call last):\n  File \"/home/iman/Personal/TLS-Checker/TLS-Checker/TLS-Checker/main.py\", line 67, in dns_resolve\n    resp = await asyncio.wait_for(\n           ^^^^^^^^^^^^^^^^^^^^^^^\n  File \"/usr/local/lib/python3.12/asyncio/tasks.py\", line 519, in wait_for\n    async with timeouts.timeout(timeout):\n  File \"/usr/local/lib/python3.12/asyncio/timeouts.py\", line 115, in __aexit__\n    raise TimeoutError from exc_val\nTimeoutError", "timestamp": "2024-05-28T08:55:28.796433+00:00", "logger": "__main__", "module": "main", "function": "dns_resolve", "line": 96, "task_name": "Task-32", "filename": "main.py", "exc_text": null, "msecs": 796.0, "relativeCreated": 13623.676061630249, "thread": 139900710250304, "threadName": "MainThread", "processName": "MainProcess", "process": 11627, "taskName": "Task-32"}
{"level": "ERROR", "message": "Timeout Error: \nTraceback (most recent call last):\n  File \"/usr/local/lib/python3.12/asyncio/tasks.py\", line 520, in wait_for\n    return await fut\n           ^^^^^^^^^\nasyncio.exceptions.CancelledError\n\nThe above exception was the direct cause of the following exception:\n\nTraceback (most recent call last):\n  File \"/home/iman/Personal/TLS-Checker/TLS-Checker/TLS-Checker/main.py\", line 67, in dns_resolve\n    resp = await asyncio.wait_for(\n           ^^^^^^^^^^^^^^^^^^^^^^^\n  File \"/usr/local/lib/python3.12/asyncio/tasks.py\", line 519, in wait_for\n    async with timeouts.timeout(timeout):\n  File \"/usr/local/lib/python3.12/asyncio/timeouts.py\", line 115, in __aexit__\n    raise TimeoutError from exc_val\nTimeoutError", "timestamp": "2024-05-28T08:55:28.796876+00:00", "logger": "__main__", "module": "main", "function": "dns_resolve", "line": 96, "task_name": "Task-48", "filename": "main.py", "exc_text": null, "msecs": 796.0, "relativeCreated": 13624.119281768799, "thread": 139900710250304, "threadName": "MainThread", "processName": "MainProcess", "process": 11627, "taskName": "Task-48"}
{"level": "ERROR", "message": "Timeout Error: \nTraceback (most recent call last):\n  File \"/usr/local/lib/python3.12/asyncio/tasks.py\", line 520, in wait_for\n    return await fut\n           ^^^^^^^^^\nasyncio.exceptions.CancelledError\n\nThe above exception was the direct cause of the following exception:\n\nTraceback (most recent call last):\n  File \"/home/iman/Personal/TLS-Checker/TLS-Checker/TLS-Checker/main.py\", line 67, in dns_resolve\n    resp = await asyncio.wait_for(\n           ^^^^^^^^^^^^^^^^^^^^^^^\n  File \"/usr/local/lib/python3.12/asyncio/tasks.py\", line 519, in wait_for\n    async with timeouts.timeout(timeout):\n  File \"/usr/local/lib/python3.12/asyncio/timeouts.py\", line 115, in __aexit__\n    raise TimeoutError from exc_val\nTimeoutError", "timestamp": "2024-05-28T08:55:28.797494+00:00", "logger": "__main__", "module": "main", "function": "dns_resolve", "line": 96, "task_name": "Task-70", "filename": "main.py", "exc_text": null, "msecs": 797.0, "relativeCreated": 13624.73726272583, "thread": 139900710250304, "threadName": "MainThread", "processName": "MainProcess", "process": 11627, "taskName": "Task-70"}
{"level": "ERROR", "message": "Timeout Error: \nTraceback (most recent call last):\n  File \"/usr/local/lib/python3.12/asyncio/tasks.py\", line 520, in wait_for\n    return await fut\n           ^^^^^^^^^\nasyncio.exceptions.CancelledError\n\nThe above exception was the direct cause of the following exception:\n\nTraceback (most recent call last):\n  File \"/home/iman/Personal/TLS-Checker/TLS-Checker/TLS-Checker/main.py\", line 67, in dns_resolve\n    resp = await asyncio.wait_for(\n           ^^^^^^^^^^^^^^^^^^^^^^^\n  File \"/usr/local/lib/python3.12/asyncio/tasks.py\", line 519, in wait_for\n    async with timeouts.timeout(timeout):\n  File \"/usr/local/lib/python3.12/asyncio/timeouts.py\", line 115, in __aexit__\n    raise TimeoutError from exc_val\nTimeoutError", "timestamp": "2024-05-28T08:55:28.797905+00:00", "logger": "__main__", "module": "main", "function": "dns_resolve", "line": 96, "task_name": "Task-78", "filename": "main.py", "exc_text": null, "msecs": 797.0, "relativeCreated": 13625.148296356201, "thread": 139900710250304, "threadName": "MainThread", "processName": "MainProcess", "process": 11627, "taskName": "Task-78"}
{"level": "ERROR", "message": "Timeout Error: \nTraceback (most recent call last):\n  File \"/usr/local/lib/python3.12/asyncio/tasks.py\", line 520, in wait_for\n    return await fut\n           ^^^^^^^^^\nasyncio.exceptions.CancelledError\n\nThe above exception was the direct cause of the following exception:\n\nTraceback (most recent call last):\n  File \"/home/iman/Personal/TLS-Checker/TLS-Checker/TLS-Checker/main.py\", line 67, in dns_resolve\n    resp = await asyncio.wait_for(\n           ^^^^^^^^^^^^^^^^^^^^^^^\n  File \"/usr/local/lib/python3.12/asyncio/tasks.py\", line 519, in wait_for\n    async with timeouts.timeout(timeout):\n  File \"/usr/local/lib/python3.12/asyncio/timeouts.py\", line 115, in __aexit__\n    raise TimeoutError from exc_val\nTimeoutError", "timestamp": "2024-05-28T08:55:28.798264+00:00", "logger": "__main__", "module": "main", "function": "dns_resolve", "line": 96, "task_name": "Task-85", "filename": "main.py", "exc_text": null, "msecs": 798.0, "relativeCreated": 13625.50663948059, "thread": 139900710250304, "threadName": "MainThread", "processName": "MainProcess", "process": 11627, "taskName": "Task-85"}
{"level": "ERROR", "message": "Timeout Error: \nTraceback (most recent call last):\n  File \"/usr/local/lib/python3.12/asyncio/tasks.py\", line 520, in wait_for\n    return await fut\n           ^^^^^^^^^\nasyncio.exceptions.CancelledError\n\nThe above exception was the direct cause of the following exception:\n\nTraceback (most recent call last):\n  File \"/home/iman/Personal/TLS-Checker/TLS-Checker/TLS-Checker/main.py\", line 67, in dns_resolve\n    resp = await asyncio.wait_for(\n           ^^^^^^^^^^^^^^^^^^^^^^^\n  File \"/usr/local/lib/python3.12/asyncio/tasks.py\", line 519, in wait_for\n    async with timeouts.timeout(timeout):\n  File \"/usr/local/lib/python3.12/asyncio/timeouts.py\", line 115, in __aexit__\n    raise TimeoutError from exc_val\nTimeoutError", "timestamp": "2024-05-28T08:55:28.798657+00:00", "logger": "__main__", "module": "main", "function": "dns_resolve", "line": 96, "task_name": "Task-90", "filename": "main.py", "exc_text": null, "msecs": 798.0, "relativeCreated": 13625.900506973267, "thread": 139900710250304, "threadName": "MainThread", "processName": "MainProcess", "process": 11627, "taskName": "Task-90"}
{"level": "ERROR", "message": "Timeout Error: \nTraceback (most recent call last):\n  File \"/usr/local/lib/python3.12/asyncio/tasks.py\", line 520, in wait_for\n    return await fut\n           ^^^^^^^^^\nasyncio.exceptions.CancelledError\n\nThe above exception was the direct cause of the following exception:\n\nTraceback (most recent call last):\n  File \"/home/iman/Personal/TLS-Checker/TLS-Checker/TLS-Checker/main.py\", line 67, in dns_resolve\n    resp = await asyncio.wait_for(\n           ^^^^^^^^^^^^^^^^^^^^^^^\n  File \"/usr/local/lib/python3.12/asyncio/tasks.py\", line 519, in wait_for\n    async with timeouts.timeout(timeout):\n  File \"/usr/local/lib/python3.12/asyncio/timeouts.py\", line 115, in __aexit__\n    raise TimeoutError from exc_val\nTimeoutError", "timestamp": "2024-05-28T08:55:28.799110+00:00", "logger": "__main__", "module": "main", "function": "dns_resolve", "line": 96, "task_name": "Task-95", "filename": "main.py", "exc_text": null, "msecs": 799.0, "relativeCreated": 13626.35350227356, "thread": 139900710250304, "threadName": "MainThread", "processName": "MainProcess", "process": 11627, "taskName": "Task-95"}
{"level": "ERROR", "message": "Timeout Error: \nTraceback (most recent call last):\n  File \"/usr/local/lib/python3.12/asyncio/tasks.py\", line 520, in wait_for\n    return await fut\n           ^^^^^^^^^\nasyncio.exceptions.CancelledError\n\nThe above exception was the direct cause of the following exception:\n\nTraceback (most recent call last):\n  File \"/home/iman/Personal/TLS-Checker/TLS-Checker/TLS-Checker/main.py\", line 67, in dns_resolve\n    resp = await asyncio.wait_for(\n           ^^^^^^^^^^^^^^^^^^^^^^^\n  File \"/usr/local/lib/python3.12/asyncio/tasks.py\", line 519, in wait_for\n    async with timeouts.timeout(timeout):\n  File \"/usr/local/lib/python3.12/asyncio/timeouts.py\", line 115, in __aexit__\n    raise TimeoutError from exc_val\nTimeoutError", "timestamp": "2024-05-28T08:55:28.800060+00:00", "logger": "__main__", "module": "main", "function": "dns_resolve", "line": 96, "task_name": "Task-99", "filename": "main.py", "exc_text": null, "msecs": 800.0, "relativeCreated": 13627.302646636963, "thread": 139900710250304, "threadName": "MainThread", "processName": "MainProcess", "process": 11627, "taskName": "Task-99"}
{"level": "INFO", "message": "Saving data into output.db was successfully", "timestamp": "2024-05-28T08:55:28.828626+00:00", "logger": "__main__", "module": "main", "function": "main", "line": 242, "task_name": "Task-1", "filename": "main.py", "exc_text": null, "msecs": 828.0, "relativeCreated": 13655.869483947754, "thread": 139900710250304, "threadName": "MainThread", "processName": "MainProcess", "process": 11627, "taskName": "Task-1"}
{"level": "INFO", "message": "Successfully converted", "timestamp": "2024-05-28T08:55:28.872153+00:00", "logger": "csv_convertor", "module": "csv_convertor", "function": "convertor", "line": 109, "task_name": "Task-1", "filename": "csv_convertor.py", "exc_text": null, "msecs": 872.0, "relativeCreated": 13699.395895004272, "thread": 139900710250304, "threadName": "MainThread", "processName": "MainProcess", "process": 11627, "taskName": "Task-1"}
{"level": "INFO", "message": "Database successfully converted to csv file", "timestamp": "2024-05-28T08:55:28.873596+00:00", "logger": "__main__", "module": "main", "function": "main", "line": 245, "task_name": "Task-1", "filename": "main.py", "exc_text": null, "msecs": 873.0, "relativeCreated": 13700.838804244995, "thread": 139900710250304, "threadName": "MainThread", "processName": "MainProcess", "process": 11627, "taskName": "Task-1"}
{"level": "INFO", "message": "App was finished gracefully", "timestamp": "2024-05-28T08:55:28.962605+00:00", "logger": "__main__", "module": "main", "function": "<module>", "line": 260, "task_name": null, "filename": "main.py", "exc_text": null, "msecs": 962.0, "relativeCreated": 13789.848327636719, "thread": 139900710250304, "threadName": "MainThread", "processName": "MainProcess", "process": 11627, "taskName": null}
