{"level": "INFO", "message": "Start reading input.csv", "timestamp": "2024-05-28T09:22:39.153721+00:00", "logger": "__main__", "module": "main", "function": "open_csv", "line": 103, "task_name": "Task-1", "filename": "main.py", "exc_text": null, "msecs": 153.0, "relativeCreated": 181.5345287322998, "thread": 139919965337408, "threadName": "MainThread", "processName": "MainProcess", "process": 13249, "taskName": "Task-1"}
{"level": "INFO", "message": "Successfully extracted domains from input.csv", "timestamp": "2024-05-28T09:22:42.113069+00:00", "logger": "__main__", "module": "main", "function": "open_csv", "line": 112, "task_name": "Task-1", "filename": "main.py", "exc_text": null, "msecs": 113.0, "relativeCreated": 3140.8822536468506, "thread": 139919965337408, "threadName": "MainThread", "processName": "MainProcess", "process": 13249, "taskName": "Task-1"}
{"level": "INFO", "message": "Start config before scanning", "timestamp": "2024-05-28T09:22:42.113185+00:00", "logger": "__main__", "module": "main", "function": "create_tasks", "line": 157, "task_name": "Task-1", "filename": "main.py", "exc_text": null, "msecs": 113.0, "relativeCreated": 3140.998601913452, "thread": 139919965337408, "threadName": "MainThread", "processName": "MainProcess", "process": 13249, "taskName": "Task-1"}
{"level": "INFO", "message": "domain_chunk was set to 100", "timestamp": "2024-05-28T09:22:46.878691+00:00", "logger": "__main__", "module": "main", "function": "create_tasks", "line": 171, "task_name": "Task-1", "filename": "main.py", "exc_text": null, "msecs": 878.0, "relativeCreated": 7906.504154205322, "thread": 139919965337408, "threadName": "MainThread", "processName": "MainProcess", "process": 13249, "taskName": "Task-1"}
{"level": "ERROR", "message": "Invalid value for active tasks: invalid literal for int() with base 10: ''", "timestamp": "2024-05-28T09:23:10.396554+00:00", "logger": "__main__", "module": "main", "function": "create_tasks", "line": 192, "task_name": "Task-1", "filename": "main.py", "exc_text": null, "msecs": 396.0, "relativeCreated": 31424.367427825928, "thread": 139919965337408, "threadName": "MainThread", "processName": "MainProcess", "process": 13249, "taskName": "Task-1"}
{"level": "ERROR", "message": "Invalid value for timeout: invalid literal for int() with base 10: ''", "timestamp": "2024-05-28T09:23:10.829529+00:00", "logger": "__main__", "module": "main", "function": "create_tasks", "line": 203, "task_name": "Task-1", "filename": "main.py", "exc_text": null, "msecs": 829.0, "relativeCreated": 31857.342004776, "thread": 139919965337408, "threadName": "MainThread", "processName": "MainProcess", "process": 13249, "taskName": "Task-1"}
{"level": "ERROR", "message": "DNSError: (1, 'DNS server returned answer with no data')\nTraceback (most recent call last):\n  File \"/home/iman/Personal/TLS-Checker/TLS-Checker/TLS-Checker/main.py\", line 67, in dns_resolve\n    resp = await asyncio.wait_for(\n           ^^^^^^^^^^^^^^^^^^^^^^^\n  File \"/usr/local/lib/python3.12/asyncio/tasks.py\", line 520, in wait_for\n    return await fut\n           ^^^^^^^^^\naiodns.error.DNSError: (1, 'DNS server returned answer with no data')", "timestamp": "2024-05-28T09:23:10.967970+00:00", "logger": "__main__", "module": "main", "function": "dns_resolve", "line": 94, "task_name": "Task-22", "filename": "main.py", "exc_text": null, "msecs": 967.0, "relativeCreated": 31995.78356742859, "thread": 139919965337408, "threadName": "MainThread", "processName": "MainProcess", "process": 13249, "taskName": "Task-22"}
{"level": "ERROR", "message": "DNSError: (1, 'DNS server returned answer with no data')\nTraceback (most recent call last):\n  File \"/home/iman/Personal/TLS-Checker/TLS-Checker/TLS-Checker/main.py\", line 67, in dns_resolve\n    resp = await asyncio.wait_for(\n           ^^^^^^^^^^^^^^^^^^^^^^^\n  File \"/usr/local/lib/python3.12/asyncio/tasks.py\", line 520, in wait_for\n    return await fut\n           ^^^^^^^^^\naiodns.error.DNSError: (1, 'DNS server returned answer with no data')", "timestamp": "2024-05-28T09:23:10.969548+00:00", "logger": "__main__", "module": "main", "function": "dns_resolve", "line": 94, "task_name": "Task-24", "filename": "main.py", "exc_text": null, "msecs": 969.0, "relativeCreated": 31997.361183166504, "thread": 139919965337408, "threadName": "MainThread", "processName": "MainProcess", "process": 13249, "taskName": "Task-24"}
{"level": "ERROR", "message": "DNSError: (1, 'DNS server returned answer with no data')\nTraceback (most recent call last):\n  File \"/home/iman/Personal/TLS-Checker/TLS-Checker/TLS-Checker/main.py\", line 67, in dns_resolve\n    resp = await asyncio.wait_for(\n           ^^^^^^^^^^^^^^^^^^^^^^^\n  File \"/usr/local/lib/python3.12/asyncio/tasks.py\", line 520, in wait_for\n    return await fut\n           ^^^^^^^^^\naiodns.error.DNSError: (1, 'DNS server returned answer with no data')", "timestamp": "2024-05-28T09:23:10.970173+00:00", "logger": "__main__", "module": "main", "function": "dns_resolve", "line": 94, "task_name": "Task-4", "filename": "main.py", "exc_text": null, "msecs": 970.0, "relativeCreated": 31997.986793518066, "thread": 139919965337408, "threadName": "MainThread", "processName": "MainProcess", "process": 13249, "taskName": "Task-4"}
{"level": "ERROR", "message": "DNSError: (1, 'DNS server returned answer with no data')\nTraceback (most recent call last):\n  File \"/home/iman/Personal/TLS-Checker/TLS-Checker/TLS-Checker/main.py\", line 67, in dns_resolve\n    resp = await asyncio.wait_for(\n           ^^^^^^^^^^^^^^^^^^^^^^^\n  File \"/usr/local/lib/python3.12/asyncio/tasks.py\", line 520, in wait_for\n    return await fut\n           ^^^^^^^^^\naiodns.error.DNSError: (1, 'DNS server returned answer with no data')", "timestamp": "2024-05-28T09:23:10.970599+00:00", "logger": "__main__", "module": "main", "function": "dns_resolve", "line": 94, "task_name": "Task-26", "filename": "main.py", "exc_text": null, "msecs": 970.0, "relativeCreated": 31998.412132263184, "thread": 139919965337408, "threadName": "MainThread", "processName": "MainProcess", "process": 13249, "taskName": "Task-26"}
{"level": "ERROR", "message": "DNSError: (1, 'DNS server returned answer with no data')\nTraceback (most recent call last):\n  File \"/home/iman/Personal/TLS-Checker/TLS-Checker/TLS-Checker/main.py\", line 67, in dns_resolve\n    resp = await asyncio.wait_for(\n           ^^^^^^^^^^^^^^^^^^^^^^^\n  File \"/usr/local/lib/python3.12/asyncio/tasks.py\", line 520, in wait_for\n    return await fut\n           ^^^^^^^^^\naiodns.error.DNSError: (1, 'DNS server returned answer with no data')", "timestamp": "2024-05-28T09:23:10.992810+00:00", "logger": "__main__", "module": "main", "function": "dns_resolve", "line": 94, "task_name": "Task-32", "filename": "main.py", "exc_text": null, "msecs": 992.0, "relativeCreated": 32020.623207092285, "thread": 139919965337408, "threadName": "MainThread", "processName": "MainProcess", "process": 13249, "taskName": "Task-32"}
{"level": "ERROR", "message": "DNSError: (1, 'DNS server returned answer with no data')\nTraceback (most recent call last):\n  File \"/home/iman/Personal/TLS-Checker/TLS-Checker/TLS-Checker/main.py\", line 67, in dns_resolve\n    resp = await asyncio.wait_for(\n           ^^^^^^^^^^^^^^^^^^^^^^^\n  File \"/usr/local/lib/python3.12/asyncio/tasks.py\", line 520, in wait_for\n    return await fut\n           ^^^^^^^^^\naiodns.error.DNSError: (1, 'DNS server returned answer with no data')", "timestamp": "2024-05-28T09:23:10.993636+00:00", "logger": "__main__", "module": "main", "function": "dns_resolve", "line": 94, "task_name": "Task-48", "filename": "main.py", "exc_text": null, "msecs": 993.0, "relativeCreated": 32021.449327468872, "thread": 139919965337408, "threadName": "MainThread", "processName": "MainProcess", "process": 13249, "taskName": "Task-48"}
{"level": "ERROR", "message": "DNSError: (1, 'DNS server returned answer with no data')\nTraceback (most recent call last):\n  File \"/home/iman/Personal/TLS-Checker/TLS-Checker/TLS-Checker/main.py\", line 79, in dns_resolve\n    resp = await asyncio.wait_for(\n           ^^^^^^^^^^^^^^^^^^^^^^^\n  File \"/usr/local/lib/python3.12/asyncio/tasks.py\", line 520, in wait_for\n    return await fut\n           ^^^^^^^^^\naiodns.error.DNSError: (1, 'DNS server returned answer with no data')", "timestamp": "2024-05-28T09:23:10.993893+00:00", "logger": "__main__", "module": "main", "function": "dns_resolve", "line": 94, "task_name": "Task-8", "filename": "main.py", "exc_text": null, "msecs": 993.0, "relativeCreated": 32021.706581115723, "thread": 139919965337408, "threadName": "MainThread", "processName": "MainProcess", "process": 13249, "taskName": "Task-8"}
{"level": "ERROR", "message": "DNSError: (1, 'DNS server returned answer with no data')\nTraceback (most recent call last):\n  File \"/home/iman/Personal/TLS-Checker/TLS-Checker/TLS-Checker/main.py\", line 79, in dns_resolve\n    resp = await asyncio.wait_for(\n           ^^^^^^^^^^^^^^^^^^^^^^^\n  File \"/usr/local/lib/python3.12/asyncio/tasks.py\", line 520, in wait_for\n    return await fut\n           ^^^^^^^^^\naiodns.error.DNSError: (1, 'DNS server returned answer with no data')", "timestamp": "2024-05-28T09:23:10.994220+00:00", "logger": "__main__", "module": "main", "function": "dns_resolve", "line": 94, "task_name": "Task-6", "filename": "main.py", "exc_text": null, "msecs": 994.0, "relativeCreated": 32022.03392982483, "thread": 139919965337408, "threadName": "MainThread", "processName": "MainProcess", "process": 13249, "taskName": "Task-6"}
{"level": "ERROR", "message": "DNSError: (1, 'DNS server returned answer with no data')\nTraceback (most recent call last):\n  File \"/home/iman/Personal/TLS-Checker/TLS-Checker/TLS-Checker/main.py\", line 79, in dns_resolve\n    resp = await asyncio.wait_for(\n           ^^^^^^^^^^^^^^^^^^^^^^^\n  File \"/usr/local/lib/python3.12/asyncio/tasks.py\", line 520, in wait_for\n    return await fut\n           ^^^^^^^^^\naiodns.error.DNSError: (1, 'DNS server returned answer with no data')", "timestamp": "2024-05-28T09:23:10.994481+00:00", "logger": "__main__", "module": "main", "function": "dns_resolve", "line": 94, "task_name": "Task-7", "filename": "main.py", "exc_text": null, "msecs": 994.0, "relativeCreated": 32022.294521331787, "thread": 139919965337408, "threadName": "MainThread", "processName": "MainProcess", "process": 13249, "taskName": "Task-7"}
{"level": "ERROR", "message": "DNSError: (1, 'DNS server returned answer with no data')\nTraceback (most recent call last):\n  File \"/home/iman/Personal/TLS-Checker/TLS-Checker/TLS-Checker/main.py\", line 79, in dns_resolve\n    resp = await asyncio.wait_for(\n           ^^^^^^^^^^^^^^^^^^^^^^^\n  File \"/usr/local/lib/python3.12/asyncio/tasks.py\", line 520, in wait_for\n    return await fut\n           ^^^^^^^^^\naiodns.error.DNSError: (1, 'DNS server returned answer with no data')", "timestamp": "2024-05-28T09:23:10.994977+00:00", "logger": "__main__", "module": "main", "function": "dns_resolve", "line": 94, "task_name": "Task-15", "filename": "main.py", "exc_text": null, "msecs": 994.0, "relativeCreated": 32022.790670394897, "thread": 139919965337408, "threadName": "MainThread", "processName": "MainProcess", "process": 13249, "taskName": "Task-15"}
{"level": "ERROR", "message": "DNSError: (1, 'DNS server returned answer with no data')\nTraceback (most recent call last):\n  File \"/home/iman/Personal/TLS-Checker/TLS-Checker/TLS-Checker/main.py\", line 79, in dns_resolve\n    resp = await asyncio.wait_for(\n           ^^^^^^^^^^^^^^^^^^^^^^^\n  File \"/usr/local/lib/python3.12/asyncio/tasks.py\", line 520, in wait_for\n    return await fut\n           ^^^^^^^^^\naiodns.error.DNSError: (1, 'DNS server returned answer with no data')", "timestamp": "2024-05-28T09:23:10.995974+00:00", "logger": "__main__", "module": "main", "function": "dns_resolve", "line": 94, "task_name": "Task-19", "filename": "main.py", "exc_text": null, "msecs": 995.0, "relativeCreated": 32023.7877368927, "thread": 139919965337408, "threadName": "MainThread", "processName": "MainProcess", "process": 13249, "taskName": "Task-19"}
{"level": "ERROR", "message": "DNSError: (1, 'DNS server returned answer with no data')\nTraceback (most recent call last):\n  File \"/home/iman/Personal/TLS-Checker/TLS-Checker/TLS-Checker/main.py\", line 79, in dns_resolve\n    resp = await asyncio.wait_for(\n           ^^^^^^^^^^^^^^^^^^^^^^^\n  File \"/usr/local/lib/python3.12/asyncio/tasks.py\", line 520, in wait_for\n    return await fut\n           ^^^^^^^^^\naiodns.error.DNSError: (1, 'DNS server returned answer with no data')", "timestamp": "2024-05-28T09:23:10.996520+00:00", "logger": "__main__", "module": "main", "function": "dns_resolve", "line": 94, "task_name": "Task-76", "filename": "main.py", "exc_text": null, "msecs": 996.0, "relativeCreated": 32024.333477020264, "thread": 139919965337408, "threadName": "MainThread", "processName": "MainProcess", "process": 13249, "taskName": "Task-76"}
{"level": "ERROR", "message": "DNSError: (1, 'DNS server returned answer with no data')\nTraceback (most recent call last):\n  File \"/home/iman/Personal/TLS-Checker/TLS-Checker/TLS-Checker/main.py\", line 79, in dns_resolve\n    resp = await asyncio.wait_for(\n           ^^^^^^^^^^^^^^^^^^^^^^^\n  File \"/usr/local/lib/python3.12/asyncio/tasks.py\", line 520, in wait_for\n    return await fut\n           ^^^^^^^^^\naiodns.error.DNSError: (1, 'DNS server returned answer with no data')", "timestamp": "2024-05-28T09:23:10.997088+00:00", "logger": "__main__", "module": "main", "function": "dns_resolve", "line": 94, "task_name": "Task-74", "filename": "main.py", "exc_text": null, "msecs": 997.0, "relativeCreated": 32024.901390075684, "thread": 139919965337408, "threadName": "MainThread", "processName": "MainProcess", "process": 13249, "taskName": "Task-74"}
{"level": "ERROR", "message": "DNSError: (1, 'DNS server returned answer with no data')\nTraceback (most recent call last):\n  File \"/home/iman/Personal/TLS-Checker/TLS-Checker/TLS-Checker/main.py\", line 79, in dns_resolve\n    resp = await asyncio.wait_for(\n           ^^^^^^^^^^^^^^^^^^^^^^^\n  File \"/usr/local/lib/python3.12/asyncio/tasks.py\", line 520, in wait_for\n    return await fut\n           ^^^^^^^^^\naiodns.error.DNSError: (1, 'DNS server returned answer with no data')", "timestamp": "2024-05-28T09:23:10.997515+00:00", "logger": "__main__", "module": "main", "function": "dns_resolve", "line": 94, "task_name": "Task-73", "filename": "main.py", "exc_text": null, "msecs": 997.0, "relativeCreated": 32025.328874588013, "thread": 139919965337408, "threadName": "MainThread", "processName": "MainProcess", "process": 13249, "taskName": "Task-73"}
{"level": "ERROR", "message": "DNSError: (1, 'DNS server returned answer with no data')\nTraceback (most recent call last):\n  File \"/home/iman/Personal/TLS-Checker/TLS-Checker/TLS-Checker/main.py\", line 79, in dns_resolve\n    resp = await asyncio.wait_for(\n           ^^^^^^^^^^^^^^^^^^^^^^^\n  File \"/usr/local/lib/python3.12/asyncio/tasks.py\", line 520, in wait_for\n    return await fut\n           ^^^^^^^^^\naiodns.error.DNSError: (1, 'DNS server returned answer with no data')", "timestamp": "2024-05-28T09:23:10.997804+00:00", "logger": "__main__", "module": "main", "function": "dns_resolve", "line": 94, "task_name": "Task-20", "filename": "main.py", "exc_text": null, "msecs": 997.0, "relativeCreated": 32025.617837905884, "thread": 139919965337408, "threadName": "MainThread", "processName": "MainProcess", "process": 13249, "taskName": "Task-20"}
{"level": "ERROR", "message": "DNSError: (1, 'DNS server returned answer with no data')\nTraceback (most recent call last):\n  File \"/home/iman/Personal/TLS-Checker/TLS-Checker/TLS-Checker/main.py\", line 79, in dns_resolve\n    resp = await asyncio.wait_for(\n           ^^^^^^^^^^^^^^^^^^^^^^^\n  File \"/usr/local/lib/python3.12/asyncio/tasks.py\", line 520, in wait_for\n    return await fut\n           ^^^^^^^^^\naiodns.error.DNSError: (1, 'DNS server returned answer with no data')", "timestamp": "2024-05-28T09:23:10.999657+00:00", "logger": "__main__", "module": "main", "function": "dns_resolve", "line": 94, "task_name": "Task-28", "filename": "main.py", "exc_text": null, "msecs": 999.0, "relativeCreated": 32027.47082710266, "thread": 139919965337408, "threadName": "MainThread", "processName": "MainProcess", "process": 13249, "taskName": "Task-28"}
{"level": "ERROR", "message": "DNSError: (1, 'DNS server returned answer with no data')\nTraceback (most recent call last):\n  File \"/home/iman/Personal/TLS-Checker/TLS-Checker/TLS-Checker/main.py\", line 79, in dns_resolve\n    resp = await asyncio.wait_for(\n           ^^^^^^^^^^^^^^^^^^^^^^^\n  File \"/usr/local/lib/python3.12/asyncio/tasks.py\", line 520, in wait_for\n    return await fut\n           ^^^^^^^^^\naiodns.error.DNSError: (1, 'DNS server returned answer with no data')", "timestamp": "2024-05-28T09:23:11.000027+00:00", "logger": "__main__", "module": "main", "function": "dns_resolve", "line": 94, "task_name": "Task-60", "filename": "main.py", "exc_text": null, "msecs": 0.0, "relativeCreated": 32027.84013748169, "thread": 139919965337408, "threadName": "MainThread", "processName": "MainProcess", "process": 13249, "taskName": "Task-60"}
{"level": "ERROR", "message": "DNSError: (1, 'DNS server returned answer with no data')\nTraceback (most recent call last):\n  File \"/home/iman/Personal/TLS-Checker/TLS-Checker/TLS-Checker/main.py\", line 67, in dns_resolve\n    resp = await asyncio.wait_for(\n           ^^^^^^^^^^^^^^^^^^^^^^^\n  File \"/usr/local/lib/python3.12/asyncio/tasks.py\", line 520, in wait_for\n    return await fut\n           ^^^^^^^^^\naiodns.error.DNSError: (1, 'DNS server returned answer with no data')", "timestamp": "2024-05-28T09:23:11.000285+00:00", "logger": "__main__", "module": "main", "function": "dns_resolve", "line": 94, "task_name": "Task-44", "filename": "main.py", "exc_text": null, "msecs": 0.0, "relativeCreated": 32028.098821640015, "thread": 139919965337408, "threadName": "MainThread", "processName": "MainProcess", "process": 13249, "taskName": "Task-44"}
{"level": "ERROR", "message": "DNSError: (1, 'DNS server returned answer with no data')\nTraceback (most recent call last):\n  File \"/home/iman/Personal/TLS-Checker/TLS-Checker/TLS-Checker/main.py\", line 79, in dns_resolve\n    resp = await asyncio.wait_for(\n           ^^^^^^^^^^^^^^^^^^^^^^^\n  File \"/usr/local/lib/python3.12/asyncio/tasks.py\", line 520, in wait_for\n    return await fut\n           ^^^^^^^^^\naiodns.error.DNSError: (1, 'DNS server returned answer with no data')", "timestamp": "2024-05-28T09:23:11.001664+00:00", "logger": "__main__", "module": "main", "function": "dns_resolve", "line": 94, "task_name": "Task-31", "filename": "main.py", "exc_text": null, "msecs": 1.0, "relativeCreated": 32029.47759628296, "thread": 139919965337408, "threadName": "MainThread", "processName": "MainProcess", "process": 13249, "taskName": "Task-31"}
{"level": "ERROR", "message": "DNSError: (1, 'DNS server returned answer with no data')\nTraceback (most recent call last):\n  File \"/home/iman/Personal/TLS-Checker/TLS-Checker/TLS-Checker/main.py\", line 67, in dns_resolve\n    resp = await asyncio.wait_for(\n           ^^^^^^^^^^^^^^^^^^^^^^^\n  File \"/usr/local/lib/python3.12/asyncio/tasks.py\", line 520, in wait_for\n    return await fut\n           ^^^^^^^^^\naiodns.error.DNSError: (1, 'DNS server returned answer with no data')", "timestamp": "2024-05-28T09:23:11.002023+00:00", "logger": "__main__", "module": "main", "function": "dns_resolve", "line": 94, "task_name": "Task-54", "filename": "main.py", "exc_text": null, "msecs": 2.0, "relativeCreated": 32029.836177825928, "thread": 139919965337408, "threadName": "MainThread", "processName": "MainProcess", "process": 13249, "taskName": "Task-54"}
{"level": "ERROR", "message": "DNSError: (1, 'DNS server returned answer with no data')\nTraceback (most recent call last):\n  File \"/home/iman/Personal/TLS-Checker/TLS-Checker/TLS-Checker/main.py\", line 79, in dns_resolve\n    resp = await asyncio.wait_for(\n           ^^^^^^^^^^^^^^^^^^^^^^^\n  File \"/usr/local/lib/python3.12/asyncio/tasks.py\", line 520, in wait_for\n    return await fut\n           ^^^^^^^^^\naiodns.error.DNSError: (1, 'DNS server returned answer with no data')", "timestamp": "2024-05-28T09:23:11.002513+00:00", "logger": "__main__", "module": "main", "function": "dns_resolve", "line": 94, "task_name": "Task-27", "filename": "main.py", "exc_text": null, "msecs": 2.0, "relativeCreated": 32030.32660484314, "thread": 139919965337408, "threadName": "MainThread", "processName": "MainProcess", "process": 13249, "taskName": "Task-27"}
{"level": "ERROR", "message": "DNSError: (1, 'DNS server returned answer with no data')\nTraceback (most recent call last):\n  File \"/home/iman/Personal/TLS-Checker/TLS-Checker/TLS-Checker/main.py\", line 79, in dns_resolve\n    resp = await asyncio.wait_for(\n           ^^^^^^^^^^^^^^^^^^^^^^^\n  File \"/usr/local/lib/python3.12/asyncio/tasks.py\", line 520, in wait_for\n    return await fut\n           ^^^^^^^^^\naiodns.error.DNSError: (1, 'DNS server returned answer with no data')", "timestamp": "2024-05-28T09:23:11.003653+00:00", "logger": "__main__", "module": "main", "function": "dns_resolve", "line": 94, "task_name": "Task-42", "filename": "main.py", "exc_text": null, "msecs": 3.0, "relativeCreated": 32031.466245651245, "thread": 139919965337408, "threadName": "MainThread", "processName": "MainProcess", "process": 13249, "taskName": "Task-42"}
{"level": "ERROR", "message": "DNSError: (1, 'DNS server returned answer with no data')\nTraceback (most recent call last):\n  File \"/home/iman/Personal/TLS-Checker/TLS-Checker/TLS-Checker/main.py\", line 79, in dns_resolve\n    resp = await asyncio.wait_for(\n           ^^^^^^^^^^^^^^^^^^^^^^^\n  File \"/usr/local/lib/python3.12/asyncio/tasks.py\", line 520, in wait_for\n    return await fut\n           ^^^^^^^^^\naiodns.error.DNSError: (1, 'DNS server returned answer with no data')", "timestamp": "2024-05-28T09:23:11.004041+00:00", "logger": "__main__", "module": "main", "function": "dns_resolve", "line": 94, "task_name": "Task-35", "filename": "main.py", "exc_text": null, "msecs": 4.0, "relativeCreated": 32031.854391098022, "thread": 139919965337408, "threadName": "MainThread", "processName": "MainProcess", "process": 13249, "taskName": "Task-35"}
{"level": "ERROR", "message": "DNSError: (1, 'DNS server returned answer with no data')\nTraceback (most recent call last):\n  File \"/home/iman/Personal/TLS-Checker/TLS-Checker/TLS-Checker/main.py\", line 67, in dns_resolve\n    resp = await asyncio.wait_for(\n           ^^^^^^^^^^^^^^^^^^^^^^^\n  File \"/usr/local/lib/python3.12/asyncio/tasks.py\", line 520, in wait_for\n    return await fut\n           ^^^^^^^^^\naiodns.error.DNSError: (1, 'DNS server returned answer with no data')", "timestamp": "2024-05-28T09:23:11.004289+00:00", "logger": "__main__", "module": "main", "function": "dns_resolve", "line": 94, "task_name": "Task-55", "filename": "main.py", "exc_text": null, "msecs": 4.0, "relativeCreated": 32032.10210800171, "thread": 139919965337408, "threadName": "MainThread", "processName": "MainProcess", "process": 13249, "taskName": "Task-55"}
{"level": "ERROR", "message": "DNSError: (1, 'DNS server returned answer with no data')\nTraceback (most recent call last):\n  File \"/home/iman/Personal/TLS-Checker/TLS-Checker/TLS-Checker/main.py\", line 79, in dns_resolve\n    resp = await asyncio.wait_for(\n           ^^^^^^^^^^^^^^^^^^^^^^^\n  File \"/usr/local/lib/python3.12/asyncio/tasks.py\", line 520, in wait_for\n    return await fut\n           ^^^^^^^^^\naiodns.error.DNSError: (1, 'DNS server returned answer with no data')", "timestamp": "2024-05-28T09:23:11.004534+00:00", "logger": "__main__", "module": "main", "function": "dns_resolve", "line": 94, "task_name": "Task-80", "filename": "main.py", "exc_text": null, "msecs": 4.0, "relativeCreated": 32032.347679138184, "thread": 139919965337408, "threadName": "MainThread", "processName": "MainProcess", "process": 13249, "taskName": "Task-80"}
{"level": "ERROR", "message": "DNSError: (1, 'DNS server returned answer with no data')\nTraceback (most recent call last):\n  File \"/home/iman/Personal/TLS-Checker/TLS-Checker/TLS-Checker/main.py\", line 79, in dns_resolve\n    resp = await asyncio.wait_for(\n           ^^^^^^^^^^^^^^^^^^^^^^^\n  File \"/usr/local/lib/python3.12/asyncio/tasks.py\", line 520, in wait_for\n    return await fut\n           ^^^^^^^^^\naiodns.error.DNSError: (1, 'DNS server returned answer with no data')", "timestamp": "2024-05-28T09:23:11.004773+00:00", "logger": "__main__", "module": "main", "function": "dns_resolve", "line": 94, "task_name": "Task-77", "filename": "main.py", "exc_text": null, "msecs": 4.0, "relativeCreated": 32032.586336135864, "thread": 139919965337408, "threadName": "MainThread", "processName": "MainProcess", "process": 13249, "taskName": "Task-77"}
{"level": "ERROR", "message": "DNSError: (1, 'DNS server returned answer with no data')\nTraceback (most recent call last):\n  File \"/home/iman/Personal/TLS-Checker/TLS-Checker/TLS-Checker/main.py\", line 79, in dns_resolve\n    resp = await asyncio.wait_for(\n           ^^^^^^^^^^^^^^^^^^^^^^^\n  File \"/usr/local/lib/python3.12/asyncio/tasks.py\", line 520, in wait_for\n    return await fut\n           ^^^^^^^^^\naiodns.error.DNSError: (1, 'DNS server returned answer with no data')", "timestamp": "2024-05-28T09:23:11.005120+00:00", "logger": "__main__", "module": "main", "function": "dns_resolve", "line": 94, "task_name": "Task-85", "filename": "main.py", "exc_text": null, "msecs": 5.0, "relativeCreated": 32032.933712005615, "thread": 139919965337408, "threadName": "MainThread", "processName": "MainProcess", "process": 13249, "taskName": "Task-85"}
{"level": "ERROR", "message": "DNSError: (1, 'DNS server returned answer with no data')\nTraceback (most recent call last):\n  File \"/home/iman/Personal/TLS-Checker/TLS-Checker/TLS-Checker/main.py\", line 79, in dns_resolve\n    resp = await asyncio.wait_for(\n           ^^^^^^^^^^^^^^^^^^^^^^^\n  File \"/usr/local/lib/python3.12/asyncio/tasks.py\", line 520, in wait_for\n    return await fut\n           ^^^^^^^^^\naiodns.error.DNSError: (1, 'DNS server returned answer with no data')", "timestamp": "2024-05-28T09:23:11.005469+00:00", "logger": "__main__", "module": "main", "function": "dns_resolve", "line": 94, "task_name": "Task-82", "filename": "main.py", "exc_text": null, "msecs": 5.0, "relativeCreated": 32033.28275680542, "thread": 139919965337408, "threadName": "MainThread", "processName": "MainProcess", "process": 13249, "taskName": "Task-82"}
{"level": "ERROR", "message": "DNSError: (1, 'DNS server returned answer with no data')\nTraceback (most recent call last):\n  File \"/home/iman/Personal/TLS-Checker/TLS-Checker/TLS-Checker/main.py\", line 79, in dns_resolve\n    resp = await asyncio.wait_for(\n           ^^^^^^^^^^^^^^^^^^^^^^^\n  File \"/usr/local/lib/python3.12/asyncio/tasks.py\", line 520, in wait_for\n    return await fut\n           ^^^^^^^^^\naiodns.error.DNSError: (1, 'DNS server returned answer with no data')", "timestamp": "2024-05-28T09:23:11.005713+00:00", "logger": "__main__", "module": "main", "function": "dns_resolve", "line": 94, "task_name": "Task-81", "filename": "main.py", "exc_text": null, "msecs": 5.0, "relativeCreated": 32033.52642059326, "thread": 139919965337408, "threadName": "MainThread", "processName": "MainProcess", "process": 13249, "taskName": "Task-81"}
{"level": "ERROR", "message": "DNSError: (1, 'DNS server returned answer with no data')\nTraceback (most recent call last):\n  File \"/home/iman/Personal/TLS-Checker/TLS-Checker/TLS-Checker/main.py\", line 79, in dns_resolve\n    resp = await asyncio.wait_for(\n           ^^^^^^^^^^^^^^^^^^^^^^^\n  File \"/usr/local/lib/python3.12/asyncio/tasks.py\", line 520, in wait_for\n    return await fut\n           ^^^^^^^^^\naiodns.error.DNSError: (1, 'DNS server returned answer with no data')", "timestamp": "2024-05-28T09:23:11.016654+00:00", "logger": "__main__", "module": "main", "function": "dns_resolve", "line": 94, "task_name": "Task-95", "filename": "main.py", "exc_text": null, "msecs": 16.0, "relativeCreated": 32044.46792602539, "thread": 139919965337408, "threadName": "MainThread", "processName": "MainProcess", "process": 13249, "taskName": "Task-95"}
{"level": "ERROR", "message": "DNSError: (1, 'DNS server returned answer with no data')\nTraceback (most recent call last):\n  File \"/home/iman/Personal/TLS-Checker/TLS-Checker/TLS-Checker/main.py\", line 79, in dns_resolve\n    resp = await asyncio.wait_for(\n           ^^^^^^^^^^^^^^^^^^^^^^^\n  File \"/usr/local/lib/python3.12/asyncio/tasks.py\", line 520, in wait_for\n    return await fut\n           ^^^^^^^^^\naiodns.error.DNSError: (1, 'DNS server returned answer with no data')", "timestamp": "2024-05-28T09:23:11.017217+00:00", "logger": "__main__", "module": "main", "function": "dns_resolve", "line": 94, "task_name": "Task-93", "filename": "main.py", "exc_text": null, "msecs": 17.0, "relativeCreated": 32045.03083229065, "thread": 139919965337408, "threadName": "MainThread", "processName": "MainProcess", "process": 13249, "taskName": "Task-93"}
{"level": "ERROR", "message": "DNSError: (1, 'DNS server returned answer with no data')\nTraceback (most recent call last):\n  File \"/home/iman/Personal/TLS-Checker/TLS-Checker/TLS-Checker/main.py\", line 67, in dns_resolve\n    resp = await asyncio.wait_for(\n           ^^^^^^^^^^^^^^^^^^^^^^^\n  File \"/usr/local/lib/python3.12/asyncio/tasks.py\", line 520, in wait_for\n    return await fut\n           ^^^^^^^^^\naiodns.error.DNSError: (1, 'DNS server returned answer with no data')", "timestamp": "2024-05-28T09:23:11.023963+00:00", "logger": "__main__", "module": "main", "function": "dns_resolve", "line": 94, "task_name": "Task-98", "filename": "main.py", "exc_text": null, "msecs": 23.0, "relativeCreated": 32051.77640914917, "thread": 139919965337408, "threadName": "MainThread", "processName": "MainProcess", "process": 13249, "taskName": "Task-98"}
{"level": "ERROR", "message": "DNSError: (1, 'DNS server returned answer with no data')\nTraceback (most recent call last):\n  File \"/home/iman/Personal/TLS-Checker/TLS-Checker/TLS-Checker/main.py\", line 79, in dns_resolve\n    resp = await asyncio.wait_for(\n           ^^^^^^^^^^^^^^^^^^^^^^^\n  File \"/usr/local/lib/python3.12/asyncio/tasks.py\", line 520, in wait_for\n    return await fut\n           ^^^^^^^^^\naiodns.error.DNSError: (1, 'DNS server returned answer with no data')", "timestamp": "2024-05-28T09:23:11.031159+00:00", "logger": "__main__", "module": "main", "function": "dns_resolve", "line": 94, "task_name": "Task-16", "filename": "main.py", "exc_text": null, "msecs": 31.0, "relativeCreated": 32058.972120285034, "thread": 139919965337408, "threadName": "MainThread", "processName": "MainProcess", "process": 13249, "taskName": "Task-16"}
{"level": "ERROR", "message": "DNSError: (1, 'DNS server returned answer with no data')\nTraceback (most recent call last):\n  File \"/home/iman/Personal/TLS-Checker/TLS-Checker/TLS-Checker/main.py\", line 79, in dns_resolve\n    resp = await asyncio.wait_for(\n           ^^^^^^^^^^^^^^^^^^^^^^^\n  File \"/usr/local/lib/python3.12/asyncio/tasks.py\", line 520, in wait_for\n    return await fut\n           ^^^^^^^^^\naiodns.error.DNSError: (1, 'DNS server returned answer with no data')", "timestamp": "2024-05-28T09:23:11.037972+00:00", "logger": "__main__", "module": "main", "function": "dns_resolve", "line": 94, "task_name": "Task-12", "filename": "main.py", "exc_text": null, "msecs": 37.0, "relativeCreated": 32065.785884857178, "thread": 139919965337408, "threadName": "MainThread", "processName": "MainProcess", "process": 13249, "taskName": "Task-12"}
{"level": "ERROR", "message": "DNSError: (1, 'DNS server returned answer with no data')\nTraceback (most recent call last):\n  File \"/home/iman/Personal/TLS-Checker/TLS-Checker/TLS-Checker/main.py\", line 79, in dns_resolve\n    resp = await asyncio.wait_for(\n           ^^^^^^^^^^^^^^^^^^^^^^^\n  File \"/usr/local/lib/python3.12/asyncio/tasks.py\", line 520, in wait_for\n    return await fut\n           ^^^^^^^^^\naiodns.error.DNSError: (1, 'DNS server returned answer with no data')", "timestamp": "2024-05-28T09:23:11.045893+00:00", "logger": "__main__", "module": "main", "function": "dns_resolve", "line": 94, "task_name": "Task-13", "filename": "main.py", "exc_text": null, "msecs": 45.0, "relativeCreated": 32073.70686531067, "thread": 139919965337408, "threadName": "MainThread", "processName": "MainProcess", "process": 13249, "taskName": "Task-13"}
{"level": "ERROR", "message": "DNSError: (1, 'DNS server returned answer with no data')\nTraceback (most recent call last):\n  File \"/home/iman/Personal/TLS-Checker/TLS-Checker/TLS-Checker/main.py\", line 79, in dns_resolve\n    resp = await asyncio.wait_for(\n           ^^^^^^^^^^^^^^^^^^^^^^^\n  File \"/usr/local/lib/python3.12/asyncio/tasks.py\", line 520, in wait_for\n    return await fut\n           ^^^^^^^^^\naiodns.error.DNSError: (1, 'DNS server returned answer with no data')", "timestamp": "2024-05-28T09:23:11.046333+00:00", "logger": "__main__", "module": "main", "function": "dns_resolve", "line": 94, "task_name": "Task-18", "filename": "main.py", "exc_text": null, "msecs": 46.0, "relativeCreated": 32074.146032333374, "thread": 139919965337408, "threadName": "MainThread", "processName": "MainProcess", "process": 13249, "taskName": "Task-18"}
{"level": "ERROR", "message": "DNSError: (1, 'DNS server returned answer with no data')\nTraceback (most recent call last):\n  File \"/home/iman/Personal/TLS-Checker/TLS-Checker/TLS-Checker/main.py\", line 79, in dns_resolve\n    resp = await asyncio.wait_for(\n           ^^^^^^^^^^^^^^^^^^^^^^^\n  File \"/usr/local/lib/python3.12/asyncio/tasks.py\", line 520, in wait_for\n    return await fut\n           ^^^^^^^^^\naiodns.error.DNSError: (1, 'DNS server returned answer with no data')", "timestamp": "2024-05-28T09:23:11.046758+00:00", "logger": "__main__", "module": "main", "function": "dns_resolve", "line": 94, "task_name": "Task-47", "filename": "main.py", "exc_text": null, "msecs": 46.0, "relativeCreated": 32074.57184791565, "thread": 139919965337408, "threadName": "MainThread", "processName": "MainProcess", "process": 13249, "taskName": "Task-47"}
{"level": "ERROR", "message": "DNSError: (1, 'DNS server returned answer with no data')\nTraceback (most recent call last):\n  File \"/home/iman/Personal/TLS-Checker/TLS-Checker/TLS-Checker/main.py\", line 79, in dns_resolve\n    resp = await asyncio.wait_for(\n           ^^^^^^^^^^^^^^^^^^^^^^^\n  File \"/usr/local/lib/python3.12/asyncio/tasks.py\", line 520, in wait_for\n    return await fut\n           ^^^^^^^^^\naiodns.error.DNSError: (1, 'DNS server returned answer with no data')", "timestamp": "2024-05-28T09:23:11.047694+00:00", "logger": "__main__", "module": "main", "function": "dns_resolve", "line": 94, "task_name": "Task-9", "filename": "main.py", "exc_text": null, "msecs": 47.0, "relativeCreated": 32075.507879257202, "thread": 139919965337408, "threadName": "MainThread", "processName": "MainProcess", "process": 13249, "taskName": "Task-9"}
{"level": "ERROR", "message": "DNSError: (1, 'DNS server returned answer with no data')\nTraceback (most recent call last):\n  File \"/home/iman/Personal/TLS-Checker/TLS-Checker/TLS-Checker/main.py\", line 79, in dns_resolve\n    resp = await asyncio.wait_for(\n           ^^^^^^^^^^^^^^^^^^^^^^^\n  File \"/usr/local/lib/python3.12/asyncio/tasks.py\", line 520, in wait_for\n    return await fut\n           ^^^^^^^^^\naiodns.error.DNSError: (1, 'DNS server returned answer with no data')", "timestamp": "2024-05-28T09:23:11.057898+00:00", "logger": "__main__", "module": "main", "function": "dns_resolve", "line": 94, "task_name": "Task-29", "filename": "main.py", "exc_text": null, "msecs": 57.0, "relativeCreated": 32085.711240768433, "thread": 139919965337408, "threadName": "MainThread", "processName": "MainProcess", "process": 13249, "taskName": "Task-29"}
{"level": "ERROR", "message": "DNSError: (1, 'DNS server returned answer with no data')\nTraceback (most recent call last):\n  File \"/home/iman/Personal/TLS-Checker/TLS-Checker/TLS-Checker/main.py\", line 79, in dns_resolve\n    resp = await asyncio.wait_for(\n           ^^^^^^^^^^^^^^^^^^^^^^^\n  File \"/usr/local/lib/python3.12/asyncio/tasks.py\", line 520, in wait_for\n    return await fut\n           ^^^^^^^^^\naiodns.error.DNSError: (1, 'DNS server returned answer with no data')", "timestamp": "2024-05-28T09:23:11.064496+00:00", "logger": "__main__", "module": "main", "function": "dns_resolve", "line": 94, "task_name": "Task-71", "filename": "main.py", "exc_text": null, "msecs": 64.0, "relativeCreated": 32092.309713363647, "thread": 139919965337408, "threadName": "MainThread", "processName": "MainProcess", "process": 13249, "taskName": "Task-71"}
{"level": "ERROR", "message": "DNSError: (1, 'DNS server returned answer with no data')\nTraceback (most recent call last):\n  File \"/home/iman/Personal/TLS-Checker/TLS-Checker/TLS-Checker/main.py\", line 79, in dns_resolve\n    resp = await asyncio.wait_for(\n           ^^^^^^^^^^^^^^^^^^^^^^^\n  File \"/usr/local/lib/python3.12/asyncio/tasks.py\", line 520, in wait_for\n    return await fut\n           ^^^^^^^^^\naiodns.error.DNSError: (1, 'DNS server returned answer with no data')", "timestamp": "2024-05-28T09:23:11.065505+00:00", "logger": "__main__", "module": "main", "function": "dns_resolve", "line": 94, "task_name": "Task-39", "filename": "main.py", "exc_text": null, "msecs": 65.0, "relativeCreated": 32093.318462371826, "thread": 139919965337408, "threadName": "MainThread", "processName": "MainProcess", "process": 13249, "taskName": "Task-39"}
{"level": "ERROR", "message": "DNSError: (1, 'DNS server returned answer with no data')\nTraceback (most recent call last):\n  File \"/home/iman/Personal/TLS-Checker/TLS-Checker/TLS-Checker/main.py\", line 79, in dns_resolve\n    resp = await asyncio.wait_for(\n           ^^^^^^^^^^^^^^^^^^^^^^^\n  File \"/usr/local/lib/python3.12/asyncio/tasks.py\", line 520, in wait_for\n    return await fut\n           ^^^^^^^^^\naiodns.error.DNSError: (1, 'DNS server returned answer with no data')", "timestamp": "2024-05-28T09:23:11.066471+00:00", "logger": "__main__", "module": "main", "function": "dns_resolve", "line": 94, "task_name": "Task-99", "filename": "main.py", "exc_text": null, "msecs": 66.0, "relativeCreated": 32094.284772872925, "thread": 139919965337408, "threadName": "MainThread", "processName": "MainProcess", "process": 13249, "taskName": "Task-99"}
{"level": "ERROR", "message": "DNSError: (1, 'DNS server returned answer with no data')\nTraceback (most recent call last):\n  File \"/home/iman/Personal/TLS-Checker/TLS-Checker/TLS-Checker/main.py\", line 67, in dns_resolve\n    resp = await asyncio.wait_for(\n           ^^^^^^^^^^^^^^^^^^^^^^^\n  File \"/usr/local/lib/python3.12/asyncio/tasks.py\", line 520, in wait_for\n    return await fut\n           ^^^^^^^^^\naiodns.error.DNSError: (1, 'DNS server returned answer with no data')", "timestamp": "2024-05-28T09:23:11.067714+00:00", "logger": "__main__", "module": "main", "function": "dns_resolve", "line": 94, "task_name": "Task-41", "filename": "main.py", "exc_text": null, "msecs": 67.0, "relativeCreated": 32095.52764892578, "thread": 139919965337408, "threadName": "MainThread", "processName": "MainProcess", "process": 13249, "taskName": "Task-41"}
{"level": "ERROR", "message": "DNSError: (1, 'DNS server returned answer with no data')\nTraceback (most recent call last):\n  File \"/home/iman/Personal/TLS-Checker/TLS-Checker/TLS-Checker/main.py\", line 79, in dns_resolve\n    resp = await asyncio.wait_for(\n           ^^^^^^^^^^^^^^^^^^^^^^^\n  File \"/usr/local/lib/python3.12/asyncio/tasks.py\", line 520, in wait_for\n    return await fut\n           ^^^^^^^^^\naiodns.error.DNSError: (1, 'DNS server returned answer with no data')", "timestamp": "2024-05-28T09:23:11.068501+00:00", "logger": "__main__", "module": "main", "function": "dns_resolve", "line": 94, "task_name": "Task-63", "filename": "main.py", "exc_text": null, "msecs": 68.0, "relativeCreated": 32096.314907073975, "thread": 139919965337408, "threadName": "MainThread", "processName": "MainProcess", "process": 13249, "taskName": "Task-63"}
{"level": "ERROR", "message": "DNSError: (1, 'DNS server returned answer with no data')\nTraceback (most recent call last):\n  File \"/home/iman/Personal/TLS-Checker/TLS-Checker/TLS-Checker/main.py\", line 79, in dns_resolve\n    resp = await asyncio.wait_for(\n           ^^^^^^^^^^^^^^^^^^^^^^^\n  File \"/usr/local/lib/python3.12/asyncio/tasks.py\", line 520, in wait_for\n    return await fut\n           ^^^^^^^^^\naiodns.error.DNSError: (1, 'DNS server returned answer with no data')", "timestamp": "2024-05-28T09:23:11.069010+00:00", "logger": "__main__", "module": "main", "function": "dns_resolve", "line": 94, "task_name": "Task-43", "filename": "main.py", "exc_text": null, "msecs": 69.0, "relativeCreated": 32096.82321548462, "thread": 139919965337408, "threadName": "MainThread", "processName": "MainProcess", "process": 13249, "taskName": "Task-43"}
{"level": "ERROR", "message": "DNSError: (1, 'DNS server returned answer with no data')\nTraceback (most recent call last):\n  File \"/home/iman/Personal/TLS-Checker/TLS-Checker/TLS-Checker/main.py\", line 79, in dns_resolve\n    resp = await asyncio.wait_for(\n           ^^^^^^^^^^^^^^^^^^^^^^^\n  File \"/usr/local/lib/python3.12/asyncio/tasks.py\", line 520, in wait_for\n    return await fut\n           ^^^^^^^^^\naiodns.error.DNSError: (1, 'DNS server returned answer with no data')", "timestamp": "2024-05-28T09:23:11.071161+00:00", "logger": "__main__", "module": "main", "function": "dns_resolve", "line": 94, "task_name": "Task-69", "filename": "main.py", "exc_text": null, "msecs": 71.0, "relativeCreated": 32098.974227905273, "thread": 139919965337408, "threadName": "MainThread", "processName": "MainProcess", "process": 13249, "taskName": "Task-69"}
{"level": "ERROR", "message": "DNSError: (1, 'DNS server returned answer with no data')\nTraceback (most recent call last):\n  File \"/home/iman/Personal/TLS-Checker/TLS-Checker/TLS-Checker/main.py\", line 79, in dns_resolve\n    resp = await asyncio.wait_for(\n           ^^^^^^^^^^^^^^^^^^^^^^^\n  File \"/usr/local/lib/python3.12/asyncio/tasks.py\", line 520, in wait_for\n    return await fut\n           ^^^^^^^^^\naiodns.error.DNSError: (1, 'DNS server returned answer with no data')", "timestamp": "2024-05-28T09:23:11.071815+00:00", "logger": "__main__", "module": "main", "function": "dns_resolve", "line": 94, "task_name": "Task-49", "filename": "main.py", "exc_text": null, "msecs": 71.0, "relativeCreated": 32099.628925323486, "thread": 139919965337408, "threadName": "MainThread", "processName": "MainProcess", "process": 13249, "taskName": "Task-49"}
{"level": "ERROR", "message": "DNSError: (1, 'DNS server returned answer with no data')\nTraceback (most recent call last):\n  File \"/home/iman/Personal/TLS-Checker/TLS-Checker/TLS-Checker/main.py\", line 79, in dns_resolve\n    resp = await asyncio.wait_for(\n           ^^^^^^^^^^^^^^^^^^^^^^^\n  File \"/usr/local/lib/python3.12/asyncio/tasks.py\", line 520, in wait_for\n    return await fut\n           ^^^^^^^^^\naiodns.error.DNSError: (1, 'DNS server returned answer with no data')", "timestamp": "2024-05-28T09:23:11.075638+00:00", "logger": "__main__", "module": "main", "function": "dns_resolve", "line": 94, "task_name": "Task-91", "filename": "main.py", "exc_text": null, "msecs": 75.0, "relativeCreated": 32103.451013565063, "thread": 139919965337408, "threadName": "MainThread", "processName": "MainProcess", "process": 13249, "taskName": "Task-91"}
{"level": "ERROR", "message": "DNSError: (1, 'DNS server returned answer with no data')\nTraceback (most recent call last):\n  File \"/home/iman/Personal/TLS-Checker/TLS-Checker/TLS-Checker/main.py\", line 79, in dns_resolve\n    resp = await asyncio.wait_for(\n           ^^^^^^^^^^^^^^^^^^^^^^^\n  File \"/usr/local/lib/python3.12/asyncio/tasks.py\", line 520, in wait_for\n    return await fut\n           ^^^^^^^^^\naiodns.error.DNSError: (1, 'DNS server returned answer with no data')", "timestamp": "2024-05-28T09:23:11.103518+00:00", "logger": "__main__", "module": "main", "function": "dns_resolve", "line": 94, "task_name": "Task-90", "filename": "main.py", "exc_text": null, "msecs": 103.0, "relativeCreated": 32131.33192062378, "thread": 139919965337408, "threadName": "MainThread", "processName": "MainProcess", "process": 13249, "taskName": "Task-90"}
{"level": "ERROR", "message": "DNSError: (1, 'DNS server returned answer with no data')\nTraceback (most recent call last):\n  File \"/home/iman/Personal/TLS-Checker/TLS-Checker/TLS-Checker/main.py\", line 67, in dns_resolve\n    resp = await asyncio.wait_for(\n           ^^^^^^^^^^^^^^^^^^^^^^^\n  File \"/usr/local/lib/python3.12/asyncio/tasks.py\", line 520, in wait_for\n    return await fut\n           ^^^^^^^^^\naiodns.error.DNSError: (1, 'DNS server returned answer with no data')", "timestamp": "2024-05-28T09:23:11.116017+00:00", "logger": "__main__", "module": "main", "function": "dns_resolve", "line": 94, "task_name": "Task-79", "filename": "main.py", "exc_text": null, "msecs": 116.0, "relativeCreated": 32143.830060958862, "thread": 139919965337408, "threadName": "MainThread", "processName": "MainProcess", "process": 13249, "taskName": "Task-79"}
{"level": "ERROR", "message": "DNSError: (1, 'DNS server returned answer with no data')\nTraceback (most recent call last):\n  File \"/home/iman/Personal/TLS-Checker/TLS-Checker/TLS-Checker/main.py\", line 79, in dns_resolve\n    resp = await asyncio.wait_for(\n           ^^^^^^^^^^^^^^^^^^^^^^^\n  File \"/usr/local/lib/python3.12/asyncio/tasks.py\", line 520, in wait_for\n    return await fut\n           ^^^^^^^^^\naiodns.error.DNSError: (1, 'DNS server returned answer with no data')", "timestamp": "2024-05-28T09:23:11.131998+00:00", "logger": "__main__", "module": "main", "function": "dns_resolve", "line": 94, "task_name": "Task-21", "filename": "main.py", "exc_text": null, "msecs": 131.0, "relativeCreated": 32159.81149673462, "thread": 139919965337408, "threadName": "MainThread", "processName": "MainProcess", "process": 13249, "taskName": "Task-21"}
{"level": "ERROR", "message": "DNSError: (1, 'DNS server returned answer with no data')\nTraceback (most recent call last):\n  File \"/home/iman/Personal/TLS-Checker/TLS-Checker/TLS-Checker/main.py\", line 79, in dns_resolve\n    resp = await asyncio.wait_for(\n           ^^^^^^^^^^^^^^^^^^^^^^^\n  File \"/usr/local/lib/python3.12/asyncio/tasks.py\", line 520, in wait_for\n    return await fut\n           ^^^^^^^^^\naiodns.error.DNSError: (1, 'DNS server returned answer with no data')", "timestamp": "2024-05-28T09:23:11.179340+00:00", "logger": "__main__", "module": "main", "function": "dns_resolve", "line": 94, "task_name": "Task-57", "filename": "main.py", "exc_text": null, "msecs": 179.0, "relativeCreated": 32207.15379714966, "thread": 139919965337408, "threadName": "MainThread", "processName": "MainProcess", "process": 13249, "taskName": "Task-57"}
{"level": "ERROR", "message": "DNSError: (1, 'DNS server returned answer with no data')\nTraceback (most recent call last):\n  File \"/home/iman/Personal/TLS-Checker/TLS-Checker/TLS-Checker/main.py\", line 79, in dns_resolve\n    resp = await asyncio.wait_for(\n           ^^^^^^^^^^^^^^^^^^^^^^^\n  File \"/usr/local/lib/python3.12/asyncio/tasks.py\", line 520, in wait_for\n    return await fut\n           ^^^^^^^^^\naiodns.error.DNSError: (1, 'DNS server returned answer with no data')", "timestamp": "2024-05-28T09:23:11.180438+00:00", "logger": "__main__", "module": "main", "function": "dns_resolve", "line": 94, "task_name": "Task-68", "filename": "main.py", "exc_text": null, "msecs": 180.0, "relativeCreated": 32208.251237869263, "thread": 139919965337408, "threadName": "MainThread", "processName": "MainProcess", "process": 13249, "taskName": "Task-68"}
{"level": "ERROR", "message": "DNSError: (1, 'DNS server returned answer with no data')\nTraceback (most recent call last):\n  File \"/home/iman/Personal/TLS-Checker/TLS-Checker/TLS-Checker/main.py\", line 79, in dns_resolve\n    resp = await asyncio.wait_for(\n           ^^^^^^^^^^^^^^^^^^^^^^^\n  File \"/usr/local/lib/python3.12/asyncio/tasks.py\", line 520, in wait_for\n    return await fut\n           ^^^^^^^^^\naiodns.error.DNSError: (1, 'DNS server returned answer with no data')", "timestamp": "2024-05-28T09:23:11.218561+00:00", "logger": "__main__", "module": "main", "function": "dns_resolve", "line": 94, "task_name": "Task-67", "filename": "main.py", "exc_text": null, "msecs": 218.0, "relativeCreated": 32246.374130249023, "thread": 139919965337408, "threadName": "MainThread", "processName": "MainProcess", "process": 13249, "taskName": "Task-67"}
{"level": "ERROR", "message": "DNSError: (1, 'DNS server returned answer with no data')\nTraceback (most recent call last):\n  File \"/home/iman/Personal/TLS-Checker/TLS-Checker/TLS-Checker/main.py\", line 79, in dns_resolve\n    resp = await asyncio.wait_for(\n           ^^^^^^^^^^^^^^^^^^^^^^^\n  File \"/usr/local/lib/python3.12/asyncio/tasks.py\", line 520, in wait_for\n    return await fut\n           ^^^^^^^^^\naiodns.error.DNSError: (1, 'DNS server returned answer with no data')", "timestamp": "2024-05-28T09:23:11.223999+00:00", "logger": "__main__", "module": "main", "function": "dns_resolve", "line": 94, "task_name": "Task-11", "filename": "main.py", "exc_text": null, "msecs": 223.0, "relativeCreated": 32251.81269645691, "thread": 139919965337408, "threadName": "MainThread", "processName": "MainProcess", "process": 13249, "taskName": "Task-11"}
{"level": "ERROR", "message": "DNSError: (1, 'DNS server returned answer with no data')\nTraceback (most recent call last):\n  File \"/home/iman/Personal/TLS-Checker/TLS-Checker/TLS-Checker/main.py\", line 67, in dns_resolve\n    resp = await asyncio.wait_for(\n           ^^^^^^^^^^^^^^^^^^^^^^^\n  File \"/usr/local/lib/python3.12/asyncio/tasks.py\", line 520, in wait_for\n    return await fut\n           ^^^^^^^^^\naiodns.error.DNSError: (1, 'DNS server returned answer with no data')", "timestamp": "2024-05-28T09:23:11.224838+00:00", "logger": "__main__", "module": "main", "function": "dns_resolve", "line": 94, "task_name": "Task-46", "filename": "main.py", "exc_text": null, "msecs": 224.0, "relativeCreated": 32252.65097618103, "thread": 139919965337408, "threadName": "MainThread", "processName": "MainProcess", "process": 13249, "taskName": "Task-46"}
{"level": "ERROR", "message": "DNSError: (1, 'DNS server returned answer with no data')\nTraceback (most recent call last):\n  File \"/home/iman/Personal/TLS-Checker/TLS-Checker/TLS-Checker/main.py\", line 79, in dns_resolve\n    resp = await asyncio.wait_for(\n           ^^^^^^^^^^^^^^^^^^^^^^^\n  File \"/usr/local/lib/python3.12/asyncio/tasks.py\", line 520, in wait_for\n    return await fut\n           ^^^^^^^^^\naiodns.error.DNSError: (1, 'DNS server returned answer with no data')", "timestamp": "2024-05-28T09:23:11.238829+00:00", "logger": "__main__", "module": "main", "function": "dns_resolve", "line": 94, "task_name": "Task-34", "filename": "main.py", "exc_text": null, "msecs": 238.0, "relativeCreated": 32266.642332077026, "thread": 139919965337408, "threadName": "MainThread", "processName": "MainProcess", "process": 13249, "taskName": "Task-34"}
{"level": "ERROR", "message": "DNSError: (1, 'DNS server returned answer with no data')\nTraceback (most recent call last):\n  File \"/home/iman/Personal/TLS-Checker/TLS-Checker/TLS-Checker/main.py\", line 79, in dns_resolve\n    resp = await asyncio.wait_for(\n           ^^^^^^^^^^^^^^^^^^^^^^^\n  File \"/usr/local/lib/python3.12/asyncio/tasks.py\", line 520, in wait_for\n    return await fut\n           ^^^^^^^^^\naiodns.error.DNSError: (1, 'DNS server returned answer with no data')", "timestamp": "2024-05-28T09:23:11.252497+00:00", "logger": "__main__", "module": "main", "function": "dns_resolve", "line": 94, "task_name": "Task-17", "filename": "main.py", "exc_text": null, "msecs": 252.0, "relativeCreated": 32280.31086921692, "thread": 139919965337408, "threadName": "MainThread", "processName": "MainProcess", "process": 13249, "taskName": "Task-17"}
{"level": "ERROR", "message": "DNSError: (1, 'DNS server returned answer with no data')\nTraceback (most recent call last):\n  File \"/home/iman/Personal/TLS-Checker/TLS-Checker/TLS-Checker/main.py\", line 67, in dns_resolve\n    resp = await asyncio.wait_for(\n           ^^^^^^^^^^^^^^^^^^^^^^^\n  File \"/usr/local/lib/python3.12/asyncio/tasks.py\", line 520, in wait_for\n    return await fut\n           ^^^^^^^^^\naiodns.error.DNSError: (1, 'DNS server returned answer with no data')", "timestamp": "2024-05-28T09:23:11.253013+00:00", "logger": "__main__", "module": "main", "function": "dns_resolve", "line": 94, "task_name": "Task-51", "filename": "main.py", "exc_text": null, "msecs": 253.0, "relativeCreated": 32280.826091766357, "thread": 139919965337408, "threadName": "MainThread", "processName": "MainProcess", "process": 13249, "taskName": "Task-51"}
{"level": "ERROR", "message": "DNSError: (1, 'DNS server returned answer with no data')\nTraceback (most recent call last):\n  File \"/home/iman/Personal/TLS-Checker/TLS-Checker/TLS-Checker/main.py\", line 79, in dns_resolve\n    resp = await asyncio.wait_for(\n           ^^^^^^^^^^^^^^^^^^^^^^^\n  File \"/usr/local/lib/python3.12/asyncio/tasks.py\", line 520, in wait_for\n    return await fut\n           ^^^^^^^^^\naiodns.error.DNSError: (1, 'DNS server returned answer with no data')", "timestamp": "2024-05-28T09:23:11.285373+00:00", "logger": "__main__", "module": "main", "function": "dns_resolve", "line": 94, "task_name": "Task-58", "filename": "main.py", "exc_text": null, "msecs": 285.0, "relativeCreated": 32313.186645507812, "thread": 139919965337408, "threadName": "MainThread", "processName": "MainProcess", "process": 13249, "taskName": "Task-58"}
{"level": "ERROR", "message": "DNSError: (1, 'DNS server returned answer with no data')\nTraceback (most recent call last):\n  File \"/home/iman/Personal/TLS-Checker/TLS-Checker/TLS-Checker/main.py\", line 79, in dns_resolve\n    resp = await asyncio.wait_for(\n           ^^^^^^^^^^^^^^^^^^^^^^^\n  File \"/usr/local/lib/python3.12/asyncio/tasks.py\", line 520, in wait_for\n    return await fut\n           ^^^^^^^^^\naiodns.error.DNSError: (1, 'DNS server returned answer with no data')", "timestamp": "2024-05-28T09:23:11.286038+00:00", "logger": "__main__", "module": "main", "function": "dns_resolve", "line": 94, "task_name": "Task-50", "filename": "main.py", "exc_text": null, "msecs": 286.0, "relativeCreated": 32313.85111808777, "thread": 139919965337408, "threadName": "MainThread", "processName": "MainProcess", "process": 13249, "taskName": "Task-50"}
{"level": "ERROR", "message": "DNSError: (1, 'DNS server returned answer with no data')\nTraceback (most recent call last):\n  File \"/home/iman/Personal/TLS-Checker/TLS-Checker/TLS-Checker/main.py\", line 79, in dns_resolve\n    resp = await asyncio.wait_for(\n           ^^^^^^^^^^^^^^^^^^^^^^^\n  File \"/usr/local/lib/python3.12/asyncio/tasks.py\", line 520, in wait_for\n    return await fut\n           ^^^^^^^^^\naiodns.error.DNSError: (1, 'DNS server returned answer with no data')", "timestamp": "2024-05-28T09:23:11.839292+00:00", "logger": "__main__", "module": "main", "function": "dns_resolve", "line": 94, "task_name": "Task-38", "filename": "main.py", "exc_text": null, "msecs": 839.0, "relativeCreated": 32867.10548400879, "thread": 139919965337408, "threadName": "MainThread", "processName": "MainProcess", "process": 13249, "taskName": "Task-38"}
{"level": "ERROR", "message": "Timeout Error: \nTraceback (most recent call last):\n  File \"/usr/local/lib/python3.12/asyncio/tasks.py\", line 520, in wait_for\n    return await fut\n           ^^^^^^^^^\nasyncio.exceptions.CancelledError\n\nThe above exception was the direct cause of the following exception:\n\nTraceback (most recent call last):\n  File \"/home/iman/Personal/TLS-Checker/TLS-Checker/TLS-Checker/main.py\", line 67, in dns_resolve\n    resp = await asyncio.wait_for(\n           ^^^^^^^^^^^^^^^^^^^^^^^\n  File \"/usr/local/lib/python3.12/asyncio/tasks.py\", line 519, in wait_for\n    async with timeouts.timeout(timeout):\n  File \"/usr/local/lib/python3.12/asyncio/timeouts.py\", line 115, in __aexit__\n    raise TimeoutError from exc_val\nTimeoutError", "timestamp": "2024-05-28T09:23:13.890099+00:00", "logger": "__main__", "module": "main", "function": "dns_resolve", "line": 96, "task_name": "Task-59", "filename": "main.py", "exc_text": null, "msecs": 890.0, "relativeCreated": 34917.91272163391, "thread": 139919965337408, "threadName": "MainThread", "processName": "MainProcess", "process": 13249, "taskName": "Task-59"}
{"level": "ERROR", "message": "Timeout Error: \nTraceback (most recent call last):\n  File \"/usr/local/lib/python3.12/asyncio/tasks.py\", line 520, in wait_for\n    return await fut\n           ^^^^^^^^^\nasyncio.exceptions.CancelledError\n\nThe above exception was the direct cause of the following exception:\n\nTraceback (most recent call last):\n  File \"/home/iman/Personal/TLS-Checker/TLS-Checker/TLS-Checker/main.py\", line 67, in dns_resolve\n    resp = await asyncio.wait_for(\n           ^^^^^^^^^^^^^^^^^^^^^^^\n  File \"/usr/local/lib/python3.12/asyncio/tasks.py\", line 519, in wait_for\n    async with timeouts.timeout(timeout):\n  File \"/usr/local/lib/python3.12/asyncio/timeouts.py\", line 115, in __aexit__\n    raise TimeoutError from exc_val\nTimeoutError", "timestamp": "2024-05-28T09:23:13.890884+00:00", "logger": "__main__", "module": "main", "function": "dns_resolve", "line": 96, "task_name": "Task-61", "filename": "main.py", "exc_text": null, "msecs": 890.0, "relativeCreated": 34918.697357177734, "thread": 139919965337408, "threadName": "MainThread", "processName": "MainProcess", "process": 13249, "taskName": "Task-61"}
{"level": "ERROR", "message": "Timeout Error: \nTraceback (most recent call last):\n  File \"/usr/local/lib/python3.12/asyncio/tasks.py\", line 520, in wait_for\n    return await fut\n           ^^^^^^^^^\nasyncio.exceptions.CancelledError\n\nThe above exception was the direct cause of the following exception:\n\nTraceback (most recent call last):\n  File \"/home/iman/Personal/TLS-Checker/TLS-Checker/TLS-Checker/main.py\", line 67, in dns_resolve\n    resp = await asyncio.wait_for(\n           ^^^^^^^^^^^^^^^^^^^^^^^\n  File \"/usr/local/lib/python3.12/asyncio/tasks.py\", line 519, in wait_for\n    async with timeouts.timeout(timeout):\n  File \"/usr/local/lib/python3.12/asyncio/timeouts.py\", line 115, in __aexit__\n    raise TimeoutError from exc_val\nTimeoutError", "timestamp": "2024-05-28T09:23:13.891263+00:00", "logger": "__main__", "module": "main", "function": "dns_resolve", "line": 96, "task_name": "Task-65", "filename": "main.py", "exc_text": null, "msecs": 891.0, "relativeCreated": 34919.076681137085, "thread": 139919965337408, "threadName": "MainThread", "processName": "MainProcess", "process": 13249, "taskName": "Task-65"}
{"level": "ERROR", "message": "Timeout Error: \nTraceback (most recent call last):\n  File \"/usr/local/lib/python3.12/asyncio/tasks.py\", line 520, in wait_for\n    return await fut\n           ^^^^^^^^^\nasyncio.exceptions.CancelledError\n\nThe above exception was the direct cause of the following exception:\n\nTraceback (most recent call last):\n  File \"/home/iman/Personal/TLS-Checker/TLS-Checker/TLS-Checker/main.py\", line 67, in dns_resolve\n    resp = await asyncio.wait_for(\n           ^^^^^^^^^^^^^^^^^^^^^^^\n  File \"/usr/local/lib/python3.12/asyncio/tasks.py\", line 519, in wait_for\n    async with timeouts.timeout(timeout):\n  File \"/usr/local/lib/python3.12/asyncio/timeouts.py\", line 115, in __aexit__\n    raise TimeoutError from exc_val\nTimeoutError", "timestamp": "2024-05-28T09:23:13.891629+00:00", "logger": "__main__", "module": "main", "function": "dns_resolve", "line": 96, "task_name": "Task-70", "filename": "main.py", "exc_text": null, "msecs": 891.0, "relativeCreated": 34919.44193840027, "thread": 139919965337408, "threadName": "MainThread", "processName": "MainProcess", "process": 13249, "taskName": "Task-70"}
{"level": "ERROR", "message": "Timeout Error: \nTraceback (most recent call last):\n  File \"/usr/local/lib/python3.12/asyncio/tasks.py\", line 520, in wait_for\n    return await fut\n           ^^^^^^^^^\nasyncio.exceptions.CancelledError\n\nThe above exception was the direct cause of the following exception:\n\nTraceback (most recent call last):\n  File \"/home/iman/Personal/TLS-Checker/TLS-Checker/TLS-Checker/main.py\", line 67, in dns_resolve\n    resp = await asyncio.wait_for(\n           ^^^^^^^^^^^^^^^^^^^^^^^\n  File \"/usr/local/lib/python3.12/asyncio/tasks.py\", line 519, in wait_for\n    async with timeouts.timeout(timeout):\n  File \"/usr/local/lib/python3.12/asyncio/timeouts.py\", line 115, in __aexit__\n    raise TimeoutError from exc_val\nTimeoutError", "timestamp": "2024-05-28T09:23:13.891997+00:00", "logger": "__main__", "module": "main", "function": "dns_resolve", "line": 96, "task_name": "Task-72", "filename": "main.py", "exc_text": null, "msecs": 891.0, "relativeCreated": 34919.8100566864, "thread": 139919965337408, "threadName": "MainThread", "processName": "MainProcess", "process": 13249, "taskName": "Task-72"}
{"level": "ERROR", "message": "Timeout Error: \nTraceback (most recent call last):\n  File \"/usr/local/lib/python3.12/asyncio/tasks.py\", line 520, in wait_for\n    return await fut\n           ^^^^^^^^^\nasyncio.exceptions.CancelledError\n\nThe above exception was the direct cause of the following exception:\n\nTraceback (most recent call last):\n  File \"/home/iman/Personal/TLS-Checker/TLS-Checker/TLS-Checker/main.py\", line 67, in dns_resolve\n    resp = await asyncio.wait_for(\n           ^^^^^^^^^^^^^^^^^^^^^^^\n  File \"/usr/local/lib/python3.12/asyncio/tasks.py\", line 519, in wait_for\n    async with timeouts.timeout(timeout):\n  File \"/usr/local/lib/python3.12/asyncio/timeouts.py\", line 115, in __aexit__\n    raise TimeoutError from exc_val\nTimeoutError", "timestamp": "2024-05-28T09:23:13.892608+00:00", "logger": "__main__", "module": "main", "function": "dns_resolve", "line": 96, "task_name": "Task-75", "filename": "main.py", "exc_text": null, "msecs": 892.0, "relativeCreated": 34920.42112350464, "thread": 139919965337408, "threadName": "MainThread", "processName": "MainProcess", "process": 13249, "taskName": "Task-75"}
{"level": "ERROR", "message": "Timeout Error: \nTraceback (most recent call last):\n  File \"/usr/local/lib/python3.12/asyncio/tasks.py\", line 520, in wait_for\n    return await fut\n           ^^^^^^^^^\nasyncio.exceptions.CancelledError\n\nThe above exception was the direct cause of the following exception:\n\nTraceback (most recent call last):\n  File \"/home/iman/Personal/TLS-Checker/TLS-Checker/TLS-Checker/main.py\", line 67, in dns_resolve\n    resp = await asyncio.wait_for(\n           ^^^^^^^^^^^^^^^^^^^^^^^\n  File \"/usr/local/lib/python3.12/asyncio/tasks.py\", line 519, in wait_for\n    async with timeouts.timeout(timeout):\n  File \"/usr/local/lib/python3.12/asyncio/timeouts.py\", line 115, in __aexit__\n    raise TimeoutError from exc_val\nTimeoutError", "timestamp": "2024-05-28T09:23:13.892975+00:00", "logger": "__main__", "module": "main", "function": "dns_resolve", "line": 96, "task_name": "Task-78", "filename": "main.py", "exc_text": null, "msecs": 892.0, "relativeCreated": 34920.788049697876, "thread": 139919965337408, "threadName": "MainThread", "processName": "MainProcess", "process": 13249, "taskName": "Task-78"}
{"level": "ERROR", "message": "Timeout Error: \nTraceback (most recent call last):\n  File \"/usr/local/lib/python3.12/asyncio/tasks.py\", line 520, in wait_for\n    return await fut\n           ^^^^^^^^^\nasyncio.exceptions.CancelledError\n\nThe above exception was the direct cause of the following exception:\n\nTraceback (most recent call last):\n  File \"/home/iman/Personal/TLS-Checker/TLS-Checker/TLS-Checker/main.py\", line 67, in dns_resolve\n    resp = await asyncio.wait_for(\n           ^^^^^^^^^^^^^^^^^^^^^^^\n  File \"/usr/local/lib/python3.12/asyncio/tasks.py\", line 519, in wait_for\n    async with timeouts.timeout(timeout):\n  File \"/usr/local/lib/python3.12/asyncio/timeouts.py\", line 115, in __aexit__\n    raise TimeoutError from exc_val\nTimeoutError", "timestamp": "2024-05-28T09:23:13.893419+00:00", "logger": "__main__", "module": "main", "function": "dns_resolve", "line": 96, "task_name": "Task-83", "filename": "main.py", "exc_text": null, "msecs": 893.0, "relativeCreated": 34921.23198509216, "thread": 139919965337408, "threadName": "MainThread", "processName": "MainProcess", "process": 13249, "taskName": "Task-83"}
{"level": "ERROR", "message": "Timeout Error: \nTraceback (most recent call last):\n  File \"/usr/local/lib/python3.12/asyncio/tasks.py\", line 520, in wait_for\n    return await fut\n           ^^^^^^^^^\nasyncio.exceptions.CancelledError\n\nThe above exception was the direct cause of the following exception:\n\nTraceback (most recent call last):\n  File \"/home/iman/Personal/TLS-Checker/TLS-Checker/TLS-Checker/main.py\", line 67, in dns_resolve\n    resp = await asyncio.wait_for(\n           ^^^^^^^^^^^^^^^^^^^^^^^\n  File \"/usr/local/lib/python3.12/asyncio/tasks.py\", line 519, in wait_for\n    async with timeouts.timeout(timeout):\n  File \"/usr/local/lib/python3.12/asyncio/timeouts.py\", line 115, in __aexit__\n    raise TimeoutError from exc_val\nTimeoutError", "timestamp": "2024-05-28T09:23:13.893807+00:00", "logger": "__main__", "module": "main", "function": "dns_resolve", "line": 96, "task_name": "Task-86", "filename": "main.py", "exc_text": null, "msecs": 893.0, "relativeCreated": 34921.62013053894, "thread": 139919965337408, "threadName": "MainThread", "processName": "MainProcess", "process": 13249, "taskName": "Task-86"}
{"level": "ERROR", "message": "Timeout Error: \nTraceback (most recent call last):\n  File \"/usr/local/lib/python3.12/asyncio/tasks.py\", line 520, in wait_for\n    return await fut\n           ^^^^^^^^^\nasyncio.exceptions.CancelledError\n\nThe above exception was the direct cause of the following exception:\n\nTraceback (most recent call last):\n  File \"/home/iman/Personal/TLS-Checker/TLS-Checker/TLS-Checker/main.py\", line 67, in dns_resolve\n    resp = await asyncio.wait_for(\n           ^^^^^^^^^^^^^^^^^^^^^^^\n  File \"/usr/local/lib/python3.12/asyncio/tasks.py\", line 519, in wait_for\n    async with timeouts.timeout(timeout):\n  File \"/usr/local/lib/python3.12/asyncio/timeouts.py\", line 115, in __aexit__\n    raise TimeoutError from exc_val\nTimeoutError", "timestamp": "2024-05-28T09:23:13.894148+00:00", "logger": "__main__", "module": "main", "function": "dns_resolve", "line": 96, "task_name": "Task-89", "filename": "main.py", "exc_text": null, "msecs": 894.0, "relativeCreated": 34921.961069107056, "thread": 139919965337408, "threadName": "MainThread", "processName": "MainProcess", "process": 13249, "taskName": "Task-89"}
{"level": "ERROR", "message": "Timeout Error: \nTraceback (most recent call last):\n  File \"/usr/local/lib/python3.12/asyncio/tasks.py\", line 520, in wait_for\n    return await fut\n           ^^^^^^^^^\nasyncio.exceptions.CancelledError\n\nThe above exception was the direct cause of the following exception:\n\nTraceback (most recent call last):\n  File \"/home/iman/Personal/TLS-Checker/TLS-Checker/TLS-Checker/main.py\", line 67, in dns_resolve\n    resp = await asyncio.wait_for(\n           ^^^^^^^^^^^^^^^^^^^^^^^\n  File \"/usr/local/lib/python3.12/asyncio/tasks.py\", line 519, in wait_for\n    async with timeouts.timeout(timeout):\n  File \"/usr/local/lib/python3.12/asyncio/timeouts.py\", line 115, in __aexit__\n    raise TimeoutError from exc_val\nTimeoutError", "timestamp": "2024-05-28T09:23:13.894491+00:00", "logger": "__main__", "module": "main", "function": "dns_resolve", "line": 96, "task_name": "Task-96", "filename": "main.py", "exc_text": null, "msecs": 894.0, "relativeCreated": 34922.30486869812, "thread": 139919965337408, "threadName": "MainThread", "processName": "MainProcess", "process": 13249, "taskName": "Task-96"}
{"level": "ERROR", "message": "Timeout Error: \nTraceback (most recent call last):\n  File \"/usr/local/lib/python3.12/asyncio/tasks.py\", line 520, in wait_for\n    return await fut\n           ^^^^^^^^^\nasyncio.exceptions.CancelledError\n\nThe above exception was the direct cause of the following exception:\n\nTraceback (most recent call last):\n  File \"/home/iman/Personal/TLS-Checker/TLS-Checker/TLS-Checker/main.py\", line 67, in dns_resolve\n    resp = await asyncio.wait_for(\n           ^^^^^^^^^^^^^^^^^^^^^^^\n  File \"/usr/local/lib/python3.12/asyncio/tasks.py\", line 519, in wait_for\n    async with timeouts.timeout(timeout):\n  File \"/usr/local/lib/python3.12/asyncio/timeouts.py\", line 115, in __aexit__\n    raise TimeoutError from exc_val\nTimeoutError", "timestamp": "2024-05-28T09:23:13.894930+00:00", "logger": "__main__", "module": "main", "function": "dns_resolve", "line": 96, "task_name": "Task-100", "filename": "main.py", "exc_text": null, "msecs": 894.0, "relativeCreated": 34922.74308204651, "thread": 139919965337408, "threadName": "MainThread", "processName": "MainProcess", "process": 13249, "taskName": "Task-100"}
{"level": "ERROR", "message": "Timeout Error: \nTraceback (most recent call last):\n  File \"/usr/local/lib/python3.12/asyncio/tasks.py\", line 520, in wait_for\n    return await fut\n           ^^^^^^^^^\nasyncio.exceptions.CancelledError\n\nThe above exception was the direct cause of the following exception:\n\nTraceback (most recent call last):\n  File \"/home/iman/Personal/TLS-Checker/TLS-Checker/TLS-Checker/main.py\", line 79, in dns_resolve\n    resp = await asyncio.wait_for(\n           ^^^^^^^^^^^^^^^^^^^^^^^\n  File \"/usr/local/lib/python3.12/asyncio/tasks.py\", line 519, in wait_for\n    async with timeouts.timeout(timeout):\n  File \"/usr/local/lib/python3.12/asyncio/timeouts.py\", line 115, in __aexit__\n    raise TimeoutError from exc_val\nTimeoutError", "timestamp": "2024-05-28T09:23:14.375185+00:00", "logger": "__main__", "module": "main", "function": "dns_resolve", "line": 96, "task_name": "Task-25", "filename": "main.py", "exc_text": null, "msecs": 375.0, "relativeCreated": 35402.99844741821, "thread": 139919965337408, "threadName": "MainThread", "processName": "MainProcess", "process": 13249, "taskName": "Task-25"}
{"level": "INFO", "message": "Saving data into output.db was successfully", "timestamp": "2024-05-28T09:23:14.435776+00:00", "logger": "__main__", "module": "main", "function": "main", "line": 242, "task_name": "Task-1", "filename": "main.py", "exc_text": null, "msecs": 435.0, "relativeCreated": 35463.58895301819, "thread": 139919965337408, "threadName": "MainThread", "processName": "MainProcess", "process": 13249, "taskName": "Task-1"}
{"level": "INFO", "message": "Successfully converted", "timestamp": "2024-05-28T09:23:14.474417+00:00", "logger": "csv_convertor", "module": "csv_convertor", "function": "convertor", "line": 109, "task_name": "Task-1", "filename": "csv_convertor.py", "exc_text": null, "msecs": 474.0, "relativeCreated": 35502.230644226074, "thread": 139919965337408, "threadName": "MainThread", "processName": "MainProcess", "process": 13249, "taskName": "Task-1"}
{"level": "INFO", "message": "Database successfully converted to csv file", "timestamp": "2024-05-28T09:23:14.475433+00:00", "logger": "__main__", "module": "main", "function": "main", "line": 245, "task_name": "Task-1", "filename": "main.py", "exc_text": null, "msecs": 475.0, "relativeCreated": 35503.24606895447, "thread": 139919965337408, "threadName": "MainThread", "processName": "MainProcess", "process": 13249, "taskName": "Task-1"}
{"level": "INFO", "message": "App was finished gracefully", "timestamp": "2024-05-28T09:23:14.558861+00:00", "logger": "__main__", "module": "main", "function": "<module>", "line": 260, "task_name": null, "filename": "main.py", "exc_text": null, "msecs": 558.0, "relativeCreated": 35586.674451828, "thread": 139919965337408, "threadName": "MainThread", "processName": "MainProcess", "process": 13249, "taskName": null}
